Workbook

Sheet vendor_01_2023
A1: ASIN | B1: Numero del modello | C1: Codice marketplace | D1: Ricavi ordini | E1: Unità ordinate | F1: Ricavi spedizioni | G1: COGS spedizioni | H1: Unità spedite | I1: Resi cliente
A2: B07ZJQTGG8 | B2: 50.245 | C2: IT | D2: 36493.17 | E2: 2989 | F2: 36359.7 | G2: 20059.05 | H2: 2978 | I2: 27
A3: B01I497WWM | B3: 90.920R | C3: IT | D3: 34319.58 | E3: 2922 | F3: 33633.59 | G3: 25554.71 | H3: 2873 | I3: 100
A4: B096MX229M | B4: P102ROB050 | C4: DE | D4: 28799.28 | E4: 2322 | F4: 28859.41 | G4: 18118.2 | H4: 2326 | I4: 78
A5: B08GY7286R | B5: P203TFO001 | C5: IT | D5: 24665.9 | E5: 1095 | F5: 24321.95 | G5: 10523.55 | H5: 1073 | I5: 77
A6: B017IUJA50 | B6: 90.920G | C6: IT | D6: 19352.55 | E6: 1487 | F6: 19373.27 | G6: 13675.4 | H6: 1493 | I6: 72
A7: B08485QRVZ | B7: BC.261 | C7: IT | D7: 18144.49 | E7: 889 | F7: 17981.21 | G7: 14031 | H7: 881 | I7: 27
A8: B095PQJGKX | B8: C107UTT002 | C8: ES | D8: 17910.24 | E8: 2190 | F8: 18294.7 | G8: 11297.2 | H8: 2237 | I8: 61
A9: B01KMJ9OXW | B9: 90.590Y | C9: IT | D9: 17144.47 | E9: 597 | F9: 17773.89 | G9: 12407.85 | H9: 619 | I9: 34
A10: B01KMJ9OXW | B10: 90.590Y | C10: FR | D10: 16195.78 | E10: 536 | F10: 16304.03 | G10: 10315.46 | H10: 538 | I10: 33
A11: B0BHHV552D | B11: P203TER201 | C11: IT | D11: 15037.82 | E11: 922 | F11: 14793.17 | G11: 12784.2 | H11: 907 | I11: 94
A12: B09146GTKW | B12: P302VIS002 | C12: IT | D12: 14888.98 | E12: 1836 | F12: 15132.28 | G12: 11062.2 | H12: 1866 | I12: 63
A13: B06Y17FS6D | B13: 90.550 | C13: IT | D13: 14362.86 | E13: 586 | F13: 14583.45 | G13: 15228.65 | H13: 595 | I13: 14
... A46: B095PQJGKX | B46: C107UTT002 | C46: IT | D46: 4428.06 | E46: 546 | F46: 4403.73 | G46: 2885.07 | H46: 543 | I46: 10
A47: B00L5H5KUW | B47: 40.121 | C47: IT | D47: 4379.44 | E47: 258 | F47: 4219.78 | G47: 2616.4 | H47: 248
A48: B0BD4VX5JB | B48: P203PAN002 | C48: IT | D48: 4258.28 | E48: 52 | F48: 3603.16 | G48: 3346.8 | H48: 44 | I48: 6
A49: B0757TJRR9 | B49: 40.500 | C49: FR | D49: 4185.81 | E49: 166 | F49: 4279.89 | G49: 3128.39 | H49: 170 | I49: 6
A50: B08B66J4C3 | B50: P101PIA001 | C50: IT | D50: 4139.19 | E50: 339 | F50: 4163.61 | G50: 2790.26 | H50: 341 | I50: 8
A51: B095PQJGKX | B51: C107UTT002 | C51: FR | D51: 4106.42 | E51: 498 | F51: 4008.46 | G51: 2184.6 | H51: 486 | I51: 7
A52: B0B8DLSNJF | B52: P302VIS050 | C52: ES | D52: 3982 | E52: 220 | F52: 4072.5 | G52: 3319.72 | H52: 225 | I52: 4
A53: B07NQ2VYGD | B53: BT.710Y | C53: ES | D53: 3953.6 | E53: 160 | F53: 4324.25 | G53: 3325.18 | H53: 175 | I53: 14
A54: B097HRQNRG | B54: P101FRI100 | C54: DE | D54: 3943.22 | E54: 124 | F54: 3757.94 | G54: 2554.42 | H54: 118 | I54: 18
A55: B00L5H5KUW | B55: 40.121 | C55: ES | D55: 3651.87 | E55: 239 | F55: 3546.06 | G55: 2745.38 | H55: 232
A56: B07NQC6S9V | B56: BT.651Y | C56: ES | D56: 3636.78 | E56: 98 | F56: 4082.1 | G56: 3858.92 | H56: 110 | I56: 4
A57: B0823CVGHX | B57: BP.400 | C57: ES | D57: 3593.88 | E57: 67 | F57: 3701.16 | G57: 2918.08 | H57: 69 | I57: 7
A58: B06Y1997YH | B58: 90.883 | C58: IT | D58: 3560.59 | E58: 65 | F58: 3445.99 | G58: 2811.2 | H58: 63 | I58: 8
A59: B085R2GCKX | B59: 40.332 | C59: IT | D59: 3405.42 | E59: 229 | F59: 3425.2 | G59: 1878.04 | H59: 230 | I59: 3
A60: B08FDYW72J | B60: P101CUD100 | C60: DE | D60: 3394.09 | E60: 111 | F60: 3488.44 | G60: 1967.16 | H60: 114 | I60: 12
A61: B09ZBHJ91Q | B61: P201UTP100 | C61: IT | D61: 3392.48 | E61: 208 | F61: 3653.44 | G61: 2357.85 | H61: 224 | I61: 16
A62: B00FAJUDU8 | B62: 40.967N | C62: IT | D62: 3367.65 | E62: 165 | F62: 3388.06 | G62: 2356.93 | H62: 166 | I62: 3
A63: B07YZZZVXP | B63: MD.404 | C63: DE | D63: 3338.97 | E63: 52 | F63: 3210.97 | G63: 2213.03 | H63: 50 | I63: 7
A64: B084C3JTC2 | B64: 40.406 | C64: FR | D64: 3264.52 | E64: 131 | F64: 3289.44 | G64: 2841.87 | H64: 132 | I64: 4
A65: B091LRR67V | B65: P101FRI050 | C65: IT | D65: 3256.79 | E65: 51 | F65: 3188.1 | G65: 2726.4 | H65: 50 | I65: 50
A66: B08KYZ2FLN | B66: P101FRI001 | C66: FR | D66: 3248.25 | E66: 71 | F66: 3111 | G66: 2161.76 | H66: 68 | I66: 1
A67: B08LZN1PWY | B67: P101TEM001 | C67: FR | D67: 3200.33 | E67: 39 | F67: 2954.18 | G67: 1885.19 | H67: 36 | I67: 1
... A101: B085JJ81R7 | B101: RCO9003028 | C101: IT | D101: 1766.5 | E101: 242 | F101: 1766.5 | G101: 1043.76 | H101: 242 | I101: 1
A102: B09LHXJXQL | B102: P102SBA007 | C102: FR | D102: 1674.58 | E102: 101 | F102: 1658 | G102: 1296.76 | H102: 100
A103: B06Y17FS6D | B103: 90.550 | C103: FR | D103: 1562.75 | E103: 47 | F103: 1629.25 | G103: 1343.98 | H103: 49 | I103: 7
A104: B0823CVGHX | B104: BP.400 | C104: DE | D104: 1556.23 | E104: 29 | F104: 1710.88 | G104: 1372.04 | H104: 32 | I104: 1
A105: B01CNX6Z78 | B105: 90.820 | C105: FR | D105: 1499.04 | E105: 72 | F105: 1499.04 | G105: 1229.81 | H105: 72 | I105: 1
...

Sheet vendor_01_2024
A1: ASIN | B1: Numero del modello | C1: Codice marketplace | D1: Ricavi ordini | E1: Unità ordinate | F1: Ricavi spedizioni | G1: COGS spedizioni | H1: Unità spedite | I1: Resi cliente
A2: B0BHHV552D | B2: P203TER201 | C2: IT | D2: 9074.87 | E2: 558 | F2: 8862.85 | G2: 6568.29 | H2: 545 | I2: 85
A3: B0050IHH4E | B3: 40.979 | C3: DE | D3: 8964.88 | E3: 634 | F3: 8911.52 | G3: 5696.78 | H3: 626 | I3: 45
A4: B0050IHH4E | B4: 40.979 | C4: IT | D4: 6983.03 | E4: 486 | F4: 6700.53 | G4: 4517.98 | H4: 466 | I4: 15
A5: B09146GTKW | B5: P302VIS002 | C5: IT | D5: 5723.45 | E5: 544 | F5: 5533.77 | G5: 3168 | H5: 528 | I5: 28
A6: B096MX229M | B6: P102ROB050 | C6: DE | D6: 5380.42 | E6: 431 | F6: 5105.68 | G6: 3225.2 | H6: 409 | I6: 31
A7: B0CLVS3FH6 | B7: P201UTP111 | C7: IT | D7: 5284.44 | E7: 324 | F7: 4990.86 | G7: 4284 | H7: 306 | I7: 24
A8: B00L5H5KUW | B8: 40.121 | C8: IT | D8: 5023.29 | E8: 275 | F8: 4969.44 | G8: 3229 | H8: 272
A9: B0BBH12BYN | B9: P101COS001 | C9: IT | D9: 5001.34 | E9: 57 | F9: 5079.94 | G9: 3342.7 | H9: 58 | I9: 16
A10: B07SSLRCT6 | B10: BP.304 | C10: FR | D10: 3652.58 | E10: 253 | F10: 3770.46 | G10: 2744.2 | H10: 262 | I10: 23
A11: B07Q38Z7CK | B11: BC.060 | C11: IT | D11: 3399.3 | E11: 168 | F11: 3460.53 | G11: 2565 | H11: 171 | I11: 34
A12: B09968BKDS | B12: P102FRU003 | C12: FR | D12: 2885.72 | E12: 203 | F12: 2835.81 | G12: 1745.72 | H12: 200 | I12: 20
A13: B07JGVMFY1 | B13: BP.581 | C13: FR | D13: 2760.2 | E13: 185 | F13: 2715.44 | G13: 1833.8 | H13: 182 | I13: 15
A14: B08GY7286R | B14: P203TFO001 | C14: IT | D14: 2651.93 | E14: 191 | F14: 2734.11 | G14: 1960.2 | H14: 198 | I14: 15
A15: B07V131F5W | B15: 40.490 | C15: IT | D15: 2591.61 | E15: 105 | F15: 2542.59 | G15: 1854 | H15: 103 | I15: 1
A16: B0B39H1Z8J | B16: C106CAS001 | C16: IT | D16: 2397.59 | E16: 222 | F16: 2343.81 | G16: 1140.12 | H16: 217 | I16: 30
A17: B0CLY2CF4T | B17: P201UTP113 | C17: IT | D17: 2234.47 | E17: 137 | F17: 2201.85 | G17: 1890 | H17: 135 | I17: 5
A18: B0BJ2TBPJW | B18: C206UTI004 | C18: IT | D18: 2224.23 | E18: 453 | F18: 2199.68 | G18: 950.98 | H18: 448 | I18: 1
A19: B076QCMZX1 | B19: 40.821 | C19: IT | D19: 1977.32 | E19: 162 | F19: 1989.53 | G19: 1371.9 | H19: 163 | I19: 13
A20: B0B8JVTQYQ | B20: P101CUD200 | C20: DE | D20: 1957.21 | E20: 42 | F20: 1957.21 | G20: 1438.29 | H20: 42 | I20: 21
... A63: B0BNNH9RZQ | B63: P302VIS060 | C63: ES | D63: 900.25 | E63: 72 | F63: 900.25 | G63: 502.92 | H63: 72 | I63: 37
A64: B07NQ2VYGD | B64: BT.710Y | C64: ES | D64: 864.85 | E64: 35 | F64: 1087.24 | G64: 765.6 | H64: 44
A65: B07NQ1T7YK | B65: BP.101H | C65: FR | D65: 856.06 | E65: 61 | F65: 980.44 | G65: 703.36 | H65: 72 | I65: 10
A66: B0CLVS3FH6 | B66: P201UTP111 | C66: DE | D66: 853.17 | E66: 45 | F66: 853.17 | G66: 630 | H66: 45 | I66: 3
A67: B09D8G2H7Q | B67: P102SBA500 | C67: IT | D67: 842.72 | E67: 8 | F67: 842.72 | G67: 646.4 | H67: 8 | I67: 11
A68: B07V131F5W | B68: 40.490 | C68: ES | D68: 819.64 | E68: 34 | F68: 716.59 | G68: 522 | H68: 29 | I68: 1
A69: B076DCL19C | B69: BP.720 | C69: IT | D69: 814.3 | E69: 17 | F69: 814.3 | G69: 670.85 | H69: 17 | I69: 6
A70: B09D8G2H7Q | B70: P102SBA500 | C70: FR | D70: 755.38 | E70: 7 | F70: 644.75 | G70: 484.8 | H70: 6
A71: B01M4O6145 | B71: 90.071 | C71: IT | D71: 755.17 | E71: 37 | F71: 693.94 | G71: 657.9 | H71: 34 | I71: 4
A72: B0B2F48ZMP | B72: P102GEL100 | C72: FR | D72: 723.25 | E72: 21 | F72: 689.72 | G72: 598.4 | H72: 20 | I72: 2
A73: B09BD8BG34 | B73: P301PIS001 | C73: DE | D73: 713.64 | E73: 57 | F73: 688.6 | G73: 484 | H73: 55 | I73: 8
A74: B08FMLPKY9 | B74: P201UTP004 | C74: FR | D74: 712.94 | E74: 43 | F74: 712.94 | G74: 580.5 | H74: 43 | I74: 8
A75: B085R2GCKX | B75: 40.332 | C75: IT | D75: 712.92 | E75: 43 | F75: 664.39 | G75: 450 | H75: 40 | I75: 14
A76: B07ZJMFB3R | B76: BC.510 | C76: IT | D76: 709.12 | E76: 12 | F76: 709.12 | G76: 556.8 | H76: 12 | I76: 6
A77: B0B8JVTQYQ | B77: P101CUD200 | C77: ES | D77: 701.68 | E77: 18 | F77: 712.34 | G77: 615.6 | H77: 18 | I77: 1
A78: B08JYWF3PK | B78: C102COC101 | C78: FR | D78: 701.25 | E78: 85 | F78: 726 | G78: 528 | H78: 88
A79: B0BD83RNDG | B79: C106CAS002 | C79: IT | D79: 690.53 | E79: 62 | F79: 722.24 | G79: 479.37 | H79: 65 | I79: 4
A80: B07R984VMS | B80: BI.505 | C80: FR | D80: 687.96 | E80: 93 | F80: 687.96 | G80: 587.76 | H80: 93 | I80: 1
A81: B011LFVLW8 | B81: 90.620 | C81: IT | D81: 686.19 | E81: 19 | F81: 751.59 | G81: 567 | H81: 21 | I81: 6
A82: B06Y1997YH | B82: 90.883 | C82: IT | D82: 685.1 | E82: 11 | F82: 742.4 | G82: 511.44 | H82: 12 | I82: 4
...

Sheet seller_01_2024
A1: amazon-order-id | B1: merchant-order-id | C1: purchase-date | D1: last-updated-date | E1: order-status | F1: fulfillment-channel | G1: sales-channel | H1: order-channel | I1: url | J1: ship-service-level | K1: product-name | L1: sku | M1: asin | N1: item-status | O1: quantity | P1: currency | Q1: item-price | R1: item-tax | S1: shipping-price | T1: shipping-tax | U1: gift-wrap-price | V1: gift-wrap-tax | W1: item-promotion-discount | X1: ship-promotion-discount | Y1: ship-city | Z1: ship-state | AA1: ship-postal-code | AB1: ship-country | AC1: promotion-ids | AD1: buyer-company-name | AE1: buyer-cst-number | AF1: buyer-vat-number | AG1: buyer-tax-registration-id | AH1: buyer-tax-registration-country | AI1: buyer-tax-registration-type
A2: 405-3843267-7979508 | B2: 405-3843267-7979508 | C2: 2024-01-31T22:55:05+00:00 | D2: 2024-02-02T12:04:06+00:00 | E2: Shipped | F2: Amazon | G2: Amazon.fr | J2: Standard | K2: BEPER BT.710Y Crêpière électrique avec poignée, 800 W, plaque en aluminium avec revêtement antiadhésif, rouge | L2: BT.710Y_FBA | M2: B07NQ2VYGD | N2: Shipped | O2: 1 | P2: EUR | Q2: 39.9 | S2: 1 | X2: 1 | Y2: clermont ferrand | AA2: 63000 | AB2: FR | AC2: Free Shipping 2017/10/17 17-17-37-677
A3: 402-3695688-5468327 | B3: 402-3695688-5468327 | C3: 2024-01-31T22:02:27+00:00 | D3: 2024-01-31T22:11:42+00:00 | E3: Cancelled | F3: Amazon | G3: Amazon.fr | J3: Expedited | K3: BEPER BT.710Y Crêpière électrique avec poignée, 800 W, plaque en aluminium avec revêtement antiadhésif, rouge | L3: BT.710Y_FBA | M3: B07NQ2VYGD | N3: Cancelled | O3: 0 | Y3: Bavilliers | AA3: 90800 | AB3: FR
A4: 406-8285919-0021116 | B4: 406-8285919-0021116 | C4: 2024-01-31T21:34:06+00:00 | D4: 2024-02-01T15:25:59+00:00 | E4: Shipped | F4: Amazon | G4: Amazon.fr | J4: Expedited | K4: BEPER BT.710Y Crêpière électrique avec poignée, 800 W, plaque en aluminium avec revêtement antiadhésif, rouge | L4: BT.710Y_FBA | M4: B07NQ2VYGD | N4: Shipped | O4: 1 | P4: EUR | Q4: 39.9 | Y4: Chateauneuf Les Martigues | AA4: 13220 | AB4: FR
A5: 408-3299766-2272353 | B5: 408-3299766-2272353 | C5: 2024-01-31T20:39:21+00:00 | D5: 2024-02-03T00:44:57+00:00 | E5: Shipped | F5: Amazon | G5: Amazon.fr | J5: Expedited | K5: BEPER BT.710Y Crêpière électrique avec poignée, 800 W, plaque en aluminium avec revêtement antiadhésif, rouge | L5: BT.710Y_FBA | M5: B07NQ2VYGD | N5: Shipped | O5: 1 | P5: EUR | Q5: 39.9 | Y5: Nanteuil Le Haudouin | AA5: 60440 | AB5: FR
A6: 406-4914578-1861133 | B6: 406-4914578-1861133 | C6: 2024-01-31T20:17:37+00:00 | D6: 2024-02-02T09:38:34+00:00 | E6: Shipped | F6: Amazon | G6: Amazon.fr | J6: Expedited | K6: BEPER BT.710Y Crêpière électrique avec poignée, 800 W, plaque en aluminium avec revêtement antiadhésif, rouge | L6: BT.710Y_FBA | M6: B07NQ2VYGD | N6: Shipped | O6: 1 | P6: EUR | Q6: 39.9 | Y6: Bruxelles Uccle | AA6: 1180 | AB6: BE
A7: 407-3888737-4981165 | B7: 407-3888737-4981165 | C7: 2024-01-31T20:03:34+00:00 | D7: 2024-02-01T15:44:28+00:00 | E7: Shipped | F7: Amazon | G7: Amazon.fr | J7: Expedited | K7: BEPER BT.710Y Crêpière électrique avec poignée, 800 W, plaque en aluminium avec revêtement antiadhésif, rouge | L7: BT.710Y_FBA | M7: B07NQ2VYGD | N7: Shipped | O7: 1 | P7: EUR | Q7: 39.9 | Y7: Mer | AA7: 41500 | AB7: FR
A8: 408-9077802-2293965 | B8: 408-9077802-2293965 | C8: 2024-01-31T19:52:59+00:00 | D8: 2024-02-01T00:25:13+00:00 | E8: Shipped | F8: Amazon | G8: Amazon.fr | J8: Expedited | K8: BEPER 40.405 Seche Cheveux de Voyage Pliable - Mini Seche Cheveux Silencieux, 2 Températures et 2 Vitesses | L8: 40.405_FBA | M8: B07N4C3H3V | N8: Shipped | O8: 1 | P8: EUR | Q8: 19.9 | Y8: BELLE ISLE EN TERRE | AA8: 22810 | AB8: FR
A9: 405-9171375-5879521 | B9: 405-9171375-5879521 | C9: 2024-01-31T17:48:58+00:00 | D9: 2024-02-01T00:32:57+00:00 | E9: Shipped | F9: Amazon | G9: Amazon.fr | J9: Expedited | K9: BEPER BT.710Y Crêpière électrique avec poignée, 800 W, plaque en aluminium avec revêtement antiadhésif, rouge | L9: BT.710Y_FBA | M9: B07NQ2VYGD | N9: Shipped | O9: 1 | P9: EUR | Q9: 39.9 | Y9: Maizieres | AA9: 14190 | AB9: FR
A10: 404-2179655-8359551 | B10: 404-2179655-8359551 | C10: 2024-01-31T17:21:55+00:00 | D10: 2024-01-31T17:50:06+00:00 | E10: Cancelled | F10: Amazon | G10: Amazon.fr | J10: Standard | K10: BEPER BT.710Y Crêpière électrique avec poignée, 800 W, plaque en aluminium avec revêtement antiadhésif, rouge | L10: BT.710Y_FBA | M10: B07NQ2VYGD | N10: Cancelled | O10: 0 | Y10: Nogent sur Oise | AA10: 60180 | AB10: FR
A11: 406-3733820-1731557 | B11: 406-3733820-1731557 | C11: 2024-01-31T16:02:50+00:00 | D11: 2024-01-31T21:02:08+00:00 | E11: Shipped | F11: Amazon | G11: Amazon.fr | J11: Expedited | K11: BEPER BT.710Y Crêpière électrique avec poignée, 800 W, plaque en aluminium avec revêtement antiadhésif, rouge | L11: BT.710Y_FBA | M11: B07NQ2VYGD | N11: Shipped | O11: 1 | P11: EUR | Q11: 39.9 | Y11: paris | AA11: 75013 | AB11: FR
A12: 408-9259204-7038733 | B12: 408-9259204-7038733 | C12: 2024-01-31T15:54:11+00:00 | D12: 2024-02-01T00:33:17+00:00 | E12: Shipped | F12: Amazon | G12: Amazon.fr | J12: Expedited | K12: BEPER BT.710Y Crêpière électrique avec poignée, 800 W, plaque en aluminium avec revêtement antiadhésif, rouge | L12: BT.710Y_FBA | M12: B07NQ2VYGD | N12: Shipped | O12: 1 | P12: EUR | Q12: 39.9 | S12: 2.99 | Y12: Liège | AA12: 4460 | AB12: BE
A13: 402-3114700-4349104 | B13: 402-3114700-4349104 | C13: 2024-01-31T13:39:35+00:00 | D13: 2024-01-31T16:38:23+00:00 | E13: Shipped | F13: Amazon | G13: Amazon.fr | J13: Expedited | K13: BEPER BT.710Y Crêpière électrique avec poignée, 800 W, plaque en aluminium avec revêtement antiadhésif, rouge | L13: BT.710Y_FBA | M13: B07NQ2VYGD | N13: Shipped | O13: 1 | P13: EUR | Q13: 39.9 | Y13: Castelnaudary | AA13: 11400 | AB13: FR
A14: 404-6584360-2083560 | B14: 404-6584360-2083560 | C14: 2024-01-31T13:36:10+00:00 | D14: 2024-02-01T00:33:16+00:00 | E14: Shipped | F14: Amazon | G14: Amazon.fr | J14: Expedited | K14: BEPER BT.710Y Crêpière électrique avec poignée, 800 W, plaque en aluminium avec revêtement antiadhésif, rouge | L14: BT.710Y_FBA | M14: B07NQ2VYGD | N14: Shipped | O14: 1 | P14: EUR | Q14: 39.9 | Y14: PLAISIR | AA14: 78370 | AB14: FR
A15: 404-1194761-5069908 | B15: 404-1194761-5069908 | C15: 2024-01-31T12:03:55+00:00 | D15: 2024-02-02T02:48:44+00:00 | E15: Shipped | F15: Amazon | G15: Amazon.fr | J15: Standard | K15: BEPER BT.710Y Crêpière électrique avec poignée, 800 W, plaque en aluminium avec revêtement antiadhésif, rouge | L15: BT.710Y_FBA | M15: B07NQ2VYGD | N15: Shipped | O15: 1 | P15: EUR | Q15: 39.9 | S15: 0.57 | X15: 0.57 | Y15: Nouilly | AA15: 57645 | AB15: FR | AC15: Free Shipping 2017/10/17 17-17-37-677
A16: 406-0575986-7234744 | B16: 406-0575986-7234744 | C16: 2024-01-31T09:45:23+00:00 | D16: 2024-02-01T04:01:47+00:00 | E16: Shipped | F16: Amazon | G16: Amazon.fr | J16: Expedited | K16: Beper - Machine à Pop-Corn, Pop-Corn en 3 Minutes, Sans Matières Grasses, Circulation d'Air Chaud, Puissance 1200W - Rouge [Classe d'efficacité én | L16: 90.590Y_FBA | M16: B01KMJ9OXW | N16: Shipped | O16: 1 | P16: EUR | Q16: 44.9 | Y16: Paris | AA16: 75015 | AB16: FR
A17: 407-3519396-5821109 | B17: 407-3519396-5821109 | C17: 2024-01-31T09:43:32+00:00 | D17: 2024-01-31T12:17:13+00:00 | E17: Shipped | F17: Amazon | G17: Amazon.fr | J17: Standard | K17: BEPER BT.710Y Crêpière électrique avec poignée, 800 W, plaque en aluminium avec revêtement antiadhésif, rouge | L17: BT.710Y_FBA | M17: B07NQ2VYGD | N17: Shipped | O17: 1 | P17: EUR | Q17: 39.9 | Y17: Chambly | AA17: 60230 | AB17: FR | AC17: Free Shipping 2017/10/17 17-17-37-677
A18: 402-5330354-4808345 | B18: 402-5330354-4808345 | C18: 2024-01-31T09:03:04+00:00 | D18: 2024-02-01T01:00:42+00:00 | E18: Shipped | F18: Amazon | G18: Amazon.fr | J18: Expedited | K18: BEPER BT.710Y Crêpière électrique avec poignée, 800 W, plaque en aluminium avec revêtement antiadhésif, rouge | L18: BT.710Y_FBA | M18: B07NQ2VYGD | N18: Shipped | O18: 1 | P18: EUR | Q18: 39.9 | Y18: Ahuy | AA18: 21121 | AB18: FR
A19: 402-2429105-0390756 | B19: 402-2429105-0390756 | C19: 2024-01-31T08:14:18+00:00 | D19: 2024-01-31T12:16:49+00:00 | E19: Shipped | F19: Amazon | G19: Amazon.fr | J19: Standard | K19: Beper - Machine à Pop-Corn, Pop-Corn en 3 Minutes, Sans Matières Grasses, Circulation d'Air Chaud, Puissance 1200W - Rouge [Classe d'efficacité én | L19: 90.590Y_FBA | M19: B01KMJ9OXW | N19: Shipped | O19: 1 | P19: EUR | Q19: 44.9 | Y19: Benfeld | AA19: 67230 | AB19: FR | AC19: Free Shipping 2017/10/17 17-17-37-677
A20: 402-6106346-5753960 | B20: 402-6106346-5753960 | C20: 2024-01-30T22:25:58+00:00 | D20: 2024-02-02T16:55:43+00:00 | E20: Shipped | F20: Amazon | G20: Amazon.fr | J20: Expedited | K20: BEPER BT.710Y Crêpière électrique avec poignée, 800 W, plaque en aluminium avec revêtement antiadhésif, rouge | L20: BT.710Y_FBA | M20: B07NQ2VYGD | N20: Shipped | O20: 1 | P20: EUR | Q20: 39.9 | Y20: jarnac | AA20: 16200 | AB20: FR
A21: 402-2680769-0229941 | B21: 402-2680769-0229941 | C21: 2024-01-30T21:15:36+00:00 | D21: 2024-01-31T04:58:38+00:00 | E21: Shipped | F21: Amazon | G21: Amazon.fr | J21: Standard | K21: Beper - Machine à Pop-Corn, Pop-Corn en 3 Minutes, Sans Matières Grasses, Circulation d'Air Chaud, Puissance 1200W - Rouge [Classe d'efficacité én | L21: 90.590Y_FBA | M21: B01KMJ9OXW | N21: Shipped | O21: 1 | P21: EUR | Q21: 44.9 | Y21: Sospel | AA21: 6380 | AB21: FR | AC21: Free Shipping 2017/10/17 17-17-37-677
A22: 407-2554927-9209102 | B22: 407-2554927-9209102 | C22: 2024-01-30T21:04:08+00:00 | D22: 2024-01-31T12:21:41+00:00 | E22: Shipped | F22: Amazon | G22: Amazon.fr | J22: Standard | K22: Beper - Machine à Pop-Corn, Pop-Corn en 3 Minutes, Sans Matières Grasses, Circulation d'Air Chaud, Puissance 1200W - Rouge [Classe d'efficacité én | L22: 90.590Y_FBA | M22: B01KMJ9OXW | N22: Shipped | O22: 1 | P22: EUR | Q22: 44.9 | Y22: pontcharra | AA22: 38530 | AB22: FR | AC22: Free Shipping 2017/10/17 17-17-37-677
A23: 408-5729419-0856354 | B23: 408-5729419-0856354 | C23: 2024-01-30T19:48:40+00:00 | D23: 2024-01-31T15:53:13+00:00 | E23: Shipped | F23: Amazon | G23: Amazon.fr | J23: Expedited | K23: BEPER BT.710Y Crêpière électrique avec poignée, 800 W, plaque en aluminium avec revêtement antiadhésif, rouge | L23: BT.710Y_FBA | M23: B07NQ2VYGD | N23: Shipped | O23: 1 | P23: EUR | Q23: 39.9 | Y23: PARIS | AA23: 75011 | AB23: FR
A24: 171-3066697-9063548 | B24: 171-3066697-9063548 | C24: 2024-01-30T18:52:31+00:00 | D24: 2024-01-31T12:19:21+00:00 | E24: Shipped | F24: Amazon | G24: Amazon.fr | J24: Standard | K24: BEPER BT.710Y Crêpière électrique avec poignée, 800 W, plaque en aluminium avec revêtement antiadhésif, rouge | L24: BT.710Y_FBA | M24: B07NQ2VYGD | N24: Shipped | O24: 1 | P24: EUR | Q24: 39.9 | Y24: Lapalud | AA24: 84840 | AB24: FR | AC24: Free Shipping 2017/10/17 17-17-37-677
A25: 402-2534146-1417125 | B25: 402-2534146-1417125 | C25: 2024-01-30T18:25:49+00:00 | D25: 2024-02-07T02:20:35+00:00 | E25: Shipped | F25: Amazon | G25: Amazon.fr | J25: Standard | K25: BEPER BT.710Y Crêpière électrique avec poignée, 800 W, plaque en aluminium avec revêtement antiadhésif, rouge | L25: BT.710Y_FBA | M25: B07NQ2VYGD | N25: Shipped | O25: 1 | P25: EUR | Q25: 39.9 | S25: 3.99 | X25: 3.99 | Y25: Paris | AA25: 75014 | AB25: FR | AC25: Free Shipping 2017/10/17 17-17-37-677
A26: 403-1560444-7321108 | B26: 403-1560444-7321108 | C26: 2024-01-30T18:00:18+00:00 | D26: 2024-02-01T18:46:24+00:00 | E26: Shipped | F26: Amazon | G26: Amazon.fr | J26: Standard | K26: BEPER BT.710Y Crêpière électrique avec poignée, 800 W, plaque en aluminium avec revêtement antiadhésif, rouge | L26: BT.710Y_FBA | M26: B07NQ2VYGD | N26: Shipped | O26: 1 | P26: EUR | Q26: 39.9 | S26: 2 | X26: 2 | Y26: PIGNY | Z26: Centre | AA26: 18110 | AB26: FR | AC26: Free Shipping 2017/10/17 17-17-37-677
A27: 407-3854702-0293935 | B27: 407-3854702-0293935 | C27: 2024-01-30T17:43:32+00:00 | D27: 2024-01-30T20:54:54+00:00 | E27: Shipped | F27: Amazon | G27: Amazon.fr | J27: Expedited | K27: BEPER BT.710Y Crêpière électrique avec poignée, 800 W, plaque en aluminium avec revêtement antiadhésif, rouge | L27: BT.710Y_FBA | M27: B07NQ2VYGD | N27: Shipped | O27: 1 | P27: EUR | Q27: 39.9 | Y27: St Soupplets | AA27: 77165 | AB27: FR
A28: 406-7573909-8095551 | B28: 406-7573909-8095551 | C28: 2024-01-30T17:42:03+00:00 | D28: 2024-01-31T08:59:35+00:00 | E28: Shipped | F28: Amazon | G28: Amazon.fr | J28: Expedited | K28: BEPER BT.710Y Crêpière électrique avec poignée, 800 W, plaque en aluminium avec revêtement antiadhésif, rouge | L28: BT.710Y_FBA | M28: B07NQ2VYGD | N28: Shipped | O28: 1 | P28: EUR | Q28: 39.9 | Y28: Sainte marie la mer | AA28: 66470 | AB28: FR
A29: 404-3092103-0753101 | B29: 404-3092103-0753101 | C29: 2024-01-30T17:26:39+00:00 | D29: 2024-01-31T12:51:59+00:00 | E29: Cancelled | F29: Amazon | G29: Amazon.fr | J29: Expedited | K29: BEPER BT.710Y Crêpière électrique avec poignée, 800 W, plaque en aluminium avec revêtement antiadhésif, rouge | L29: BT.710Y_FBA | M29: B07NQ2VYGD | N29: Cancelled | O29: 0 | Y29: ST SOUPPLETS | AA29: 77165 | AB29: FR
A30: 405-0174707-0062737 | B30: 405-0174707-0062737 | C30: 2024-01-30T16:15:58+00:00 | D30: 2024-01-30T20:55:26+00:00 | E30: Shipped | F30: Amazon | G30: Amazon.fr | J30: Standard | K30: Beper - Machine à Pop-Corn, Pop-Corn en 3 Minutes, Sans Matières Grasses, Circulation d'Air Chaud, Puissance 1200W - Rouge [Classe d'efficacité én | L30: 90.590Y_FBA | M30: B01KMJ9OXW | N30: Shipped | O30: 1 | P30: EUR | Q30: 44.9 | Y30: Le Cannet Rocheville | Z30: Sud | AA30: 6110 | AB30: FR | AC30: Free Shipping 2017/10/17 17-17-37-677
A31: 403-1958801-9690746 | B31: 403-1958801-9690746 | C31: 2024-01-30T15:10:38+00:00 | D31: 2024-01-31T05:02:33+00:00 | E31: Shipped | F31: Amazon | G31: Amazon.fr | J31: Standard | K31: BEPER BT.710Y Crêpière électrique avec poignée, 800 W, plaque en aluminium avec revêtement antiadhésif, rouge | L31: BT.710Y_FBA | M31: B07NQ2VYGD | N31: Shipped | O31: 1 | P31: EUR | Q31: 39.9 | Y31: LAVERNOSE lacasse | AA31: 31410 | AB31: FR | AC31: Free Shipping 2017/10/17 17-17-37-677
A32: 405-3145505-5999559 | B32: 405-3145505-5999559 | C32: 2024-01-30T14:53:57+00:00 | D32: 2024-01-31T00:33:17+00:00 | E32: Shipped | F32: Amazon | G32: Amazon.fr | J32: Expedited | K32: BEPER BT.710Y Crêpière électrique avec poignée, 800 W, plaque en aluminium avec revêtement antiadhésif, rouge | L32: BT.710Y_FBA | M32: B07NQ2VYGD | N32: Shipped | O32: 1 | P32: EUR | Q32: 39.9 | Y32: CHELLES | AA32: 77500 | AB32: FR
A33: 407-9216780-6296325 | B33: 407-9216780-6296325 | C33: 2024-01-30T14:39:19+00:00 | D33: 2024-01-31T00:33:18+00:00 | E33: Shipped | F33: Amazon | G33: Amazon.fr | J33: Expedited | K33: BEPER BT.710Y Crêpière électrique avec poignée, 800 W, plaque en aluminium avec revêtement antiadhésif, rouge | L33: BT.710Y_FBA | M33: B07NQ2VYGD | N33: Shipped | O33: 1 | P33: EUR | Q33: 39.9 | Y33: Caudebec Lès Elbeuf | AA33: 76320 | AB33: FR
A34: 406-8231380-3077109 | B34: 406-8231380-3077109 | C34: 2024-01-30T13:57:20+00:00 | D34: 2024-01-31T01:47:16+00:00 | E34: Shipped | F34: Amazon | G34: Amazon.fr | J34: Expedited | K34: BEPER BT.710Y Crêpière électrique avec poignée, 800 W, plaque en aluminium avec revêtement antiadhésif, rouge | L34: BT.710Y_FBA | M34: B07NQ2VYGD | N34: Shipped | O34: 1 | P34: EUR | Q34: 39.9 | Y34: RESTIGNE | AA34: 37140 | AB34: FR
A35: 406-1070790-2301149 | B35: 406-1070790-2301149 | C35: 2024-01-30T13:11:48+00:00 | D35: 2024-01-31T00:33:17+00:00 | E35: Shipped | F35: Amazon | G35: Amazon.fr | J35: Expedited | K35: BEPER BT.710Y Crêpière électrique avec poignée, 800 W, plaque en aluminium avec revêtement antiadhésif, rouge | L35: BT.710Y_FBA | M35: B07NQ2VYGD | N35: Shipped | O35: 1 | P35: EUR | Q35: 39.9 | Y35: Linselles | AA35: 59126 | AB35: FR
A36: 402-8553313-3173166 | B36: 402-8553313-3173166 | C36: 2024-01-30T12:21:36+00:00 | D36: 2024-02-12T08:04:09+00:00 | E36: Shipped | F36: Amazon | G36: Amazon.fr | J36: Standard | K36: Beper - Machine à Pop-Corn, Pop-Corn en 3 Minutes, Sans Matières Grasses, Circulation d'Air Chaud, Puissance 1200W - Rouge [Classe d'efficacité én | L36: 90.590Y_FBA | M36: B01KMJ9OXW | N36: Shipped | O36: 2 | P36: EUR | Q36: 89.8 | S36: 3.99 | X36: 3.99 | Y36: St Pierre Montlimart | AA36: 49110 | AB36: FR | AC36: Free Shipping 2017/10/17 17-17-37-677
A37: 405-3363135-7459552 | B37: 405-3363135-7459552 | C37: 2024-01-30T12:18:04+00:00 | D37: 2024-01-30T20:55:30+00:00 | E37: Shipped | F37: Amazon | G37: Amazon.fr | J37: Expedited | K37: BEPER BT.710Y Crêpière électrique avec poignée, 800 W, plaque en aluminium avec revêtement antiadhésif, rouge | L37: BT.710Y_FBA | M37: B07NQ2VYGD | N37: Shipped | O37: 1 | P37: EUR | Q37: 39.9 | Y37: Draveil | AA37: 91210 | AB37: FR
A38: 405-7404889-1469149 | B38: 405-7404889-1469149 | C38: 2024-01-30T10:32:57+00:00 | D38: 2024-02-01T15:07:39+00:00 | E38: Shipped | F38: Amazon | G38: Amazon.fr | J38: Expedited | K38: BEPER BT.710Y Crêpière électrique avec poignée, 800 W, plaque en aluminium avec revêtement antiadhésif, rouge | L38: BT.710Y_FBA | M38: B07NQ2VYGD | N38: Shipped | O38: 1 | P38: EUR | Q38: 39.9 | Y38: Fos-sur-Mer | AA38: 13270 | AB38: FR
A39: 402-2190183-7726739 | B39: 402-2190183-7726739 | C39: 2024-01-30T10:15:59+00:00 | D39: 2024-02-04T10:19:29+00:00 | E39: Cancelled | F39: Amazon | G39: Amazon.fr | J39: Expedited | K39: BEPER BT.710Y Crêpière électrique avec poignée, 800 W, plaque en aluminium avec revêtement antiadhésif, rouge | L39: BT.710Y_FBA | M39: B07NQ2VYGD | N39: Cancelled | O39: 0 | Y39: WALDOLWISHEIM | AA39: 67700 | AB39: FR
A40: 171-9571645-3937903 | B40: 171-9571645-3937903 | C40: 2024-01-30T09:42:23+00:00 | D40: 2024-01-31T00:38:18+00:00 | E40: Shipped | F40: Amazon | G40: Amazon.fr | J40: Expedited | K40: BEPER BT.710Y Crêpière électrique avec poignée, 800 W, plaque en aluminium avec revêtement antiadhésif, rouge | L40: BT.710Y_FBA | M40: B07NQ2VYGD | N40: Shipped | O40: 1 | P40: EUR | Q40: 39.9 | Y40: rimbach pres masevaux | AA40: 68290 | AB40: FR
...

Sheet v_2023
A1: Codice marketplace | B1: (Tutto) | F1: Codice marketplace | G1: IT
A3: ASIN | B3: Numero del modello | C3: Somma di Unità ordinate | D3: Somma di Ricavi ordini | F3: ASIN | G3: Numero del modello | H3: Somma di Unità ordinate | I3: Somma di Ricavi ordini
A4: B0050IHH4E | B4: 40.979 | C4: 14 | D4: 182.42 | F4: B0050IHH4E | G4: 40.979 | H4: 14 | I4: 182.42
A5: B00BH202XK | B5: 40.808A | C5: 1 | D5: 20.59 | F5: B00BH202XK | G5: 40.808A | H5: 1 | I5: 20.59
A6: B00C5CCJP0 | B6: 40.993 | C6: 8 | D6: 121.8 | F6: B00CMAD2FG | G6: HK-NV009W | H6: 1 | I6: 19.69
A7: B00CMAD2FG | B7: HK-NV009W | C7: 2 | D7: 34.18 | F7: B00EYDRS1I | G7: 90.349 | H7: 109 | I7: 755.85
A8: B00EYDRS1I | B8: 90.349 | C8: 119 | D8: 828.55 | F8: B00EYF02AU | G8: 90.502 | H8: 0 | I8: 0
A9: B00EYF02AU | B9: 90.502 | C9: 0 | D9: 0 | F9: B00FAJUDU8 | G9: 40.967N | H9: 165 | I9: 3367.65
A10: B00EZ4185S | B10: RI.501SL | C10: 1 | D10: 119.51 | F10: B00FFBFVG2 | G10: 40.100 | H10: 9 | I10: 71.49
A11: B00FAJUDU8 | B11: 40.967N | C11: 302 | D11: 6543.96 | F11: B00L5GPWFG | G11: 40.120 | H11: 20 | I11: 325.84
A12: B00FFBED98 | B12: 40.11 | C12: 1 | D12: 28.03 | F12: B00L5H5KUW | G12: 40.121 | H12: 258 | I12: 4379.44
A13: B00FFBFVG2 | B13: 40.100 | C13: 13 | D13: 104.24 | F13: B00NSNZSLM | G13: 90.602 | H13: 388 | I13: 7919.08
A14: B00J7MNQFS | B14: 40.994 | C14: 0 | D14: 0 | F14: B00OKE4RTM | G14: 90.386 | H14: 7 | I14: 364.33
A15: B00L5GPWFG | B15: 40.120 | C15: 20 | D15: 325.84 | F15: B00OLZPU5K | G15: 40.947 | H15: 7 | I15: 71.13
... A207: B08MM2VK11 | B207: P302MAS001 | C207: 13 | D207: 376.61 | F207: B0BRQB2J4B | G207: PET005 | H207: 9 | I207: 36.18
A208: B08MX1SQKC | B208: P302VIS001 | C208: 154 | D208: 1887.5 | F208: Totale complessivo | H208: 31233 | I208: 477924.76
A209: B08NDZKNF5 | B209: P102CON001 | C209: 35 | D209: 1010.82
A210: B08NF8TQKT | B210: P102FRU100 | C210: 9 | D210: 220.59
A211: B08NTD853X | B211: P102SBA006 | C211: 21 | D211: 172.9
A212: B08V4VTTQN | B212: C107UTT001 | C212: 27 | D212: 191.08
A213: B08X4VZV3S | B213: P303BIP001 | C213: 1 | D213: 10.57
A214: B08XQT9P5C | B214: P102GEL001 | C214: 5 | D214: 194.29
A215: B08XVV3PVK | B215: P303MED001 | C215: 4 | D215: 45
A216: B09146GTKW | B216: P302VIS002 | C216: 4056 | D216: 33322.03
A217: B091C5XQZN | B217: P202ASP001 | C217: 3 | D217: 168.63
A218: B091LRR67V | B218: P101FRI050 | C218: 66 | D218: 4251.64
A219: B091VSY78C | B219: P303BIP050 | C219: 0 | D219: 0
A220: B09251R9RJ | B220: P304CAP001 | C220: 5 | D220: 81.96
... A295: B0BRQB2J4B | B295: PET005 | C295: 13 | D295: 52.36
A296: Totale complessivo | C296: 51985 | D296: 814456.16

Sheet v_2024
A1: Codice marketplace | B1: (Tutto) | F1: Codice marketplace | G1: IT
A3: ASIN | B3: Numero del modello | C3: Somma di Unità ordinate | D3: Somma di Ricavi ordini | F3: ASIN | G3: Numero del modello | H3: Somma di Unità ordinate | I3: Somma di Ricavi ordini
A4: B0050IHH4E | B4: 40.979 | C4: 1183 | D4: 16822.21 | F4: B0050IHH4E | G4: 40.979 | H4: 486 | I4: 6983.03
A5: B009O92WU4 | B5: 40.999 | C5: 1 | D5: 5.03 | F5: B00BH202XK | G5: 40.808A | H5: 6 | I5: 83.1
A6: B00BH202XK | B6: 40.808A | C6: 10 | D6: 127.35 | F6: B00EYDRS1I | G6: 90.349 | H6: 36 | I6: 211.74
A7: B00CMAD2FG | B7: HK-NV009W | C7: 1 | D7: 15.18 | F7: B00FFBFVG2 | G7: 40.100 | H7: 0 | I7: 0
A8: B00EYDRS1I | B8: 90.349 | C8: 48 | D8: 271.81 | F8: B00L5GPWFG | G8: 40.120 | H8: 6 | I8: 147.9
A9: B00FFBFVG2 | B9: 40.100 | C9: 0 | D9: 0 | F9: B00L5H5KUW | G9: 40.121 | H9: 275 | I9: 5023.29
A10: B00FMZ2VW8 | B10: HK-HQ601C PINK | C10: 0 | D10: 0 | F10: B00NSNZSLM | G10: 90.602 | H10: 1 | I10: 20.41
A11: B00L5GPWFG | B11: 40.120 | C11: 6 | D11: 147.9 | F11: B00OKE4RTM | G11: 90.386 | H11: 2 | I11: 98.08
A12: B00L5H5KUW | B12: 40.121 | C12: 275 | D12: 5023.29 | F12: B00YH3FRV8 | G12: 40.998 | H12: 1 | I12: 7.43
A13: B00NSNZSLM | B13: 90.602 | C13: 1 | D13: 20.41 | F13: B011LFM60E | G13: 40.948T | H13: 2 | I13: 12.96
A14: B00OKE4RTM | B14: 90.386 | C14: 2 | D14: 98.08 | F14: B011LFVLW8 | G14: 90.620 | H14: 19 | I14: 686.19
A15: B00YH3FRV8 | B15: 40.998 | C15: 1 | D15: 7.43 | F15: B017IUJA50 | G15: 90.920G | H15: 15 | I15: 209.45
... A201: B097785V2V | B201: P202VAL110 | C201: 1 | D201: 5.42 | F201: B0CXJCJF5B | G201: P101PIA003 | H201: 8 | I201: 117.36
A202: B0978ZKW4S | B202: P205DIF100 | C202: 35 | D202: 428.14 | F202: Totale complessivo | H202: 6632 | I202: 104761.64
A203: B097F45J2B | B203: P102FRU500 | C203: 2 | D203: 65.4
A204: B097HRQNRG | B204: P101FRI100 | C204: 5 | D204: 150.29
A205: B097YTGFH7 | B205: P102ROB200 | C205: 22 | D205: 1103.13
A206: B098F33WBD | B206: RCO4091819 | C206: 21 | D206: 2.93
A207: B098QM485T | B207: P101CUD050 | C207: 5 | D207: 208.96
A208: B09968BKDS | B208: P102FRU003 | C208: 243 | D208: 3443.57
A209: B09B15P5H1 | B209: P102FRU200 | C209: 6 | D209: 91.74
A210: B09B2NT2SV | B210: P102FRU150 | C210: 9 | D210: 194.04
A211: B09B47S644 | B211: P101CUD501 | C211: 79 | D211: 2302.19
A212: B09BBFTDLJ | B212: P101TOS501 | C212: 1 | D212: 61.57
A213: B09BD8BG34 | B213: P301PIS001 | C213: 188 | D213: 2349.32
A214: B09BG1GGSM | B214: P204FER003 | C214: 0 | D214: 0
... A284: B0CXJCJF5B | B284: P101PIA003 | C284: 13 | D284: 191.49
A285: Totale complessivo | C285: 13774 | D285: 219396.13

Sheet s_2024
A1: sales-channel | B1: (Tutto) | E1: sales-channel | F1: Amazon.it
A3: Etichette di riga | B3: Somma di quantity | C3: Somma di item-price | E3: Etichette di riga | F3: Somma di quantity | G3: Somma di item-price
A4: B0050IHH4E | B4: 3 | C4: 60.7 | E4: B0050IHH4E | F4: 3 | G4: 60.7
A5: B00FAJUDU8 | B5: 27 | C5: 822.3 | E5: B00FAJUDU8 | F5: 27 | G5: 822.3
A6: B00NSNZSLM | B6: 48 | C6: 1440.2 | E6: B00NSNZSLM | F6: 48 | G6: 1440.2
A7: B01CNX704K | B7: 6 | C7: 281.4 | E7: B01CNX704K | F7: 6 | G7: 281.4
A8: B01I497WWM | B8: 534 | C8: 10674.53 | E8: B01I497WWM | F8: 534 | G8: 10674.53
A9: B01KMJ9OXW | B9: 394 | C9: 14503.53 | E9: B01KMJ9OXW | F9: 317 | G9: 11062.43
A10: B01MTSEGF9 | B10: 8 | C10: 432.8 | E10: B01MTSEGF9 | F10: 8 | G10: 432.8
A11: B06Y17FS6D | B11: 1 | E11: B06Y195DJN | F11: 18 | G11: 898.2
A12: B06Y195DJN | B12: 18 | C12: 898.2 | E12: B0757TJRR9 | F12: 385 | G12: 12660.57
A13: B0757TJRR9 | B13: 388 | C13: 12795.27 | E13: B076D74TC7 | F13: 1 | G13: 36.99
A14: B076D74TC7 | B14: 1 | C14: 36.99 | E14: B076DCKSTJ | F14: 35 | G14: 871.5
A15: B076DCKSTJ | B15: 36 | C15: 906.4 | E15: B07BB2DQ4V | F15: 8 | G15: 377.4
A16: B07BB2DQ4V | B16: 13 | C16: 626.9 | E16: B07HM7P6MP | F16: 17 | G16: 542.99
A17: B07HM7P6MP | B17: 17 | C17: 542.99 | E17: B07N4C3H3V | F17: 44 | G17: 652.91
A18: B07N4C3H3V | B18: 45 | C18: 672.81 | E18: B07NQ2VYGD | F18: 229 | G18: 6838.12
A19: B07NQ2VYGD | B19: 365 | C19: 12257.32 | E19: B07NQC6S9V | F19: 16 | G19: 798.4
A20: B07NQC6S9V | B20: 20 | C20: 1038 | E20: B07P7GGGQM | F20: 19 | G20: 1138.1
A21: B07P7GGGQM | B21: 19 | C21: 1138.1 | E21: B07TVSJDCL | F21: 1 | G21: 15.9
A22: B07TVSJDCL | B22: 1 | C22: 15.9 | E22: B07V131F5W | F22: 104 | G22: 3109.6
A23: B07V131F5W | B23: 104 | C23: 3109.6 | E23: B07YBN2FS3 | F23: 26 | G23: 2077.4
... A40: B0B8DLSNJF | B40: 17 | C40: 418.81 | E40: Totale complessivo | F40: 2257 | G40: 67095.84
A41: Totale complessivo | B41: 2497 | C41: 77269.54

Sheet pivot
A3: ASIN | B3: SKU | C3: Somma di Ordini Vendor 24 | D3: Somma di Valori ordini Vendor 24 | E3: Somma di Ordini Seller 24 | F3: Somma di Valori ordini Seller 24 | G3: Somma di Ordini Complessivi 24 | H3: Somma di Valori ordini Complessivi 24 | I3: Somma di Ordini Vendor 23 | J3: Somma di Valori ordini Vendor 23
A4: B0050IHH4E | B4: 40.979 | C4: 1183 | D4: 16822.21 | E4: 3 | F4: 60.7 | G4: 1186 | H4: 16882.91 | I4: 14 | J4: 182.42
A5: B009O92WU4 | B5: 40.999 | C5: 1 | D5: 5.03 | E5: 0 | F5: 0 | G5: 1 | H5: 5.03 | I5: 0 | J5: 0
A6: B00BH202XK | B6: 40.808A | C6: 10 | D6: 127.35 | E6: 0 | F6: 0 | G6: 10 | H6: 127.35 | I6: 1 | J6: 20.59
A7: B00C5CCJP0 | B7: 40.993 | C7: 0 | D7: 0 | E7: 0 | F7: 0 | G7: 0 | H7: 0 | I7: 8 | J7: 121.8
A8: B00CMAD2FG | B8: HK-NV009W | C8: 1 | D8: 15.18 | E8: 0 | F8: 0 | G8: 1 | H8: 15.18 | I8: 2 | J8: 34.18
A9: B00EYDRS1I | B9: 90.349 | C9: 48 | D9: 271.81 | E9: 0 | F9: 0 | G9: 48 | H9: 271.81 | I9: 119 | J9: 828.55
A10: B00EYF02AU | B10: 90.502 | C10: 0 | D10: 0 | E10: 0 | F10: 0 | G10: 0 | H10: 0 | I10: 0 | J10: 0
A11: B00EZ4185S | B11: RI.501SL | C11: 0 | D11: 0 | E11: 0 | F11: 0 | G11: 0 | H11: 0 | I11: 1 | J11: 119.51
A12: B00FAJUDU8 | B12: 40.967N | C12: 0 | D12: 0 | E12: 27 | F12: 822.3 | G12: 27 | H12: 822.3 | I12: 302 | J12: 6543.96
A13: B00FFBED98 | B13: 40.11 | C13: 0 | D13: 0 | E13: 0 | F13: 0 | G13: 0 | H13: 0 | I13: 1 | J13: 28.03
A14: B00FFBFVG2 | B14: 40.100 | C14: 0 | D14: 0 | E14: 0 | F14: 0 | G14: 0 | H14: 0 | I14: 13 | J14: 104.24
A15: B00FMZ2VW8 | B15: HK-HQ601C PINK | C15: 0 | D15: 0 | E15: 0 | F15: 0 | G15: 0 | H15: 0 | I15: 0 | J15: 0
... A362: Totale complessivo | B362: Totale complessivo | C362: 13774 | D362: 219396.13 | E362: 2497 | F362: 77269.54 | G362: 16271 | H362: 296665.67 | I362: 51985 | J362: 814456.16
A363: Totale complessivo | C363: 27548 | D363: 438792.26 | E363: 4994 | F363: 154539.08 | G363: 32542 | H363: 593331.34 | I363: 103970 | J363: 1628912.3

Sheet IT
A1: ASIN | B1: SKU | C1: Ordini Vendor 24 | D1: Valori ordini Vendor 24 | E1: Ordini Seller 24 | F1: Valori ordini Seller 24 | G1: % seller / totale | H1: Ordini Complessivi 24 | I1: Valori ordini Complessivi 24 | J1: Ordini Vendor 23 | K1: Valori ordini Vendor 23 | L1: Differenza Ordini | M1: Differenza Valore | N1: Differenza Valore %
A2: B0050IHH4E | B2: 40.979 | C2: =VLOOKUP(A2,v_2024!F:I,3,FALSE) -> 486 | D2: =VLOOKUP(A2,v_2024!F:I,4,FALSE) -> 6983.03 | E2: =VLOOKUP(A2,s_2024!E:G,2,FALSE) -> 3 | F2: =VLOOKUP(A2,s_2024!E:G,3,FALSE) -> 60.7 | G2: =F2/I2 -> 0.0086175932 | H2: =E2+C2 -> 489 | I2: =F2+D2 -> 7043.73 | J2: =VLOOKUP(A2,v_2023!F:I,3,FALSE) -> 14 | K2: =VLOOKUP(A2,v_2023!F:I,4,FALSE) -> 182.42 | L2: =H2-J2 -> 475 | M2: =I2-K2 -> 6861.31 | N2: =M2/K2 -> 37.612707
A3: B009O92WU4 | B3: 40.999 | C3: 0 | D3: 0 | E3: 0 | F3: 0 | H3: =E3+C3 -> 0 | I3: =F3+D3 -> 0 | J3: 0 | K3: 0 | L3: =H3-J3 -> 0 | M3: =I3-K3 -> 0
A4: B00BH202XK | B4: 40.808A | C4: =VLOOKUP(A4,v_2024!F:I,3,FALSE) -> 6 | D4: =VLOOKUP(A4,v_2024!F:I,4,FALSE) -> 83.1 | E4: 0 | F4: 0 | G4: =F4/I4 -> 0 | H4: =E4+C4 -> 6 | I4: =F4+D4 -> 83.1 | J4: =VLOOKUP(A4,v_2023!F:I,3,FALSE) -> 1 | K4: =VLOOKUP(A4,v_2023!F:I,4,FALSE) -> 20.59 | L4: =H4-J4 -> 5 | M4: =I4-K4 -> 62.51 | N4: =M4/K4 -> 3.0359398
A5: B00CMAD2FG | B5: HK-NV009W | C5: 0 | D5: 0 | E5: 0 | F5: 0 | H5: =E5+C5 -> 0 | I5: =F5+D5 -> 0 | J5: =VLOOKUP(A5,v_2023!F:I,3,FALSE) -> 1 | K5: =VLOOKUP(A5,v_2023!F:I,4,FALSE) -> 19.69 | L5: =H5-J5 -> -1 | M5: =I5-K5 -> -19.69 | N5: =M5/K5 -> -1
A6: B00EYDRS1I | B6: 90.349 | C6: =VLOOKUP(A6,v_2024!F:I,3,FALSE) -> 36 | D6: =VLOOKUP(A6,v_2024!F:I,4,FALSE) -> 211.74 | E6: 0 | F6: 0 | G6: =F6/I6 -> 0 | H6: =E6+C6 -> 36 | I6: =F6+D6 -> 211.74 | J6: =VLOOKUP(A6,v_2023!F:I,3,FALSE) -> 109 | K6: =VLOOKUP(A6,v_2023!F:I,4,FALSE) -> 755.85 | L6: =H6-J6 -> -73 | M6: =I6-K6 -> -544.11 | N6: =M6/K6 -> -0.71986505
A7: B00FFBFVG2 | B7: 40.100 | C7: =VLOOKUP(A7,v_2024!F:I,3,FALSE) -> 0 | D7: =VLOOKUP(A7,v_2024!F:I,4,FALSE) -> 0 | E7: 0 | F7: 0 | H7: =E7+C7 -> 0 | I7: =F7+D7 -> 0 | J7: =VLOOKUP(A7,v_2023!F:I,3,FALSE) -> 9 | K7: =VLOOKUP(A7,v_2023!F:I,4,FALSE) -> 71.49 | L7: =H7-J7 -> -9 | M7: =I7-K7 -> -71.49 | N7: =M7/K7 -> -1
A8: B00FMZ2VW8 | B8: HK-HQ601C PINK | C8: 0 | D8: 0 | E8: 0 | F8: 0 | H8: =E8+C8 -> 0 | I8: =F8+D8 -> 0 | J8: 0 | K8: 0 | L8: =H8-J8 -> 0 | M8: =I8-K8 -> 0
A9: B00L5GPWFG | B9: 40.120 | C9: =VLOOKUP(A9,v_2024!F:I,3,FALSE) -> 6 | D9: =VLOOKUP(A9,v_2024!F:I,4,FALSE) -> 147.9 | E9: 0 | F9: 0 | G9: =F9/I9 -> 0 | H9: =E9+C9 -> 6 | I9: =F9+D9 -> 147.9 | J9: =VLOOKUP(A9,v_2023!F:I,3,FALSE) -> 20 | K9: =VLOOKUP(A9,v_2023!F:I,4,FALSE) -> 325.84 | L9: =H9-J9 -> -14 | M9: =I9-K9 -> -177.94 | N9: =M9/K9 -> -0.54609624
A10: B00L5H5KUW | B10: 40.121 | C10: =VLOOKUP(A10,v_2024!F:I,3,FALSE) -> 275 | D10: =VLOOKUP(A10,v_2024!F:I,4,FALSE) -> 5023.29 | E10: 0 | F10: 0 | G10: =F10/I10 -> 0 | H10: =E10+C10 -> 275 | I10: =F10+D10 -> 5023.29 | J10: =VLOOKUP(A10,v_2023!F:I,3,FALSE) -> 258 | K10: =VLOOKUP(A10,v_2023!F:I,4,FALSE) -> 4379.44 | L10: =H10-J10 -> 17 | M10: =I10-K10 -> 643.85 | N10: =M10/K10 -> 0.14701651
A11: B00NSNZSLM | B11: 90.602 | C11: =VLOOKUP(A11,v_2024!F:I,3,FALSE) -> 1 | D11: =VLOOKUP(A11,v_2024!F:I,4,FALSE) -> 20.41 | E11: =VLOOKUP(A11,s_2024!E:G,2,FALSE) -> 48 | F11: =VLOOKUP(A11,s_2024!E:G,3,FALSE) -> 1440.2 | G11: =F11/I11 -> 0.98602639 | H11: =E11+C11 -> 49 | I11: =F11+D11 -> 1460.61 | J11: =VLOOKUP(A11,v_2023!F:I,3,FALSE) -> 388 | K11: =VLOOKUP(A11,v_2023!F:I,4,FALSE) -> 7919.08 | L11: =H11-J11 -> -339 | M11: =I11-K11 -> -6458.47 | N11: =M11/K11 -> -0.81555812
A12: B00OKE4RTM | B12: 90.386 | C12: =VLOOKUP(A12,v_2024!F:I,3,FALSE) -> 2 | D12: =VLOOKUP(A12,v_2024!F:I,4,FALSE) -> 98.08 | E12: 0 | F12: 0 | G12: =F12/I12 -> 0 | H12: =E12+C12 -> 2 | I12: =F12+D12 -> 98.08 | J12: =VLOOKUP(A12,v_2023!F:I,3,FALSE) -> 7 | K12: =VLOOKUP(A12,v_2023!F:I,4,FALSE) -> 364.33 | L12: =H12-J12 -> -5 | M12: =I12-K12 -> -266.25 | N12: =M12/K12 -> -0.73079351
A13: B00YH3FRV8 | B13: 40.998 | C13: =VLOOKUP(A13,v_2024!F:I,3,FALSE) -> 1 | D13: =VLOOKUP(A13,v_2024!F:I,4,FALSE) -> 7.43 | E13: 0 | F13: 0 | G13: =F13/I13 -> 0 | H13: =E13+C13 -> 1 | I13: =F13+D13 -> 7.43 | J13: 0 | K13: 0 | L13: =H13-J13 -> 1 | M13: =I13-K13 -> 7.43
A14: B011LFM60E | B14: 40.948T | C14: =VLOOKUP(A14,v_2024!F:I,3,FALSE) -> 2 | D14: =VLOOKUP(A14,v_2024!F:I,4,FALSE) -> 12.96 | E14: 0 | F14: 0 | G14: =F14/I14 -> 0 | H14: =E14+C14 -> 2 | I14: =F14+D14 -> 12.96 | J14: 0 | K14: 0 | L14: =H14-J14 -> 2 | M14: =I14-K14 -> 12.96
A15: B011LFVLW8 | B15: 90.620 | C15: =VLOOKUP(A15,v_2024!F:I,3,FALSE) -> 19 | D15: =VLOOKUP(A15,v_2024!F:I,4,FALSE) -> 686.19 | E15: 0 | F15: 0 | G15: =F15/I15 -> 0 | H15: =E15+C15 -> 19 | I15: =F15+D15 -> 686.19 | J15: =VLOOKUP(A15,v_2023!F:I,3,FALSE) -> 99 | K15: =VLOOKUP(A15,v_2023!F:I,4,FALSE) -> 2832.39 | L15: =H15-J15 -> -80 | M15: =I15-K15 -> -2146.2 | N15: =M15/K15 -> -0.75773463
A16: B017IUJA50 | B16: 90.920G | C16: =VLOOKUP(A16,v_2024!F:I,3,FALSE) -> 15 | D16: =VLOOKUP(A16,v_2024!F:I,4,FALSE) -> 209.45 | E16: 0 | F16: 0 | G16: =F16/I16 -> 0 | H16: =E16+C16 -> 15 | I16: =F16+D16 -> 209.45 | J16: =VLOOKUP(A16,v_2023!F:I,3,FALSE) -> 1487 | K16: =VLOOKUP(A16,v_2023!F:I,4,FALSE) -> 19352.55 | L16: =H16-J16 -> -1472 | M16: =I16-K16 -> -19143.1 | N16: =M16/K16 -> -0.98917714
A17: B01CHW1L88 | B17: PE.001 | C17: =VLOOKUP(A17,v_2024!F:I,3,FALSE) -> 1 | D17: =VLOOKUP(A17,v_2024!F:I,4,FALSE) -> 15.05 | E17: 0 | F17: 0 | G17: =F17/I17 -> 0 | H17: =E17+C17 -> 1 | I17: =F17+D17 -> 15.05 | J17: 0 | K17: 0 | L17: =H17-J17 -> 1 | M17: =I17-K17 -> 15.05
A18: B01CNX6T10 | B18: PE.165 | C18: 0 | D18: 0 | E18: 0 | F18: 0 | H18: =E18+C18 -> 0 | I18: =F18+D18 -> 0 | J18: 0 | K18: 0 | L18: =H18-J18 -> 0 | M18: =I18-K18 -> 0
A19: B01CNX6UIM | B19: PE.300 | C19: =VLOOKUP(A19,v_2024!F:I,3,FALSE) -> 0 | D19: =VLOOKUP(A19,v_2024!F:I,4,FALSE) -> 0 | E19: 0 | F19: 0 | H19: =E19+C19 -> 0 | I19: =F19+D19 -> 0 | J19: 0 | K19: 0 | L19: =H19-J19 -> 0 | M19: =I19-K19 -> 0
A20: B01CNX6Z78 | B20: 90.820 | C20: 0 | D20: 0 | E20: 0 | F20: 0 | H20: =E20+C20 -> 0 | I20: =F20+D20 -> 0 | J20: 0 | K20: 0 | L20: =H20-J20 -> 0 | M20: =I20-K20 -> 0
A21: B01CNX704K | B21: 90.825 | C21: 0 | D21: 0 | E21: =VLOOKUP(A21,s_2024!E:G,2,FALSE) -> 6 | F21: =VLOOKUP(A21,s_2024!E:G,3,FALSE) -> 281.4 | G21: =F21/I21 -> 1 | H21: =E21+C21 -> 6 | I21: =F21+D21 -> 281.4 | J21: 0 | K21: 0 | L21: =H21-J21 -> 6 | M21: =I21-K21 -> 281.4
A22: B01CNX71NA | B22: 90.871 | C22: =VLOOKUP(A22,v_2024!F:I,3,FALSE) -> 1 | D22: =VLOOKUP(A22,v_2024!F:I,4,FALSE) -> 86.86 | E22: 0 | F22: 0 | G22: =F22/I22 -> 0 | H22: =E22+C22 -> 1 | I22: =F22+D22 -> 86.86 | J22: =VLOOKUP(A22,v_2023!F:I,3,FALSE) -> 3 | K22: =VLOOKUP(A22,v_2023!F:I,4,FALSE) -> 238.42 | L22: =H22-J22 -> -2 | M22: =I22-K22 -> -151.56 | N22: =M22/K22 -> -0.63568493
A23: B01HM47LF8 | B23: MD.004 | C23: =VLOOKUP(A23,v_2024!F:I,3,FALSE) -> 2 | D23: =VLOOKUP(A23,v_2024!F:I,4,FALSE) -> 7.25 | E23: 0 | F23: 0 | G23: =F23/I23 -> 0 | H23: =E23+C23 -> 2 | I23: =F23+D23 -> 7.25 | J23: =VLOOKUP(A23,v_2023!F:I,3,FALSE) -> 13 | K23: =VLOOKUP(A23,v_2023!F:I,4,FALSE) -> 44.07 | L23: =H23-J23 -> -11 | M23: =I23-K23 -> -36.82 | N23: =M23/K23 -> -0.83548899
A24: B01I497WWM | B24: 90.920R | C24: =VLOOKUP(A24,v_2024!F:I,3,FALSE) -> 14 | D24: =VLOOKUP(A24,v_2024!F:I,4,FALSE) -> 260.2 | E24: =VLOOKUP(A24,s_2024!E:G,2,FALSE) -> 534 | F24: =VLOOKUP(A24,s_2024!E:G,3,FALSE) -> 10674.53 | G24: =F24/I24 -> 0.97620426 | H24: =E24+C24 -> 548 | I24: =F24+D24 -> 10934.73 | J24: =VLOOKUP(A24,v_2023!F:I,3,FALSE) -> 2922 | K24: =VLOOKUP(A24,v_2023!F:I,4,FALSE) -> 34319.58 | L24: =H24-J24 -> -2374 | M24: =I24-K24 -> -23384.85 | N24: =M24/K24 -> -0.68138509
A25: B01IHGX2HQ | B25: MD.104 | C25: =VLOOKUP(A25,v_2024!F:I,3,FALSE) -> 14 | D25: =VLOOKUP(A25,v_2024!F:I,4,FALSE) -> 58.41 | E25: 0 | F25: 0 | G25: =F25/I25 -> 0 | H25: =E25+C25 -> 14 | I25: =F25+D25 -> 58.41 | J25: =VLOOKUP(A25,v_2023!F:I,3,FALSE) -> 9 | K25: =VLOOKUP(A25,v_2023!F:I,4,FALSE) -> 37.22 | L25: =H25-J25 -> 5 | M25: =I25-K25 -> 21.19 | N25: =M25/K25 -> 0.56931757
A26: B01II7S968 | B26: MD.217 | C26: 0 | D26: 0 | E26: 0 | F26: 0 | H26: =E26+C26 -> 0 | I26: =F26+D26 -> 0 | J26: =VLOOKUP(A26,v_2023!F:I,3,FALSE) -> 7 | K26: =VLOOKUP(A26,v_2023!F:I,4,FALSE) -> 42.76 | L26: =H26-J26 -> -7 | M26: =I26-K26 -> -42.76 | N26: =M26/K26 -> -1
A27: B01KMJ9OXW | B27: 90.590Y | C27: =VLOOKUP(A27,v_2024!F:I,3,FALSE) -> 1 | D27: =VLOOKUP(A27,v_2024!F:I,4,FALSE) -> 35.32 | E27: =VLOOKUP(A27,s_2024!E:G,2,FALSE) -> 317 | F27: =VLOOKUP(A27,s_2024!E:G,3,FALSE) -> 11062.43 | G27: =F27/I27 -> 0.99681737 | H27: =E27+C27 -> 318 | I27: =F27+D27 -> 11097.75 | J27: =VLOOKUP(A27,v_2023!F:I,3,FALSE) -> 597 | K27: =VLOOKUP(A27,v_2023!F:I,4,FALSE) -> 17144.47 | L27: =H27-J27 -> -279 | M27: =I27-K27 -> -6046.72 | N27: =M27/K27 -> -0.35269215
A28: B01M4O6145 | B28: 90.071 | C28: =VLOOKUP(A28,v_2024!F:I,3,FALSE) -> 37 | D28: =VLOOKUP(A28,v_2024!F:I,4,FALSE) -> 755.17 | E28: 0 | F28: 0 | G28: =F28/I28 -> 0 | H28: =E28+C28 -> 37 | I28: =F28+D28 -> 755.17 | J28: =VLOOKUP(A28,v_2023!F:I,3,FALSE) -> 60 | K28: =VLOOKUP(A28,v_2023!F:I,4,FALSE) -> 1297.24 | L28: =H28-J28 -> -23 | M28: =I28-K28 -> -542.07 | N28: =M28/K28 -> -0.41786408
A29: B01MTSEGF9 | B29: 50.700 | C29: =VLOOKUP(A29,v_2024!F:I,3,FALSE) -> 0 | D29: =VLOOKUP(A29,v_2024!F:I,4,FALSE) -> 0 | E29: =VLOOKUP(A29,s_2024!E:G,2,FALSE) -> 8 | F29: =VLOOKUP(A29,s_2024!E:G,3,FALSE) -> 432.8 | G29: =F29/I29 -> 1 | H29: =E29+C29 -> 8 | I29: =F29+D29 -> 432.8 | J29: =VLOOKUP(A29,v_2023!F:I,3,FALSE) -> 266 | K29: =VLOOKUP(A29,v_2023!F:I,4,FALSE) -> 7610.26 | L29: =H29-J29 -> -258 | M29: =I29-K29 -> -7177.46 | N29: =M29/K29 -> -0.94312941
A30: B01N12PI05 | B30: PE.301 | C30: 0 | D30: 0 | E30: 0 | F30: 0 | H30: =E30+C30 -> 0 | I30: =F30+D30 -> 0 | J30: 0 | K30: 0 | L30: =H30-J30 -> 0 | M30: =I30-K30 -> 0
A31: B06WGS8ZVG | B31: 90.131 | C31: =VLOOKUP(A31,v_2024!F:I,3,FALSE) -> 2 | D31: =VLOOKUP(A31,v_2024!F:I,4,FALSE) -> 27.28 | E31: 0 | F31: 0 | G31: =F31/I31 -> 0 | H31: =E31+C31 -> 2 | I31: =F31+D31 -> 27.28 | J31: =VLOOKUP(A31,v_2023!F:I,3,FALSE) -> 8 | K31: =VLOOKUP(A31,v_2023!F:I,4,FALSE) -> 100.16 | L31: =H31-J31 -> -6 | M31: =I31-K31 -> -72.88 | N31: =M31/K31 -> -0.72763578
A32: B06XPK3BTC | B32: 40.450GO | C32: =VLOOKUP(A32,v_2024!F:I,3,FALSE) -> 2 | D32: =VLOOKUP(A32,v_2024!F:I,4,FALSE) -> 31.65 | E32: 0 | F32: 0 | G32: =F32/I32 -> 0 | H32: =E32+C32 -> 2 | I32: =F32+D32 -> 31.65 | J32: =VLOOKUP(A32,v_2023!F:I,3,FALSE) -> 3 | K32: =VLOOKUP(A32,v_2023!F:I,4,FALSE) -> 48.93 | L32: =H32-J32 -> -1 | M32: =I32-K32 -> -17.28 | N32: =M32/K32 -> -0.35315757
A33: B06XPYSCGJ | B33: 40.939 | C33: =VLOOKUP(A33,v_2024!F:I,3,FALSE) -> 0 | D33: =VLOOKUP(A33,v_2024!F:I,4,FALSE) -> 0 | E33: 0 | F33: 0 | H33: =E33+C33 -> 0 | I33: =F33+D33 -> 0 | J33: =VLOOKUP(A33,v_2023!F:I,3,FALSE) -> 1 | K33: =VLOOKUP(A33,v_2023!F:I,4,FALSE) -> 6.89 | L33: =H33-J33 -> -1 | M33: =I33-K33 -> -6.89 | N33: =M33/K33 -> -1
A34: B06XQ25NLB | B34: 40.220 | C34: 0 | D34: 0 | E34: 0 | F34: 0 | H34: =E34+C34 -> 0 | I34: =F34+D34 -> 0 | J34: 0 | K34: 0 | L34: =H34-J34 -> 0 | M34: =I34-K34 -> 0
A35: B06XSJPGR9 | B35: 50.130 | C35: =VLOOKUP(A35,v_2024!F:I,3,FALSE) -> 0 | D35: =VLOOKUP(A35,v_2024!F:I,4,FALSE) -> 0 | E35: 0 | F35: 0 | H35: =E35+C35 -> 0 | I35: =F35+D35 -> 0 | J35: 0 | K35: 0 | L35: =H35-J35 -> 0 | M35: =I35-K35 -> 0
A36: B06XYMCV3W | B36: 90.485H | C36: =VLOOKUP(A36,v_2024!F:I,3,FALSE) -> 0 | D36: =VLOOKUP(A36,v_2024!F:I,4,FALSE) -> 0 | E36: 0 | F36: 0 | H36: =E36+C36 -> 0 | I36: =F36+D36 -> 0 | J36: 0 | K36: 0 | L36: =H36-J36 -> 0 | M36: =I36-K36 -> 0
A37: B06Y17FS6D | B37: 90.550 | C37: =VLOOKUP(A37,v_2024!F:I,3,FALSE) -> 49 | D37: =VLOOKUP(A37,v_2024!F:I,4,FALSE) -> 1395.95 | E37: 0 | F37: 0 | G37: =F37/I37 -> 0 | H37: =E37+C37 -> 49 | I37: =F37+D37 -> 1395.95 | J37: =VLOOKUP(A37,v_2023!F:I,3,FALSE) -> 586 | K37: =VLOOKUP(A37,v_2023!F:I,4,FALSE) -> 14362.86 | L37: =H37-J37 -> -537 | M37: =I37-K37 -> -12966.91 | N37: =M37/K37 -> -0.90280835
A38: B06Y195DJN | B38: 90.882 | C38: 0 | D38: 0 | E38: =VLOOKUP(A38,s_2024!E:G,2,FALSE) -> 18 | F38: =VLOOKUP(A38,s_2024!E:G,3,FALSE) -> 898.2 | G38: =F38/I38 -> 1 | H38: =E38+C38 -> 18 | I38: =F38+D38 -> 898.2 | J38: 0 | K38: 0 | L38: =H38-J38 -> 18 | M38: =I38-K38 -> 898.2
A39: B06Y1997YH | B39: 90.883 | C39: =VLOOKUP(A39,v_2024!F:I,3,FALSE) -> 11 | D39: =VLOOKUP(A39,v_2024!F:I,4,FALSE) -> 685.1 | E39: 0 | F39: 0 | G39: =F39/I39 -> 0 | H39: =E39+C39 -> 11 | I39: =F39+D39 -> 685.1 | J39: =VLOOKUP(A39,v_2023!F:I,3,FALSE) -> 65 | K39: =VLOOKUP(A39,v_2023!F:I,4,FALSE) -> 3560.59 | L39: =H39-J39 -> -54 | M39: =I39-K39 -> -2875.49 | N39: =M39/K39 -> -0.80758807
A40: B06Y1P6DPZ | B40: VE.112 | C40: 0 | D40: 0 | E40: 0 | F40: 0 | H40: =E40+C40 -> 0 | I40: =F40+D40 -> 0 | J40: 0 | K40: 0 | L40: =H40-J40 -> 0 | M40: =I40-K40 -> 0
...

Sheet complessivo
A1: ASIN | B1: SKU | C1: Ordini Vendor 24 | D1: Valori ordini Vendor 24 | E1: Ordini Seller 24 | F1: Valori ordini Seller 24 | G1: % seller / totale | H1: Ordini Complessivi 24 | I1: Valori ordini Complessivi 24 | J1: Ordini Vendor 23 | K1: Valori ordini Vendor 23 | L1: Differenza Ordini | M1: Differenza Valore | N1: Differenza Valore %
A2: B0050IHH4E | B2: 40.979 | C2: 1183 | D2: 16822.21 | E2: =VLOOKUP(A2,s_2024!A:C,2,FALSE) -> 3 | F2: =VLOOKUP(A2,s_2024!A:C,3,FALSE) -> 60.7 | G2: =F2/I2 -> 0.0035953517 | H2: =E2+C2 -> 1186 | I2: =F2+D2 -> 16882.91 | J2: =VLOOKUP(A2,v_2023!A:D,3,FALSE) -> 14 | K2: =VLOOKUP(A2,v_2023!A:D,4,FALSE) -> 182.42 | L2: =H2-J2 -> 1172 | M2: =I2-K2 -> 16700.49 | N2: =M2/K2 -> 91.549666
A3: B009O92WU4 | B3: 40.999 | C3: 1 | D3: 5.03 | E3: 0 | F3: 0 | G3: =F3/I3 -> 0 | H3: =E3+C3 -> 1 | I3: =F3+D3 -> 5.03 | J3: 0 | K3: 0 | L3: =H3-J3 -> 1 | M3: =I3-K3 -> 5.03
A4: B00BH202XK | B4: 40.808A | C4: 10 | D4: 127.35 | E4: 0 | F4: 0 | G4: =F4/I4 -> 0 | H4: =E4+C4 -> 10 | I4: =F4+D4 -> 127.35 | J4: =VLOOKUP(A4,v_2023!A:D,3,FALSE) -> 1 | K4: =VLOOKUP(A4,v_2023!A:D,4,FALSE) -> 20.59 | L4: =H4-J4 -> 9 | M4: =I4-K4 -> 106.76 | N4: =M4/K4 -> 5.1850413
A5: B00CMAD2FG | B5: HK-NV009W | C5: 1 | D5: 15.18 | E5: 0 | F5: 0 | G5: =F5/I5 -> 0 | H5: =E5+C5 -> 1 | I5: =F5+D5 -> 15.18 | J5: =VLOOKUP(A5,v_2023!A:D,3,FALSE) -> 2 | K5: =VLOOKUP(A5,v_2023!A:D,4,FALSE) -> 34.18 | L5: =H5-J5 -> -1 | M5: =I5-K5 -> -19 | N5: =M5/K5 -> -0.55588063
A6: B00EYDRS1I | B6: 90.349 | C6: 48 | D6: 271.81 | E6: 0 | F6: 0 | G6: =F6/I6 -> 0 | H6: =E6+C6 -> 48 | I6: =F6+D6 -> 271.81 | J6: =VLOOKUP(A6,v_2023!A:D,3,FALSE) -> 119 | K6: =VLOOKUP(A6,v_2023!A:D,4,FALSE) -> 828.55 | L6: =H6-J6 -> -71 | M6: =I6-K6 -> -556.74 | N6: =M6/K6 -> -0.67194496
A7: B00FFBFVG2 | B7: 40.100 | C7: 0 | D7: 0 | E7: 0 | F7: 0 | H7: =E7+C7 -> 0 | I7: =F7+D7 -> 0 | J7: =VLOOKUP(A7,v_2023!A:D,3,FALSE) -> 13 | K7: =VLOOKUP(A7,v_2023!A:D,4,FALSE) -> 104.24 | L7: =H7-J7 -> -13 | M7: =I7-K7 -> -104.24 | N7: =M7/K7 -> -1
A8: B00FMZ2VW8 | B8: HK-HQ601C PINK | C8: 0 | D8: 0 | E8: 0 | F8: 0 | H8: =E8+C8 -> 0 | I8: =F8+D8 -> 0 | J8: 0 | K8: 0 | L8: =H8-J8 -> 0 | M8: =I8-K8 -> 0
A9: B00L5GPWFG | B9: 40.120 | C9: 6 | D9: 147.9 | E9: 0 | F9: 0 | G9: =F9/I9 -> 0 | H9: =E9+C9 -> 6 | I9: =F9+D9 -> 147.9 | J9: =VLOOKUP(A9,v_2023!A:D,3,FALSE) -> 20 | K9: =VLOOKUP(A9,v_2023!A:D,4,FALSE) -> 325.84 | L9: =H9-J9 -> -14 | M9: =I9-K9 -> -177.94 | N9: =M9/K9 -> -0.54609624
A10: B00L5H5KUW | B10: 40.121 | C10: 275 | D10: 5023.29 | E10: 0 | F10: 0 | G10: =F10/I10 -> 0 | H10: =E10+C10 -> 275 | I10: =F10+D10 -> 5023.29 | J10: =VLOOKUP(A10,v_2023!A:D,3,FALSE) -> 573 | K10: =VLOOKUP(A10,v_2023!A:D,4,FALSE) -> 9291.39 | L10: =H10-J10 -> -298 | M10: =I10-K10 -> -4268.1 | N10: =M10/K10 -> -0.45936076
A11: B00NSNZSLM | B11: 90.602 | C11: 1 | D11: 20.41 | E11: =VLOOKUP(A11,s_2024!A:C,2,FALSE) -> 48 | F11: =VLOOKUP(A11,s_2024!A:C,3,FALSE) -> 1440.2 | G11: =F11/I11 -> 0.98602639 | H11: =E11+C11 -> 49 | I11: =F11+D11 -> 1460.61 | J11: =VLOOKUP(A11,v_2023!A:D,3,FALSE) -> 400 | K11: =VLOOKUP(A11,v_2023!A:D,4,FALSE) -> 8213.58 | L11: =H11-J11 -> -351 | M11: =I11-K11 -> -6752.97 | N11: =M11/K11 -> -0.82217133
A12: B00OKE4RTM | B12: 90.386 | C12: 2 | D12: 98.08 | E12: 0 | F12: 0 | G12: =F12/I12 -> 0 | H12: =E12+C12 -> 2 | I12: =F12+D12 -> 98.08 | J12: =VLOOKUP(A12,v_2023!A:D,3,FALSE) -> 8 | K12: =VLOOKUP(A12,v_2023!A:D,4,FALSE) -> 425.01 | L12: =H12-J12 -> -6 | M12: =I12-K12 -> -326.93 | N12: =M12/K12 -> -0.76922896
A13: B00YH3FRV8 | B13: 40.998 | C13: 1 | D13: 7.43 | E13: 0 | F13: 0 | G13: =F13/I13 -> 0 | H13: =E13+C13 -> 1 | I13: =F13+D13 -> 7.43 | J13: 0 | K13: 0 | L13: =H13-J13 -> 1 | M13: =I13-K13 -> 7.43
A14: B011LFM60E | B14: 40.948T | C14: 2 | D14: 12.96 | E14: 0 | F14: 0 | G14: =F14/I14 -> 0 | H14: =E14+C14 -> 2 | I14: =F14+D14 -> 12.96 | J14: 0 | K14: 0 | L14: =H14-J14 -> 2 | M14: =I14-K14 -> 12.96
A15: B011LFVLW8 | B15: 90.620 | C15: 19 | D15: 686.19 | E15: 0 | F15: 0 | G15: =F15/I15 -> 0 | H15: =E15+C15 -> 19 | I15: =F15+D15 -> 686.19 | J15: =VLOOKUP(A15,v_2023!A:D,3,FALSE) -> 99 | K15: =VLOOKUP(A15,v_2023!A:D,4,FALSE) -> 2832.39 | L15: =H15-J15 -> -80 | M15: =I15-K15 -> -2146.2 | N15: =M15/K15 -> -0.75773463
A16: B017IUJA50 | B16: 90.920G | C16: 15 | D16: 209.45 | E16: 0 | F16: 0 | G16: =F16/I16 -> 0 | H16: =E16+C16 -> 15 | I16: =F16+D16 -> 209.45 | J16: =VLOOKUP(A16,v_2023!A:D,3,FALSE) -> 1584 | K16: =VLOOKUP(A16,v_2023!A:D,4,FALSE) -> 20644.51 | L16: =H16-J16 -> -1569 | M16: =I16-K16 -> -20435.06 | N16: =M16/K16 -> -0.98985445
A17: B01CHW1L88 | B17: PE.001 | C17: 1 | D17: 15.05 | E17: 0 | F17: 0 | G17: =F17/I17 -> 0 | H17: =E17+C17 -> 1 | I17: =F17+D17 -> 15.05 | J17: 0 | K17: 0 | L17: =H17-J17 -> 1 | M17: =I17-K17 -> 15.05
A18: B01CNX6T10 | B18: PE.165 | C18: 1 | D18: 18.03 | E18: 0 | F18: 0 | G18: =F18/I18 -> 0 | H18: =E18+C18 -> 1 | I18: =F18+D18 -> 18.03 | J18: 0 | K18: 0 | L18: =H18-J18 -> 1 | M18: =I18-K18 -> 18.03
A19: B01CNX6UIM | B19: PE.300 | C19: 3 | D19: 17.19 | E19: 0 | F19: 0 | G19: =F19/I19 -> 0 | H19: =E19+C19 -> 3 | I19: =F19+D19 -> 17.19 | J19: 0 | K19: 0 | L19: =H19-J19 -> 3 | M19: =I19-K19 -> 17.19
A20: B01CNX6Z78 | B20: 90.820 | C20: 9 | D20: 199.98 | E20: 0 | F20: 0 | G20: =F20/I20 -> 0 | H20: =E20+C20 -> 9 | I20: =F20+D20 -> 199.98 | J20: =VLOOKUP(A20,v_2023!A:D,3,FALSE) -> 75 | K20: =VLOOKUP(A20,v_2023!A:D,4,FALSE) -> 1575.73 | L20: =H20-J20 -> -66 | M20: =I20-K20 -> -1375.75 | N20: =M20/K20 -> -0.87308739
A21: B01CNX704K | B21: 90.825 | C21: 1 | D21: 22.97 | E21: =VLOOKUP(A21,s_2024!A:C,2,FALSE) -> 6 | F21: =VLOOKUP(A21,s_2024!A:C,3,FALSE) -> 281.4 | G21: =F21/I21 -> 0.92453264 | H21: =E21+C21 -> 7 | I21: =F21+D21 -> 304.37 | J21: =VLOOKUP(A21,v_2023!A:D,3,FALSE) -> 8 | K21: =VLOOKUP(A21,v_2023!A:D,4,FALSE) -> 319.22 | L21: =H21-J21 -> -1 | M21: =I21-K21 -> -14.85 | N21: =M21/K21 -> -0.046519642
A22: B01CNX71NA | B22: 90.871 | C22: 12 | D22: 1075.69 | E22: 0 | F22: 0 | G22: =F22/I22 -> 0 | H22: =E22+C22 -> 12 | I22: =F22+D22 -> 1075.69 | J22: =VLOOKUP(A22,v_2023!A:D,3,FALSE) -> 13 | K22: =VLOOKUP(A22,v_2023!A:D,4,FALSE) -> 973.92 | L22: =H22-J22 -> -1 | M22: =I22-K22 -> 101.77 | N22: =M22/K22 -> 0.10449524
A23: B01HM47LF8 | B23: MD.004 | C23: 3 | D23: 10.49 | E23: 0 | F23: 0 | G23: =F23/I23 -> 0 | H23: =E23+C23 -> 3 | I23: =F23+D23 -> 10.49 | J23: =VLOOKUP(A23,v_2023!A:D,3,FALSE) -> 13 | K23: =VLOOKUP(A23,v_2023!A:D,4,FALSE) -> 44.07 | L23: =H23-J23 -> -10 | M23: =I23-K23 -> -33.58 | N23: =M23/K23 -> -0.76196959
A24: B01I497WWM | B24: 90.920R | C24: 23 | D24: 410.8 | E24: =VLOOKUP(A24,s_2024!A:C,2,FALSE) -> 534 | F24: =VLOOKUP(A24,s_2024!A:C,3,FALSE) -> 10674.53 | G24: =F24/I24 -> 0.96294201 | H24: =E24+C24 -> 557 | I24: =F24+D24 -> 11085.33 | J24: =VLOOKUP(A24,v_2023!A:D,3,FALSE) -> 3002 | K24: =VLOOKUP(A24,v_2023!A:D,4,FALSE) -> 35627.11 | L24: =H24-J24 -> -2445 | M24: =I24-K24 -> -24541.78 | N24: =M24/K24 -> -0.68885127
A25: B01IHGX2HQ | B25: MD.104 | C25: 14 | D25: 58.41 | E25: 0 | F25: 0 | G25: =F25/I25 -> 0 | H25: =E25+C25 -> 14 | I25: =F25+D25 -> 58.41 | J25: =VLOOKUP(A25,v_2023!A:D,3,FALSE) -> 9 | K25: =VLOOKUP(A25,v_2023!A:D,4,FALSE) -> 37.22 | L25: =H25-J25 -> 5 | M25: =I25-K25 -> 21.19 | N25: =M25/K25 -> 0.56931757
A26: B01II7S968 | B26: MD.217 | C26: 6 | D26: 36.93 | E26: 0 | F26: 0 | G26: =F26/I26 -> 0 | H26: =E26+C26 -> 6 | I26: =F26+D26 -> 36.93 | J26: =VLOOKUP(A26,v_2023!A:D,3,FALSE) -> 9 | K26: =VLOOKUP(A26,v_2023!A:D,4,FALSE) -> 54.1 | L26: =H26-J26 -> -3 | M26: =I26-K26 -> -17.17 | N26: =M26/K26 -> -0.31737523
A27: B01KMJ9OXW | B27: 90.590Y | C27: 9 | D27: 267.96 | E27: =VLOOKUP(A27,s_2024!A:C,2,FALSE) -> 394 | F27: =VLOOKUP(A27,s_2024!A:C,3,FALSE) -> 14503.53 | G27: =F27/I27 -> 0.98185965 | H27: =E27+C27 -> 403 | I27: =F27+D27 -> 14771.49 | J27: =VLOOKUP(A27,v_2023!A:D,3,FALSE) -> 1143 | K27: =VLOOKUP(A27,v_2023!A:D,4,FALSE) -> 33655.87 | L27: =H27-J27 -> -740 | M27: =I27-K27 -> -18884.38 | N27: =M27/K27 -> -0.56110212
A28: B01M4O6145 | B28: 90.071 | C28: 66 | D28: 1357.87 | E28: 0 | F28: 0 | G28: =F28/I28 -> 0 | H28: =E28+C28 -> 66 | I28: =F28+D28 -> 1357.87 | J28: =VLOOKUP(A28,v_2023!A:D,3,FALSE) -> 72 | K28: =VLOOKUP(A28,v_2023!A:D,4,FALSE) -> 1646.1 | L28: =H28-J28 -> -6 | M28: =I28-K28 -> -288.23 | N28: =M28/K28 -> -0.17509872
A29: B01MTSEGF9 | B29: 50.700 | C29: 0 | D29: 0 | E29: =VLOOKUP(A29,s_2024!A:C,2,FALSE) -> 8 | F29: =VLOOKUP(A29,s_2024!A:C,3,FALSE) -> 432.8 | G29: =F29/I29 -> 1 | H29: =E29+C29 -> 8 | I29: =F29+D29 -> 432.8 | J29: =VLOOKUP(A29,v_2023!A:D,3,FALSE) -> 266 | K29: =VLOOKUP(A29,v_2023!A:D,4,FALSE) -> 7610.26 | L29: =H29-J29 -> -258 | M29: =I29-K29 -> -7177.46 | N29: =M29/K29 -> -0.94312941
A30: B01N12PI05 | B30: PE.301 | C30: 11 | D30: 45.74 | E30: 0 | F30: 0 | G30: =F30/I30 -> 0 | H30: =E30+C30 -> 11 | I30: =F30+D30 -> 45.74 | J30: 0 | K30: 0 | L30: =H30-J30 -> 11 | M30: =I30-K30 -> 45.74
A31: B06WGS8ZVG | B31: 90.131 | C31: 2 | D31: 27.28 | E31: 0 | F31: 0 | G31: =F31/I31 -> 0 | H31: =E31+C31 -> 2 | I31: =F31+D31 -> 27.28 | J31: =VLOOKUP(A31,v_2023!A:D,3,FALSE) -> 8 | K31: =VLOOKUP(A31,v_2023!A:D,4,FALSE) -> 100.16 | L31: =H31-J31 -> -6 | M31: =I31-K31 -> -72.88 | N31: =M31/K31 -> -0.72763578
A32: B06XPK3BTC | B32: 40.450GO | C32: 4 | D32: 51.29 | E32: 0 | F32: 0 | G32: =F32/I32 -> 0 | H32: =E32+C32 -> 4 | I32: =F32+D32 -> 51.29 | J32: =VLOOKUP(A32,v_2023!A:D,3,FALSE) -> 6 | K32: =VLOOKUP(A32,v_2023!A:D,4,FALSE) -> 98.39 | L32: =H32-J32 -> -2 | M32: =I32-K32 -> -47.1 | N32: =M32/K32 -> -0.47870719
A33: B06XPYSCGJ | B33: 40.939 | C33: 36 | D33: 3.64 | E33: 0 | F33: 0 | G33: =F33/I33 -> 0 | H33: =E33+C33 -> 36 | I33: =F33+D33 -> 3.64 | J33: =VLOOKUP(A33,v_2023!A:D,3,FALSE) -> 17 | K33: =VLOOKUP(A33,v_2023!A:D,4,FALSE) -> 72.96 | L33: =H33-J33 -> 19 | M33: =I33-K33 -> -69.32 | N33: =M33/K33 -> -0.95010965
A34: B06XQ25NLB | B34: 40.220 | C34: 0 | D34: 0 | E34: 0 | F34: 0 | H34: =E34+C34 -> 0 | I34: =F34+D34 -> 0 | J34: =VLOOKUP(A34,v_2023!A:D,3,FALSE) -> 0 | K34: =VLOOKUP(A34,v_2023!A:D,4,FALSE) -> 0 | L34: =H34-J34 -> 0 | M34: =I34-K34 -> 0
A35: B06XSJPGR9 | B35: 50.130 | C35: 0 | D35: 0 | E35: 0 | F35: 0 | H35: =E35+C35 -> 0 | I35: =F35+D35 -> 0 | J35: 0 | K35: 0 | L35: =H35-J35 -> 0 | M35: =I35-K35 -> 0
A36: B06XYMCV3W | B36: 90.485H | C36: 0 | D36: 0 | E36: 0 | F36: 0 | H36: =E36+C36 -> 0 | I36: =F36+D36 -> 0 | J36: 0 | K36: 0 | L36: =H36-J36 -> 0 | M36: =I36-K36 -> 0
