Workbook

Sheet vendor_02_2023
A1: Programma=[Retail] | B1: Visualizza per=[ASIN] | C1: Paesi=[IT;ES;DE;FR;UK;NL;SE] | D1: Aziende=[Beper s.r.l.;Beper s.r.l.;Beper s.r.l. - DE Account;Beper s.r.l. - FR Account;Beper s.r.l. - GB Account;Beper s.r.l. - NL Account;Beper s.r.l. - SE Account] | E1: Lingua=[it_IT] | F1: Valuta=[EUR] | G1: Intervallo report=[Mese] | H1: Intervallo di visualizzazione=[01/02/23 - 28/02/23] | I1: Report aggiornato=[01/04/24]
A2: ASIN | B2: Numero del modello | C2: Codice marketplace | D2: Ricavi ordini | E2: Unità ordinate | F2: Ricavi spedizioni | G2: COGS spedizioni | H2: Unità spedite | I2: Resi cliente
A3: B01I497WWM | B3: 90.920R | C3: IT | D3: 30066.66 | E3: 2222 | F3: 30676.77 | G3: 19018.52 | H3: 2275 | I3: 198
A4: B07ZJQTGG8 | B4: 50.245 | C4: IT | D4: 25188.39 | E4: 2063 | F4: 25322.7 | G4: 16406.9 | H4: 2074 | I4: 71
A5: B096MX229M | B5: P102ROB050 | C5: DE | D5: 17654.29 | E5: 1419 | F5: 17469.22 | G5: 10791.6 | H5: 1405 | I5: 125
A6: B095PQJGKX | B6: C107UTT002 | C6: ES | D6: 15786.08 | E6: 1930 | F6: 15794.26 | G6: 9173.44 | H6: 1931 | I6: 56
A7: B08GY7286R | B7: P203TFO001 | C7: IT | D7: 14353 | E7: 748 | F7: 14939.17 | G7: 7779.98 | H7: 780 | I7: 62
A8: B08485QRVZ | B8: BC.261 | C8: IT | D8: 13551.02 | E8: 664 | F8: 13755.12 | G8: 11654.4 | H8: 674 | I8: 35
A9: B096MX229M | B9: P102ROB050 | C9: FR | D9: 12664.05 | E9: 1133 | F9: 12592.35 | G9: 8600.4 | H9: 1124 | I9: 44
A10: B01KMJ9OXW | B10: 90.590Y | C10: FR | D10: 11559.69 | E10: 349 | F10: 11593.14 | G10: 6915 | H10: 350 | I10: 31
A11: B079SB5VJZ | B11: 50451 | C11: IT | D11: 11019.9 | E11: 337 | F11: 10333.2 | G11: 10599.59 | H11: 316 | I11: 15
A12: B00NSNZSLM | B12: 90.602 | C12: IT | D12: 10511.15 | E12: 515 | F12: 10347.87 | G12: 8617.51 | H12: 507 | I12: 29
A13: B085JJ8RC6 | B13: BB.050 | C13: IT | D13: 10327.56 | E13: 846 | F13: 10061.04 | G13: 8343.53 | H13: 824 | I13: 105
A14: B0757TJRR9 | B14: 40.500 | C14: IT | D14: 10284.5 | E14: 382 | F14: 10343.36 | G14: 7114.91 | H14: 384 | I14: 30
... A67: B08GY7286R | B67: P203TFO001 | C67: DE | D67: 2244.48 | E67: 168 | F67: 2191.04 | G67: 1727.82 | H67: 164 | I67: 14
A68: B00L5H5KUW | B68: 40.121 | C68: ES | D68: 2229.19 | E68: 122 | F68: 2346.22 | G68: 1641.17 | H68: 130
A69: B0B39H1Z8J | B69: C106CAS001 | C69: FR | D69: 2227.5 | E69: 270 | F69: 2227.5 | G69: 1657.8 | H69: 270 | I69: 2
A70: B085JJJR91 | B70: BC.210 | C70: FR | D70: 2151.92 | E70: 74 | F70: 2268.24 | G70: 2250.48 | H70: 78 | I70: 4
A71: B07KYWNC7Z | B71: 40.405 | C71: IT | D71: 2118.97 | E71: 108 | F71: 2022.94 | G71: 1587.62 | H71: 103 | I71: 5
A72: B08GS7XW73 | B72: P204FER250 | C72: IT | D72: 2111.81 | E72: 131 | F72: 1927.84 | G72: 1516.72 | H72: 119 | I72: 8
A73: B076QFRRZ5 | B73: 40.931 | C73: IT | D73: 2062.9 | E73: 149 | F73: 2063.44 | G73: 1003.06 | H73: 149 | I73: 24
A74: B08GY7286R | B74: P203TFO001 | C74: FR | D74: 2061.71 | E74: 114 | F74: 2130.38 | G74: 1230.15 | H74: 118 | I74: 12
A75: B017IUJA50 | B75: 90.920G | C75: FR | D75: 1921.25 | E75: 145 | F75: 1828.5 | G75: 1175.9 | H75: 138 | I75: 12
A76: B09BD8BG34 | B76: P301PIS001 | C76: IT | D76: 1913.17 | E76: 181 | F76: 1860.32 | G76: 1489.62 | H76: 176 | I76: 6
A77: B07YZZZVXP | B77: MD.404 | C77: DE | D77: 1897.28 | E77: 30 | F77: 1961.2 | G77: 1449.08 | H77: 31 | I77: 14
A78: B08485QRVZ | B78: BC.261 | C78: FR | D78: 1895.99 | E78: 60 | F78: 1988.83 | G78: 1083 | H78: 63 | I78: 1
A79: B00FAJUDU8 | B79: 40.967N | C79: IT | D79: 1877.72 | E79: 92 | F79: 1857.31 | G79: 1378.4 | H79: 91 | I79: 8
A80: B0BD83RNDG | B80: C106CAS002 | C80: IT | D80: 1839.18 | E80: 174 | F80: 1849.75 | G80: 1524.04 | H80: 175 | I80: 4
... A82: B07N4C3H3V | B82: 40.405 | C82: DE | D82: 1768.29 | E82: 177 | F82: 1728.29 | G82: 1067.4 | H82: 173 | I82: 3
A83: B085JJJR91 | B83: BC.210 | C83: DE | D83: 1743.56 | E83: 52 | F83: 1710.03 | G83: 1463.1 | H83: 51
A84: B08FDYW72J | B84: P101CUD100 | C84: DE | D84: 1657.83 | E84: 47 | F84: 1650.19 | G84: 835.8 | H84: 47 | I84: 12
A85: B00FAJUDU8 | B85: 40.967N | C85: FR | D85: 1618.5 | E85: 78 | F85: 1597.75 | G85: 1017.46 | H85: 77 | I85: 6
A86: B0BJ2TBPJW | B86: C206UTI004 | C86: IT | D86: 1615.55 | E86: 395 | F86: 1627.82 | G86: 1128.54 | H86: 398 | I86: 1
A87: B09KYD9JGY | B87: P301PIS100 | C87: IT | D87: 1591.98 | E87: 78 | F87: 1530.75 | G87: 1151.39 | H87: 75 | I87: 19
A88: B09KYD9JGY | B88: P301PIS100 | C88: FR | D88: 1556.25 | E88: 75 | F88: 1535.5 | G88: 1134.69 | H88: 74 | I88: 9
A89: B08FMLPKY9 | B89: P201UTP004 | C89: IT | D89: 1552.45 | E89: 83 | F89: 1613.82 | G89: 812.11 | H89: 86 | I89: 3
A90: B09KYD9JGY | B90: P301PIS100 | C90: ES | D90: 1510.96 | E90: 76 | F90: 1533.2 | G90: 1191.42 | H90: 77 | I90: 15
A91: B07TQVD94L | B91: BP.690 | C91: IT | D91: 1470.6 | E91: 60 | F91: 1544.13 | G91: 1709.1 | H91: 63 | I91: 1
A92: B08LZN1PWY | B92: P101TEM001 | C92: ES | D92: 1444.25 | E92: 25 | F92: 1444.25 | G92: 939.85 | H92: 25
A93: B07BB2DQ4V | B93: BT.150Y | C93: DE | D93: 1412.76 | E93: 47 | F93: 1387.05 | G93: 884.71 | H93: 46 | I93: 3
...

Sheet vendor_02_2024
A1: ASIN | B1: Numero del modello | C1: Codice marketplace | D1: Ricavi ordini | E1: Unità ordinate | F1: Ricavi spedizioni | G1: COGS spedizioni | H1: Unità spedite | I1: Resi cliente
A2: B0CPFRMPTM | B2: P101CAF001 | C2: IT | D2: 9465.85 | E2: 382 | F2: 9375.1 | G2: 10043.5 | H2: 379 | I2: 3
A3: B0050IHH4E | B3: 40.979 | C3: DE | D3: 9135.52 | E3: 646 | F3: 8823.12 | G3: 5691.84 | H3: 624 | I3: 16
A4: B0CC5QZ9CJ | B4: C206UTI006 | C4: FR | D4: 8784.54 | E4: 1319 | F4: 8897.76 | G4: 5409.39 | H4: 1336 | I4: 8
A5: B07ZJQTGG8 | B5: 50.245 | C5: IT | D5: 8094.4 | E5: 638 | F5: 8192.08 | G5: 5445.78 | H5: 646 | I5: 20
A6: B00L5H5KUW | B6: 40.121 | C6: IT | D6: 7577.95 | E6: 424 | F6: 7019.45 | G6: 4695.43 | H6: 392 | I6: 2
A7: B0BBH12BYN | B7: P101COS001 | C7: IT | D7: 7189.97 | E7: 83 | F7: 6924.69 | G7: 4687.06 | H7: 80 | I7: 14
A8: B0CHF7YW6B | B8: P203PAN010 | C8: IT | D8: 6394.47 | E8: 253 | F8: 6364.71 | G8: 4680.5 | H8: 253 | I8: 55
A9: B06Y17FS6D | B9: 90.550 | C9: IT | D9: 5475.75 | E9: 197 | F9: 5406.6 | G9: 4508 | H9: 196 | I9: 7
A10: B0CHFQXMZX | B10: P203PAN001 | C10: IT | D10: 4902.9 | E10: 354 | F10: 4930.6 | G10: 3382 | H10: 356 | I10: 7
A11: B0050IHH4E | B11: 40.979 | C11: IT | D11: 4876.26 | E11: 311 | F11: 4736.87 | G11: 3022.06 | H11: 302 | I11: 18
A12: B09146GTKW | B12: P302VIS002 | C12: IT | D12: 4828.53 | E12: 421 | F12: 4862.97 | G12: 2544 | H12: 424 | I12: 33
A13: B017IUJA50 | B13: 90.920G | C13: IT | D13: 4464.61 | E13: 274 | F13: 4549.25 | G13: 2329.65 | H13: 279 | I13: 11
... A28: B0BNNH9RZQ | B28: P302VIS060 | C28: IT | D28: 1835.74 | E28: 165 | F28: 1824.24 | G28: 1190.76 | H28: 164 | I28: 19
A29: B07JGVMFY1 | B29: BP.581 | C29: FR | D29: 1820.24 | E29: 122 | F29: 1760.56 | G29: 1188.26 | H29: 118
A30: B06Y1997YH | B30: 90.883 | C30: IT | D30: 1743.72 | E30: 30 | F30: 1571.82 | G30: 1130.94 | H30: 27 | I30: 2
A31: B0BTHSH5MK | B31: C103ACC001 | C31: IT | D31: 1742.62 | E31: 188 | F31: 1807.11 | G31: 1085.4 | H31: 197 | I31: 1
A32: B073B67PLQ | B32: 90.884 | C32: IT | D32: 1715.37 | E32: 21 | F32: 1716.83 | G32: 1385.5 | H32: 21 | I32: 2
A33: B0BVZG7FPY | B33: P206VEN600 | C33: IT | D33: 1665.99 | E33: 41 | F33: 990.13 | G33: 649.95 | H33: 25 | I33: 1
A34: B0BNNH9RZQ | B34: P302VIS060 | C34: DE | D34: 1661.52 | E34: 132 | F34: 1749.16 | G34: 1054.99 | H34: 139 | I34: 26
A35: B08L9D9KR9 | B35: P202VAL001 | C35: IT | D35: 1604.4 | E35: 28 | F35: 1489.8 | G35: 1170 | H35: 26 | I35: 2
A36: B0CFB71DMN | B36: C203PUL004 | C36: IT | D36: 1566.85 | E36: 277 | F36: 1426.09 | G36: 718.8 | H36: 251 | I36: 2
A37: B07ZJMFB3R | B37: BC.510 | C37: IT | D37: 1547.1 | E37: 27 | F37: 1547.1 | G37: 1252.8 | H37: 27
A38: B0BD83RNDG | B38: C106CAS002 | C38: FR | D38: 1429.75 | E38: 133 | F38: 1408.25 | G38: 988.43 | H38: 131 | I38: 2
A39: B0BNNH9RZQ | B39: P302VIS060 | C39: ES | D39: 1424.94 | E39: 114 | F39: 1476.96 | G39: 824.42 | H39: 118 | I39: 32
A40: B0B8DLSNJF | B40: P302VIS050 | C40: IT | D40: 1419.28 | E40: 88 | F40: 1052.15 | G40: 913.9 | H40: 65
A41: B08FDYW72J | B41: P101CUD100 | C41: DE | D41: 1414.8 | E41: 45 | F41: 1420.75 | G41: 911.25 | H41: 45 | I41: 4
A42: B0CHF7YW6B | B42: P203PAN010 | C42: FR | D42: 1343.58 | E42: 49 | F42: 1316.16 | G42: 888 | H42: 48 | I42: 17
A43: B07SSLRCT6 | B43: BP.304 | C43: IT | D43: 1343.45 | E43: 97 | F43: 1371.15 | G43: 939.25 | H43: 99 | I43: 3
A44: B0050IHH4E | B44: 40.979 | C44: FR | D44: 1311.73 | E44: 80 | F44: 1298.23 | G44: 732.37 | H44: 79 | I44: 1
A45: B08L9D9KR9 | B45: P202VAL001 | C45: DE | D45: 1292.31 | E45: 20 | F45: 1634.77 | G45: 1125 | H45: 25
A46: B09B47S644 | B46: P101CUD501 | C46: FR | D46: 1279.52 | E46: 44 | F46: 1279.52 | G46: 908.6 | H46: 44 | I46: 3
A47: B0BNNH9RZQ | B47: P302VIS060 | C47: FR | D47: 1266.84 | E47: 102 | F47: 1254.42 | G47: 767.33 | H47: 101 | I47: 4
A48: B09B47S644 | B48: P101CUD501 | C48: DE | D48: 1264.5 | E48: 42 | F48: 1266.54 | G48: 877.8 | H48: 42 | I48: 5
A49: B076QCMZX1 | B49: 40.821 | C49: IT | D49: 1257.63 | E49: 103 | F49: 1221 | G49: 849.15 | H49: 100 | I49: 7
A50: B07Q38Z7CK | B50: BC.060 | C50: IT | D50: 1245.32 | E50: 59 | F50: 1224.91 | G50: 870 | H50: 58
A51: B0B2F48ZMP | B51: P102GEL100 | C51: FR | D51: 1159.67 | E51: 30 | F51: 1121.84 | G51: 867.68 | H51: 29 | I51: 2
A52: B09NBXYF5J | B52: P101TOS002 | C52: FR | D52: 1124.64 | E52: 50 | F52: 562.32 | G52: 320.75 | H52: 25
A53: B0050IHH4E | B53: 40.979 | C53: ES | D53: 1087.35 | E53: 80 | F53: 901.68 | G53: 652.98 | H53: 66 | I53: 4
A54: B0CHWMFNNT | B54: P202ASP250 | C54: FR | D54: 1081.08 | E54: 26 | F54: 1164.24 | G54: 840 | H54: 28
...

Sheet seller_02_2024
A1: amazon-order-id | B1: merchant-order-id | C1: purchase-date | D1: last-updated-date | E1: order-status | F1: fulfillment-channel | G1: sales-channel | H1: order-channel | I1: url | J1: ship-service-level | K1: product-name | L1: sku | M1: asin | N1: item-status | O1: quantity | P1: currency | Q1: item-price | R1: item-tax | S1: shipping-price | T1: shipping-tax | U1: gift-wrap-price | V1: gift-wrap-tax | W1: item-promotion-discount | X1: ship-promotion-discount | Y1: ship-city | Z1: ship-state | AA1: ship-postal-code | AB1: ship-country | AC1: promotion-ids | AD1: buyer-company-name | AE1: buyer-cst-number | AF1: buyer-vat-number | AG1: buyer-tax-registration-id | AH1: buyer-tax-registration-country | AI1: buyer-tax-registration-type
A2: 405-5748540-3173901 | B2: 405-5748540-3173901 | C2: 2024-02-29T20:28:36+00:00 | D2: 2024-03-04T01:15:21+00:00 | E2: Shipped | F2: Amazon | G2: Amazon.fr | J2: Standard | K2: BEPER BT.710Y Crêpière électrique avec poignée, 800 W, plaque en aluminium avec revêtement antiadhésif, rouge | L2: BT.710Y_FBA | M2: B07NQ2VYGD | N2: Shipped | O2: 1 | P2: EUR | Q2: 39.9 | R2: 6.65 | S2: 0.83 | X2: 0.83 | Y2: Bagneux | AA2: 92220 | AB2: FR | AC2: Free Shipping 2017/10/17 17-17-37-677
A3: 171-3315909-6981140 | B3: 171-3315909-6981140 | C3: 2024-02-29T20:20:43+00:00 | D3: 2024-03-01T16:30:40+00:00 | E3: Shipped | F3: Amazon | G3: Amazon.fr | J3: Standard | K3: BEPER BT.710Y Crêpière électrique avec poignée, 800 W, plaque en aluminium avec revêtement antiadhésif, rouge | L3: BT.710Y_FBA | M3: B07NQ2VYGD | N3: Shipped | O3: 1 | P3: EUR | Q3: 39.9 | R3: 6.65 | S3: 1.67 | X3: 1.67 | Y3: Vaux le pénil | AA3: 77000 | AB3: FR | AC3: Free Shipping 2017/10/17 17-17-37-677
A4: 404-7228953-0182728 | B4: 404-7228953-0182728 | C4: 2024-02-29T19:06:50+00:00 | D4: 2024-03-01T10:56:11+00:00 | E4: Shipped | F4: Amazon | G4: Amazon.fr | J4: Standard | K4: BEPER BT.710Y Crêpière électrique avec poignée, 800 W, plaque en aluminium avec revêtement antiadhésif, rouge | L4: BT.710Y_FBA | M4: B07NQ2VYGD | N4: Shipped | O4: 1 | P4: EUR | Q4: 39.9 | R4: 6.65 | Y4: LE MANS | AA4: 72100 | AB4: FR | AC4: Free Shipping 2017/10/17 17-17-37-677
A5: 404-5208901-0567553 | B5: 404-5208901-0567553 | C5: 2024-02-29T16:51:11+00:00 | D5: 2024-03-01T10:32:06+00:00 | E5: Shipped | F5: Amazon | G5: Amazon.fr | J5: Expedited | K5: BEPER 50.700 Nettoyeur Vapeur pour Sol, Canapé, Tapis - Nettoyant Vapeur, 135° max, câble de 3 Mètres, 350 ml | L5: 50.700_FBA | M5: B01MTSEGF9 | N5: Shipped | O5: 1 | P5: EUR | Q5: 49.9 | R5: 8.32 | Y5: Roissy-en-France | Z5: IDF | AA5: 95700 | AB5: FR
A6: 403-1479699-4346739 | B6: 403-1479699-4346739 | C6: 2024-02-29T16:04:25+00:00 | D6: 2024-02-29T16:20:22+00:00 | E6: Cancelled | F6: Amazon | G6: Amazon.fr | J6: Expedited | K6: Beper - Machine à Pop-Corn, Pop-Corn en 3 Minutes, Sans Matières Grasses, Circulation d'Air Chaud, Puissance 1200W - Rouge [Classe d'efficacité én | L6: 90.590Y_FBA | M6: B01KMJ9OXW | N6: Cancelled | O6: 0 | Y6: St Aunes | AA6: 34130 | AB6: FR
A7: 403-4262482-2499565 | B7: 403-4262482-2499565 | C7: 2024-02-29T14:19:31+00:00 | D7: 2024-02-29T23:45:05+00:00 | E7: Shipped | F7: Amazon | G7: Amazon.fr | J7: Standard | K7: Beper - Machine à Pop-Corn, Pop-Corn en 3 Minutes, Sans Matières Grasses, Circulation d'Air Chaud, Puissance 1200W - Rouge [Classe d'efficacité én | L7: 90.590Y_FBA | M7: B01KMJ9OXW | N7: Shipped | O7: 1 | P7: EUR | Q7: 44.9 | R7: 7.79 | S7: 2.47 | X7: 2.47 | Y7: Strepy-bracquegnies | AA7: 7110 | AB7: BE | AC7: Free Shipping 2017/10/17 17-17-37-677
A8: 404-7699547-2737150 | B8: 404-7699547-2737150 | C8: 2024-02-29T13:44:12+00:00 | D8: 2024-02-29T21:31:36+00:00 | E8: Shipped | F8: Amazon | G8: Amazon.fr | J8: Expedited | K8: BEPER BT.710Y Crêpière électrique avec poignée, 800 W, plaque en aluminium avec revêtement antiadhésif, rouge | L8: BT.710Y_FBA | M8: B07NQ2VYGD | N8: Shipped | O8: 2 | P8: EUR | Q8: 79.8 | R8: 13.3 | Y8: NICE | Z8: - | AA8: 6000 | AB8: FR
A9: 407-2306782-6777128 | B9: 407-2306782-6777128 | C9: 2024-02-29T13:26:54+00:00 | D9: 2024-03-01T03:26:36+00:00 | E9: Shipped | F9: Amazon | G9: Amazon.fr | J9: Expedited | K9: Beper - Vert & Blanc Sauna Facial et Aromathérapie 2 Puissances, Traitements Curatifs et Relaxants, Hydratation et Nettoyage du Visage, Réservoir d' | L9: 40.967N_FBA | M9: B00FAJUDU8 | N9: Shipped | O9: 1 | P9: EUR | Q9: 39.9 | R9: 6.65 | Y9: Paris | AA9: 75017 | AB9: FR
A10: 404-9509364-4987529 | B10: 404-9509364-4987529 | C10: 2024-02-28T19:06:05+00:00 | D10: 2024-02-29T07:52:17+00:00 | E10: Shipped | F10: Amazon | G10: Amazon.fr | J10: Expedited | K10: Beper - Machine à Pop-Corn, Pop-Corn en 3 Minutes, Sans Matières Grasses, Circulation d'Air Chaud, Puissance 1200W - Rouge [Classe d'efficacité én | L10: 90.590Y_FBA | M10: B01KMJ9OXW | N10: Shipped | O10: 1 | P10: EUR | Q10: 44.9 | R10: 7.48 | Y10: Merignac | AA10: 33700 | AB10: FR
A11: 406-4079321-5371530 | B11: 406-4079321-5371530 | C11: 2024-02-28T13:42:28+00:00 | D11: 2024-03-07T02:27:35+00:00 | E11: Shipped | F11: Amazon | G11: Amazon.fr | J11: Expedited | K11: BEPER Distributeur automatique de couvre-chaussures, ABS, blanc, taille unique | L11: C206UTI001_FBA | M11: B08JM7SZ36 | N11: Shipped | O11: 2 | P11: EUR | Q11: 99.8 | R11: 16.64 | Y11: ST TROPEZ | AA11: 83990 | AB11: FR
A12: 171-0524532-6619517 | B12: 171-0524532-6619517 | C12: 2024-02-28T12:13:56+00:00 | D12: 2024-02-29T01:30:46+00:00 | E12: Shipped | F12: Amazon | G12: Amazon.fr | J12: Expedited | K12: BEPER BT.602H Gaufrier 700W Cable poignée Thermo-Isolante, Rouge/Blanc | L12: BT.602H_FBA | M12: B076DCKSTJ | N12: Shipped | O12: 1 | P12: EUR | Q12: 34.9 | R12: 5.82 | Y12: Fouras | AA12: 17450 | AB12: FR
A13: 171-6271965-1018725 | B13: 171-6271965-1018725 | C13: 2024-02-28T10:39:57+00:00 | D13: 2024-02-29T01:32:32+00:00 | E13: Shipped | F13: Amazon | G13: Amazon.fr | J13: Expedited | K13: BEPER 50.700 Nettoyeur Vapeur pour Sol, Canapé, Tapis - Nettoyant Vapeur, 135° max, câble de 3 Mètres, 350 ml | L13: 50.700_FBA | M13: B01MTSEGF9 | N13: Shipped | O13: 1 | P13: EUR | Q13: 49.9 | R13: 8.32 | Y13: Toulouse | AA13: 31100 | AB13: FR
A14: 406-2825047-4865914 | B14: 406-2825047-4865914 | C14: 2024-02-28T08:21:01+00:00 | D14: 2024-02-28T12:30:39+00:00 | E14: Shipped | F14: Amazon | G14: Amazon.fr | J14: Expedited | K14: BEPER BT.710Y Crêpière électrique avec poignée, 800 W, plaque en aluminium avec revêtement antiadhésif, rouge | L14: BT.710Y_FBA | M14: B07NQ2VYGD | N14: Shipped | O14: 1 | P14: EUR | Q14: 39.9 | R14: 6.65 | Y14: Oloron sainte marie | AA14: 64400 | AB14: FR
A15: 407-3195543-2260353 | B15: 407-3195543-2260353 | C15: 2024-02-27T21:03:55+00:00 | D15: 2024-03-02T00:02:05+00:00 | E15: Shipped | F15: Amazon | G15: Amazon.fr | J15: Standard | K15: BEPER BT.710Y Crêpière électrique avec poignée, 800 W, plaque en aluminium avec revêtement antiadhésif, rouge | L15: BT.710Y_FBA | M15: B07NQ2VYGD | N15: Shipped | O15: 1 | P15: EUR | Q15: 39.9 | R15: 6.65 | S15: 0.27 | X15: 0.27 | Y15: Bordeaux | AA15: 33000 | AB15: FR | AC15: Free Shipping 2017/10/17 17-17-37-677
A16: 405-4938954-9370745 | B16: 405-4938954-9370745 | C16: 2024-02-27T19:36:32+00:00 | D16: 2024-02-28T15:21:21+00:00 | E16: Shipped | F16: Amazon | G16: Amazon.fr | J16: Expedited | K16: Beper - Machine à Pop-Corn, Pop-Corn en 3 Minutes, Sans Matières Grasses, Circulation d'Air Chaud, Puissance 1200W - Rouge [Classe d'efficacité én | L16: 90.590Y_FBA | M16: B01KMJ9OXW | N16: Shipped | O16: 1 | P16: EUR | Q16: 44.9 | R16: 7.48 | Y16: Bonneville Avit Fumadieres | AA16: 24230 | AB16: FR
A17: 403-4114106-8420368 | B17: 403-4114106-8420368 | C17: 2024-02-27T18:42:11+00:00 | D17: 2024-02-28T02:27:34+00:00 | E17: Shipped | F17: Amazon | G17: Amazon.fr | J17: Expedited | K17: BEPER BT.710Y Crêpière électrique avec poignée, 800 W, plaque en aluminium avec revêtement antiadhésif, rouge | L17: BT.710Y_FBA | M17: B07NQ2VYGD | N17: Shipped | O17: 1 | P17: EUR | Q17: 39.9 | R17: 6.65 | Y17: bazancourt | AA17: 51110 | AB17: FR
A18: 403-3306891-3853917 | B18: 403-3306891-3853917 | C18: 2024-02-27T17:18:33+00:00 | D18: 2024-02-29T03:52:29+00:00 | E18: Shipped | F18: Amazon | G18: Amazon.fr | J18: Standard | K18: BEPER BT.710Y Crêpière électrique avec poignée, 800 W, plaque en aluminium avec revêtement antiadhésif, rouge | L18: BT.710Y_FBA | M18: B07NQ2VYGD | N18: Shipped | O18: 1 | P18: EUR | Q18: 39.9 | R18: 6.65 | S18: 3.32 | X18: 3.32 | Y18: Orange | Z18: Vaucluse | AA18: 84100 | AB18: FR | AC18: Free Shipping 2017/10/17 17-17-37-677
A19: 404-1236735-1081902 | B19: 404-1236735-1081902 | C19: 2024-02-27T16:15:10+00:00 | D19: 2024-02-28T12:20:09+00:00 | E19: Shipped | F19: Amazon | G19: Amazon.fr | J19: Standard | K19: Beper - Cuiseur à Vapeur Multicombustion de 5L, Économiseur d'Espace, Minuterie de 60 minutes, Cuisson à la Vapeur Saine, Puissance 400-500W - Arge | L19: BC.261_FBA | M19: B08485QRVZ | N19: Shipped | O19: 1 | P19: EUR | Q19: 39.9 | R19: 6.65 | S19: 3.32 | X19: 3.32 | Y19: Saint-Amand-Montrond | AA19: 18200 | AB19: FR | AC19: Free Shipping 2017/10/17 17-17-37-677
A20: 171-9512897-1425940 | B20: 171-9512897-1425940 | C20: 2024-02-27T14:22:29+00:00 | D20: 2024-02-28T11:08:14+00:00 | E20: Shipped | F20: Amazon | G20: Amazon.fr | J20: Standard | K20: Beper BF.640 - Four ventilé multifonction 12L Anneau de rallonge pour capacité totale 18L Minuterie 60 minutes Température réglable jusqu'à 250° | L20: BF.640_FBA | M20: B07YBN2FS3 | N20: Shipped | O20: 1 | P20: EUR | Q20: 99 | R20: 16.5 | Y20: LABASTIDE ST PIERRE | AA20: 82370 | AB20: FR | AC20: Free Shipping 2017/10/17 17-17-37-677
A21: 403-4162250-7026753 | B21: 403-4162250-7026753 | C21: 2024-02-27T09:08:12+00:00 | D21: 2024-02-27T09:25:03+00:00 | E21: Cancelled | F21: Amazon | G21: Amazon.fr | J21: Standard | K21: BEPER BT.710Y Crêpière électrique avec poignée, 800 W, plaque en aluminium avec revêtement antiadhésif, rouge | L21: BT.710Y_FBA | M21: B07NQ2VYGD | N21: Cancelled | O21: 0 | Y21: LAMORLAYE | AA21: 60260 | AB21: FR | AC21: Free Shipping 2017/10/17 17-17-37-677
A22: 405-2195406-4629145 | B22: 405-2195406-4629145 | C22: 2024-02-27T07:48:46+00:00 | D22: 2024-02-27T20:26:41+00:00 | E22: Shipped | F22: Amazon | G22: Amazon.fr | J22: Expedited | K22: BEPER 50.700 Nettoyeur Vapeur pour Sol, Canapé, Tapis - Nettoyant Vapeur, 135° max, câble de 3 Mètres, 350 ml | L22: 50.700_FBA | M22: B01MTSEGF9 | N22: Shipped | O22: 1 | P22: EUR | Q22: 49.9 | R22: 8.32 | Y22: Montpellier | AA22: 34000 | AB22: FR
A23: 402-6733882-9715545 | B23: 402-6733882-9715545 | C23: 2024-02-27T02:16:39+00:00 | D23: 2024-02-27T02:31:50+00:00 | E23: Cancelled | F23: Amazon | G23: Amazon.fr | J23: Standard | K23: BEPER BT.710Y Crêpière électrique avec poignée, 800 W, plaque en aluminium avec revêtement antiadhésif, rouge | L23: BT.710Y_FBA | M23: B07NQ2VYGD | N23: Cancelled | O23: 0 | Y23: LE BLANC MESNIL | AA23: 93150 | AB23: FR
A24: 404-3961814-0651540 | B24: 404-3961814-0651540 | C24: 2024-02-27T00:54:11+00:00 | D24: 2024-02-28T03:49:46+00:00 | E24: Shipped | F24: Amazon | G24: Amazon.fr | J24: Standard | K24: BEPER BT.710Y Crêpière électrique avec poignée, 800 W, plaque en aluminium avec revêtement antiadhésif, rouge | L24: BT.710Y_FBA | M24: B07NQ2VYGD | N24: Shipped | O24: 1 | P24: EUR | Q24: 39.9 | R24: 6.65 | S24: 3.32 | X24: 3.32 | Y24: Marseille | AA24: 13006 | AB24: FR | AC24: Free Shipping 2017/10/17 17-17-37-677
A25: 407-6426127-6527546 | B25: 407-6426127-6527546 | C25: 2024-02-26T22:30:28+00:00 | D25: 2024-02-28T12:21:08+00:00 | E25: Shipped | F25: Amazon | G25: Amazon.fr | J25: Standard | K25: Beper - Machine à Pop-Corn, Pop-Corn en 3 Minutes, Sans Matières Grasses, Circulation d'Air Chaud, Puissance 1200W - Rouge [Classe d'efficacité én | L25: 90.590Y_FBA | M25: B01KMJ9OXW | N25: Shipped | O25: 1 | P25: EUR | Q25: 44.9 | R25: 7.48 | S25: 0.83 | X25: 0.83 | Y25: Croix | AA25: 59170 | AB25: FR | AC25: Free Shipping 2017/10/17 17-17-37-677
A26: 407-8680279-9617150 | B26: 407-8680279-9617150 | C26: 2024-02-26T22:25:07+00:00 | D26: 2024-02-28T22:12:39+00:00 | E26: Shipped | F26: Amazon | G26: Amazon.fr | J26: Standard | K26: Beper - Machine à Pop-Corn, Pop-Corn en 3 Minutes, Sans Matières Grasses, Circulation d'Air Chaud, Puissance 1200W - Rouge [Classe d'efficacité én | L26: 90.590Y_FBA | M26: B01KMJ9OXW | N26: Shipped | O26: 1 | P26: EUR | Q26: 44.9 | R26: 7.48 | S26: 0.83 | X26: 0.83 | Y26: Arcueil | AA26: 94110 | AB26: FR | AC26: Free Shipping 2017/10/17 17-17-37-677
A27: 403-6501864-4350727 | B27: 403-6501864-4350727 | C27: 2024-02-26T21:19:43+00:00 | D27: 2024-02-27T04:56:50+00:00 | E27: Shipped | F27: Amazon | G27: Amazon.fr | J27: Standard | K27: BEPER BT.710Y Crêpière électrique avec poignée, 800 W, plaque en aluminium avec revêtement antiadhésif, rouge | L27: BT.710Y_FBA | M27: B07NQ2VYGD | N27: Shipped | O27: 1 | P27: EUR | Q27: 39.9 | R27: 6.65 | S27: 3.32 | X27: 3.32 | Y27: L'Isle-sur-la-Sorgue | AA27: 84800 | AB27: FR | AC27: Free Shipping 2017/10/17 17-17-37-677
A28: 405-9914630-9017966 | B28: 405-9914630-9017966 | C28: 2024-02-26T19:29:42+00:00 | D28: 2024-02-27T07:52:25+00:00 | E28: Shipped | F28: Amazon | G28: Amazon.fr | J28: Standard | K28: BEPER BT.710Y Crêpière électrique avec poignée, 800 W, plaque en aluminium avec revêtement antiadhésif, rouge | L28: BT.710Y_FBA | M28: B07NQ2VYGD | N28: Shipped | O28: 1 | P28: EUR | Q28: 39.9 | R28: 6.65 | Y28: St Herblain | AA28: 44800 | AB28: FR | AC28: Free Shipping 2017/10/17 17-17-37-677
A29: 404-7268355-1429934 | B29: 404-7268355-1429934 | C29: 2024-02-26T17:42:54+00:00 | D29: 2024-02-27T00:28:52+00:00 | E29: Shipped | F29: Amazon | G29: Amazon.fr | J29: Expedited | K29: BEPER BT.710Y Crêpière électrique avec poignée, 800 W, plaque en aluminium avec revêtement antiadhésif, rouge | L29: BT.710Y_FBA | M29: B07NQ2VYGD | N29: Shipped | O29: 1 | P29: EUR | Q29: 39.9 | R29: 6.65 | Y29: algolsheim | AA29: 68600 | AB29: FR
A30: 405-2022639-4876344 | B30: 405-2022639-4876344 | C30: 2024-02-26T15:37:10+00:00 | D30: 2024-02-27T04:33:48+00:00 | E30: Shipped | F30: Amazon | G30: Amazon.fr | J30: Standard | K30: BEPER BT.710Y Crêpière électrique avec poignée, 800 W, plaque en aluminium avec revêtement antiadhésif, rouge | L30: BT.710Y_FBA | M30: B07NQ2VYGD | N30: Shipped | O30: 1 | P30: EUR | Q30: 39.9 | R30: 6.65 | S30: 3.32 | X30: 3.32 | Y30: Pierrefitte Sur Seine | AA30: 93380 | AB30: FR | AC30: Free Shipping 2017/10/17 17-17-37-677
A31: 405-0037849-7716361 | B31: 405-0037849-7716361 | C31: 2024-02-26T13:15:37+00:00 | D31: 2024-02-27T04:56:24+00:00 | E31: Shipped | F31: Amazon | G31: Amazon.fr | J31: Expedited | K31: BEPER BT.710Y Crêpière électrique avec poignée, 800 W, plaque en aluminium avec revêtement antiadhésif, rouge | L31: BT.710Y_FBA | M31: B07NQ2VYGD | N31: Shipped | O31: 1 | P31: EUR | Q31: 39.9 | R31: 6.65 | Y31: matemale | AA31: 66210 | AB31: FR
A32: 403-4571122-8710729 | B32: 403-4571122-8710729 | C32: 2024-02-26T12:46:40+00:00 | D32: 2024-02-26T19:24:30+00:00 | E32: Shipped | F32: Amazon | G32: Amazon.fr | J32: Expedited | K32: Beper BF.640 - Four ventilé multifonction 12L Anneau de rallonge pour capacité totale 18L Minuterie 60 minutes Température réglable jusqu'à 250° | L32: BF.640_FBA | M32: B07YBN2FS3 | N32: Shipped | O32: 1 | P32: EUR | Q32: 99 | R32: 16.5 | Y32: VITRY SUR SEINE | AA32: 94400 | AB32: FR
A33: 171-3587644-2609900 | B33: 171-3587644-2609900 | C33: 2024-02-26T12:23:35+00:00 | D33: 2024-02-27T02:30:25+00:00 | E33: Shipped | F33: Amazon | G33: Amazon.fr | J33: Expedited | K33: BEPER BT.710Y Crêpière électrique avec poignée, 800 W, plaque en aluminium avec revêtement antiadhésif, rouge | L33: BT.710Y_FBA | M33: B07NQ2VYGD | N33: Shipped | O33: 2 | P33: EUR | Q33: 79.8 | R33: 13.84 | Y33: Anderlecht | AA33: 1070 | AB33: BE
A34: 404-7410750-3447546 | B34: 404-7410750-3447546 | C34: 2024-02-26T08:32:20+00:00 | D34: 2024-02-27T09:15:51+00:00 | E34: Shipped | F34: Amazon | G34: Amazon.fr | J34: Expedited | K34: Beper - Machine à Pop-Corn, Pop-Corn en 3 Minutes, Sans Matières Grasses, Circulation d'Air Chaud, Puissance 1200W - Rouge [Classe d'efficacité én | L34: 90.590Y_FBA | M34: B01KMJ9OXW | N34: Shipped | O34: 1 | P34: EUR | Q34: 44.9 | R34: 7.48 | Y34: La Penne | AA34: 6260 | AB34: FR
A35: 407-8147695-4288363 | B35: 407-8147695-4288363 | C35: 2024-02-25T22:12:57+00:00 | D35: 2024-02-26T02:21:03+00:00 | E35: Shipped | F35: Amazon | G35: Amazon.fr | J35: Expedited | K35: BEPER BT.710Y Crêpière électrique avec poignée, 800 W, plaque en aluminium avec revêtement antiadhésif, rouge | L35: BT.710Y_FBA | M35: B07NQ2VYGD | N35: Shipped | O35: 1 | P35: EUR | Q35: 39.9 | R35: 6.65 | Y35: Ivry Sur Seine | AA35: 94200 | AB35: FR
A36: 407-5366691-0114743 | B36: 407-5366691-0114743 | C36: 2024-02-25T21:56:39+00:00 | D36: 2024-02-26T12:20:11+00:00 | E36: Shipped | F36: Amazon | G36: Amazon.fr | J36: Expedited | K36: Beper - Machine à Pop-Corn, Pop-Corn en 3 Minutes, Sans Matières Grasses, Circulation d'Air Chaud, Puissance 1200W - Rouge [Classe d'efficacité én | L36: 90.590Y_FBA | M36: B01KMJ9OXW | N36: Shipped | O36: 1 | P36: EUR | Q36: 44.9 | R36: 7.48 | Y36: Lyon | AA36: 69004 | AB36: FR
A37: 171-8348783-6107561 | B37: 171-8348783-6107561 | C37: 2024-02-25T21:44:42+00:00 | D37: 2024-02-26T04:56:47+00:00 | E37: Shipped | F37: Amazon | G37: Amazon.fr | J37: Expedited | K37: BEPER BT.710Y Crêpière électrique avec poignée, 800 W, plaque en aluminium avec revêtement antiadhésif, rouge | L37: BT.710Y_FBA | M37: B07NQ2VYGD | N37: Shipped | O37: 1 | P37: EUR | Q37: 39.9 | R37: 6.65 | Y37: Beaumont de pertuis | AA37: 84120 | AB37: FR
A38: 408-7761563-3924340 | B38: 408-7761563-3924340 | C38: 2024-02-25T18:55:02+00:00 | D38: 2024-02-26T04:57:34+00:00 | E38: Shipped | F38: Amazon | G38: Amazon.fr | J38: Expedited | K38: BEPER BT.710Y Crêpière électrique avec poignée, 800 W, plaque en aluminium avec revêtement antiadhésif, rouge | L38: BT.710Y_FBA | M38: B07NQ2VYGD | N38: Shipped | O38: 1 | P38: EUR | Q38: 39.9 | R38: 6.65 | Y38: Marseille | AA38: 13006 | AB38: FR
A39: 171-6568599-5969115 | B39: 171-6568599-5969115 | C39: 2024-02-25T16:06:44+00:00 | D39: 2024-02-26T02:04:28+00:00 | E39: Shipped | F39: Amazon | G39: Amazon.fr | J39: Standard | K39: BEPER BT.710Y Crêpière électrique avec poignée, 800 W, plaque en aluminium avec revêtement antiadhésif, rouge | L39: BT.710Y_FBA | M39: B07NQ2VYGD | N39: Shipped | O39: 1 | P39: EUR | Q39: 39.9 | R39: 6.65 | Y39: ST RAMBERT EN BUGEY | AA39: 1230 | AB39: FR | AC39: Free Shipping 2017/10/17 17-17-37-677
A40: 407-9983301-1856328 | B40: 407-9983301-1856328 | C40: 2024-02-25T14:59:44+00:00 | D40: 2024-02-27T01:40:58+00:00 | E40: Shipped | F40: Amazon | G40: Amazon.fr | J40: Standard | K40: BEPER BT.700Y Crêpière électrique avec Spatule en Bois, 1300W, Plaque antiadhésive, Rouge | L40: BT.700Y_FBA | M40: B076D74TC7 | N40: Shipped | O40: 1 | P40: EUR | Q40: 49.9 | R40: 8.32 | S40: 3.32 | X40: 3.32 | Y40: Argenteuil | AA40: 95100 | AB40: FR | AC40: Free Shipping 2017/10/17 17-17-37-677
...

Sheet v_02_2023
A1: Codice marketplace | B1: (Tutto) | F1: Codice marketplace | G1: IT
A3: ASIN | B3: Numero del modello | C3: Somma di Unità ordinate | D3: Somma di Ricavi ordini | F3: ASIN | G3: Numero del modello | H3: Somma di Unità ordinate | I3: Somma di Ricavi ordini
A4: B0050IHH4E | B4: 40.979 | C4: 31 | D4: 404.7 | F4: B0050IHH4E | G4: 40.979 | H4: 24 | I4: 312.72
A5: B00BH202XK | B5: 40.808A | C5: 2 | D5: 35.73 | F5: B00BH202XK | G5: 40.808A | H5: 2 | I5: 35.73
A6: B00C5CCJP0 | B6: 40.993 | C6: 4 | D6: 43.54 | F6: B00CMAD2FG | G6: HK-NV009W | H6: 1 | I6: 19.87
A7: B00CMAD2FG | B7: HK-NV009W | C7: 2 | D7: 32.58 | F7: B00EYDRS1I | G7: 90.349 | H7: 159 | I7: 878.28
A8: B00EYDRS1I | B8: 90.349 | C8: 198 | D8: 1106.56 | F8: B00FAJUDU8 | G8: 40.967N | H8: 92 | I8: 1877.72
A9: B00EZ4185S | B9: RI.501SL | C9: 0 | D9: 0 | F9: B00FFBFVG2 | G9: 40.100 | H9: 3 | I9: 18.99
A10: B00FAJUDU8 | B10: 40.967N | C10: 195 | D10: 4239.58 | F10: B00J7MNQFS | G10: 40.994 | H10: 3 | I10: 49.83
A11: B00FFBFVG2 | B11: 40.100 | C11: 5 | D11: 32.25 | F11: B00L5GPWFG | G11: 40.120 | H11: 2 | I11: 49.02
A12: B00J7MNQFS | B12: 40.994 | C12: 4 | D12: 69.7 | F12: B00L5H5KUW | G12: 40.121 | H12: 202 | I12: 3294.62
A13: B00L5GPWFG | B13: 40.120 | C13: 2 | D13: 49.02 | F13: B00NSNZSLM | G13: 90.602 | H13: 515 | I13: 10511.15
A14: B00L5H5KUW | B14: 40.121 | C14: 374 | D14: 6370.16 | F14: B00OKE4RTM | G14: 90.386 | H14: 1 | I14: 53.22
A15: B00NSNZSLM | B15: 90.602 | C15: 529 | D15: 10857.32 | F15: B00OLZPU5K | G15: 40.947 | H15: 3 | I15: 31.71
... A204: B08NDZKNF5 | B204: P102CON001 | C204: 19 | D204: 547.96 | F204: B0BRQB2J4B | G204: PET005 | H204: 39 | I204: 156.78
A205: B08NF8TQKT | B205: P102FRU100 | C205: 12 | D205: 266.54 | F205: Totale complessivo | H205: 21467 | I205: 329286.49
A206: B08NTD853X | B206: P102SBA006 | C206: 17 | D206: 139.9
A207: B08V4VTTQN | B207: C107UTT001 | C207: 17 | D207: 119.85
A208: B08XQT9P5C | B208: P102GEL001 | C208: 2 | D208: 83.08
A209: B08XVV3PVK | B209: P303MED001 | C209: 3 | D209: 27.27
A210: B08XWBGJHR | B210: P101PIA002 | C210: 0 | D210: 0
A211: B09146GTKW | B211: P302VIS002 | C211: 2634 | D211: 21633.79
A212: B091C5XQZN | B212: P202ASP001 | C212: 6 | D212: 236.64
A213: B091LRR67V | B213: P101FRI050 | C213: 72 | D213: 4725.07
A214: B091VSY78C | B214: P303BIP050 | C214: 1 | D214: 20.41
A215: B09251R9RJ | B215: P304CAP001 | C215: 8 | D215: 130.9
A216: B0929CVW7Q | B216: P206ZAN110 | C216: 4 | D216: 48.84
A217: B092DN1NCS | B217: P206VEN440 | C217: 2 | D217: 16.5
... A289: B0BRQB2J4B | B289: PET005 | C289: 43 | D289: 172.91
A290: Totale complessivo | C290: 39365 | D290: 612405.58

Sheet v_02_2024
A1: Codice marketplace | B1: (Tutto) | F1: Codice marketplace | G1: IT
A3: ASIN | B3: Numero del modello | C3: Somma di Unità ordinate | D3: Somma di Ricavi ordini | F3: ASIN | G3: Numero del modello | H3: Somma di Unità ordinate | I3: Somma di Ricavi ordini
A4: B0050IHH4E | B4: 40.979 | C4: 1117 | D4: 16410.86 | F4: B0050IHH4E | G4: 40.979 | H4: 311 | I4: 4876.26
A5: B00BH202XK | B5: 40.808A | C5: 2 | D5: 22.85 | F5: B00BH202XK | G5: 40.808A | H5: 1 | I5: 13.85
A6: B00EYDRS1I | B6: 90.349 | C6: 23 | D6: 131.27 | F6: B00EYDRS1I | G6: 90.349 | H6: 17 | I6: 102.19
A7: B00FAJUDU8 | B7: 40.967N | C7: 0 | D7: 0 | F7: B00FFBFVG2 | G7: 40.100 | H7: 0 | I7: 0
A8: B00FFBED98 | B8: 40.11 | C8: 1 | D8: 41.24 | F8: B00J7MNQFS | G8: 40.994 | H8: 3 | I8: 61.3
A9: B00FFBFVG2 | B9: 40.100 | C9: 0 | D9: 0 | F9: B00L5GPWFG | G9: 40.120 | H9: 3 | I9: 73.53
A10: B00FMZ2VW8 | B10: HK-HQ601C PINK | C10: 0 | D10: 0 | F10: B00L5H5KUW | G10: 40.121 | H10: 424 | I10: 7577.95
A11: B00J7MNQFS | B11: 40.994 | C11: 3 | D11: 61.3 | F11: B00NSNZSLM | G11: 90.602 | H11: 0 | I11: 0
A12: B00L5GPWFG | B12: 40.120 | C12: 3 | D12: 73.53 | F12: B00OKE4RTM | G12: 90.386 | H12: 3 | I12: 147.35
A13: B00L5H5KUW | B13: 40.121 | C13: 424 | D13: 7577.95 | F13: B00OLZPU5K | G13: 40.947 | H13: 1 | I13: 10.57
A14: B00NSNZSLM | B14: 90.602 | C14: 1 | D14: 27.03 | F14: B011LFVLW8 | G14: 90.620 | H14: 24 | I14: 784.8
A15: B00OKE4RTM | B15: 90.386 | C15: 3 | D15: 147.35 | F15: B011LH9V8M | G15: 40.958V | H15: 1 | I15: 6.73
... A198: B095X9KDJR | B198: P101BOL100 | C198: 1 | D198: 16.45 | F198: B0CPFRMPTM | G198: P101CAF001 | H198: 382 | I198: 9465.85
A199: B096KVY46G | B199: P303MED050 | C199: 5 | D199: 68.65 | F199: Totale complessivo | H199: 7751 | I199: 134126.27
A200: B096MX229M | B200: P102ROB050 | C200: 250 | D200: 3151.84
A201: B096SVXQDX | B201: P201UTP011 | C201: 2 | D201: 28.26
A202: B097785V2V | B202: P202VAL110 | C202: 14 | D202: 57.29
A203: B0978ZKW4S | B203: P205DIF100 | C203: 54 | D203: 664.1
A204: B097F45J2B | B204: P102FRU500 | C204: 3 | D204: 88.7
A205: B097HRQNRG | B205: P101FRI100 | C205: 78 | D205: 2332.18
A206: B097YTGFH7 | B206: P102ROB200 | C206: 10 | D206: 642.61
A207: B098QM485T | B207: P101CUD050 | C207: 2 | D207: 83.86
A208: B09968BKDS | B208: P102FRU003 | C208: 292 | D208: 4099.28
A209: B09B15P5H1 | B209: P102FRU200 | C209: 7 | D209: 131.05
A210: B09B2NT2SV | B210: P102FRU150 | C210: 4 | D210: 112.76
A211: B09B47S644 | B211: P101CUD501 | C211: 106 | D211: 3110.64
... A286: B0CPFRMPTM | B286: P101CAF001 | C286: 425 | D286: 10531.95
A287: Totale complessivo | C287: 15469 | D287: 257741.07

Sheet s_02_2024
A1: sales-channel | B1: (Tutto) | E1: sales-channel | F1: Amazon.it
A3: Etichette di riga | B3: Somma di quantity | C3: Somma di item-price | E3: Etichette di riga | F3: Somma di quantity | G3: Somma di item-price
A4: B0050IHH4E | B4: 1 | C4: 19.9 | E4: B0050IHH4E | F4: 1 | G4: 19.9
A5: B00FAJUDU8 | B5: 38 | C5: 1231.71 | E5: B00FAJUDU8 | F5: 36 | G5: 1151.91
A6: B00NSNZSLM | B6: 96 | C6: 2882.4 | E6: B00NSNZSLM | F6: 96 | G6: 2882.4
A7: B017IUJA50 | B7: 7 | C7: 155.61 | E7: B017IUJA50 | F7: 7 | G7: 155.61
A8: B01CNX704K | B8: 5 | C8: 234.5 | E8: B01CNX704K | F8: 5 | G8: 234.5
A9: B01I497WWM | B9: 1084 | C9: 21587.91 | E9: B01I497WWM | F9: 1084 | G9: 21587.91
A10: B01KMJ9OXW | B10: 346 | C10: 12658.72 | E10: B01KMJ9OXW | F10: 285 | G10: 9936.02
A11: B01MTSEGF9 | B11: 31 | C11: 1446.9 | E11: B01MTSEGF9 | F11: 20 | G11: 898
A12: B06Y17FS6D | B12: 3 | C12: 49.9 | E12: B06Y195DJN | F12: 31 | G12: 1546.9
A13: B06Y195DJN | B13: 32 | C13: 1606.8 | E13: B0757TJRR9 | F13: 602 | G13: 19788.01
A14: B0757TJRR9 | B14: 606 | C14: 19967.61 | E14: B075FX6RFP | F14: 25 | G14: 950.5
A15: B075FX6RFP | B15: 25 | C15: 950.5 | E15: B076D74TC7 | F15: 4 | G15: 147.96
... A50: B0CLY2CF4T | B50: 56 | C50: 1299.4 | E50: Totale complessivo | F50: 4207 | G50: 118277.01
A51: (vuoto)
A52: Totale complessivo | B52: 4616 | C52: 135835.27

Sheet pivot
A3: ASIN | B3: SKU | C3: Somma di Ordini Vendor 24 | D3: Somma di Valori ordini Vendor 24 | E3: Somma di Ordini Seller 24 | F3: Somma di Valori ordini Seller 24 | G3: Somma di Ordini Complessivi 24 | H3: Somma di Valori ordini Complessivi 24 | I3: Somma di Ordini Vendor 23 | J3: Somma di Valori ordini Vendor 23
A4: B0050IHH4E | B4: 40.979 | C4: 1117 | D4: 16410.86 | E4: 1 | F4: 19.9 | G4: 1118 | H4: 16430.76 | I4: 31 | J4: 404.7
A5: B00BH202XK | B5: 40.808A | C5: 2 | D5: 22.85 | E5: 0 | F5: 0 | G5: 2 | H5: 22.85 | I5: 2 | J5: 35.73
A6: B00C5CCJP0 | B6: 40.993 | C6: 0 | D6: 0 | E6: 0 | F6: 0 | G6: 0 | H6: 0 | I6: 4 | J6: 43.54
A7: B00CMAD2FG | B7: HK-NV009W | C7: 0 | D7: 0 | E7: 0 | F7: 0 | G7: 0 | H7: 0 | I7: 2 | J7: 32.58
A8: B00EYDRS1I | B8: 90.349 | C8: 23 | D8: 131.27 | E8: 0 | F8: 0 | G8: 23 | H8: 131.27 | I8: 198 | J8: 1106.56
A9: B00EZ4185S | B9: RI.501SL | C9: 0 | D9: 0 | E9: 0 | F9: 0 | G9: 0 | H9: 0 | I9: 0 | J9: 0
A10: B00FAJUDU8 | B10: 40.967N | C10: 0 | D10: 0 | E10: 38 | F10: 1231.71 | G10: 38 | H10: 1231.71 | I10: 195 | J10: 4239.58
A11: B00FFBED98 | B11: 40.11 | C11: 1 | D11: 41.24 | E11: 0 | F11: 0 | G11: 1 | H11: 41.24 | I11: 0 | J11: 0
A12: B00FFBFVG2 | B12: 40.100 | C12: 0 | D12: 0 | E12: 0 | F12: 0 | G12: 0 | H12: 0 | I12: 5 | J12: 32.25
A13: B00FMZ2VW8 | B13: HK-HQ601C PINK | C13: 0 | D13: 0 | E13: 0 | F13: 0 | G13: 0 | H13: 0 | I13: 0 | J13: 0
A14: B00J7MNQFS | B14: 40.994 | C14: 3 | D14: 61.3 | E14: 0 | F14: 0 | G14: 3 | H14: 61.3 | I14: 4 | J14: 69.7
A15: B00L5GPWFG | B15: 40.120 | C15: 3 | D15: 73.53 | E15: 0 | F15: 0 | G15: 3 | H15: 73.53 | I15: 2 | J15: 49.02
... A358: (vuoto) | B358: Totale complessivo | C358: 15469 | D358: 257741.07 | E358: 4616 | F358: 135835.27 | G358: 20085 | H358: 393576.34 | I358: 39365 | J358: 612405.58
A359: Totale complessivo | C359: 30938 | D359: 515482.14 | E359: 9231 | F359: 271541.54 | G359: 40169 | H359: 787023.68 | I359: 78730 | J359: 1224811.2

Sheet complessivo
A1: ASIN | B1: SKU | C1: Ordini Vendor 24 | D1: Valori ordini Vendor 24 | E1: Ordini Seller 24 | F1: Valori ordini Seller 24 | G1: % seller / totale | H1: Ordini Complessivi 24 | I1: Valori ordini Complessivi 24 | J1: Ordini Vendor 23 | K1: Valori ordini Vendor 23 | L1: Differenza Ordini | M1: Differenza Valore | N1: Differenza Valore %
A2: B0050IHH4E | B2: 40.979 | C2: 1117 | D2: 16410.86 | E2: =VLOOKUP(A2,s_02_2024!E:G,2,FALSE) -> 1 | F2: =VLOOKUP(A2,s_02_2024!E:G,3,FALSE) -> 19.9 | G2: =F2/I2 -> 0.001211143 | H2: =E2+C2 -> 1118 | I2: =F2+D2 -> 16430.76 | J2: =VLOOKUP(A2,v_02_2023!A:D,3,FALSE) -> 31 | K2: =VLOOKUP(A2,v_02_2023!A:D,4,FALSE) -> 404.7 | L2: =H2-J2 -> 1087 | M2: =I2-K2 -> 16026.06 | N2: =M2/K2 -> 39.599852
A3: B00BH202XK | B3: 40.808A | C3: 2 | D3: 22.85 | E3: 0 | F3: 0 | G3: =F3/I3 -> 0 | H3: =E3+C3 -> 2 | I3: =F3+D3 -> 22.85 | J3: =VLOOKUP(A3,v_02_2023!A:D,3,FALSE) -> 2 | K3: =VLOOKUP(A3,v_02_2023!A:D,4,FALSE) -> 35.73 | L3: =H3-J3 -> 0 | M3: =I3-K3 -> -12.88 | N3: =M3/K3 -> -0.36048139
A4: B00EYDRS1I | B4: 90.349 | C4: 23 | D4: 131.27 | E4: 0 | F4: 0 | G4: =F4/I4 -> 0 | H4: =E4+C4 -> 23 | I4: =F4+D4 -> 131.27 | J4: =VLOOKUP(A4,v_02_2023!A:D,3,FALSE) -> 198 | K4: =VLOOKUP(A4,v_02_2023!A:D,4,FALSE) -> 1106.56 | L4: =H4-J4 -> -175 | M4: =I4-K4 -> -975.29 | N4: =M4/K4 -> -0.8813711
A5: B00FAJUDU8 | B5: 40.967N | C5: 0 | D5: 0 | E5: =VLOOKUP(A5,s_02_2024!E:G,2,FALSE) -> 36 | F5: =VLOOKUP(A5,s_02_2024!E:G,3,FALSE) -> 1151.91 | G5: =F5/I5 -> 1 | H5: =E5+C5 -> 36 | I5: =F5+D5 -> 1151.91 | J5: =VLOOKUP(A5,v_02_2023!A:D,3,FALSE) -> 195 | K5: =VLOOKUP(A5,v_02_2023!A:D,4,FALSE) -> 4239.58 | L5: =H5-J5 -> -159 | M5: =I5-K5 -> -3087.67 | N5: =M5/K5 -> -0.7282962
A6: B00FFBED98 | B6: 40.11 | C6: 1 | D6: 41.24 | E6: 0 | F6: 0 | G6: =F6/I6 -> 0 | H6: =E6+C6 -> 1 | I6: =F6+D6 -> 41.24 | J6: 0 | K6: 0 | L6: =H6-J6 -> 1 | M6: =I6-K6 -> 41.24
A7: B00FFBFVG2 | B7: 40.100 | C7: 0 | D7: 0 | E7: 0 | F7: 0 | H7: =E7+C7 -> 0 | I7: =F7+D7 -> 0 | J7: =VLOOKUP(A7,v_02_2023!A:D,3,FALSE) -> 5 | K7: =VLOOKUP(A7,v_02_2023!A:D,4,FALSE) -> 32.25 | L7: =H7-J7 -> -5 | M7: =I7-K7 -> -32.25 | N7: =M7/K7 -> -1
A8: B00FMZ2VW8 | B8: HK-HQ601C PINK | C8: 0 | D8: 0 | E8: 0 | F8: 0 | H8: =E8+C8 -> 0 | I8: =F8+D8 -> 0 | J8: 0 | K8: 0 | L8: =H8-J8 -> 0 | M8: =I8-K8 -> 0
A9: B00J7MNQFS | B9: 40.994 | C9: 3 | D9: 61.3 | E9: 0 | F9: 0 | G9: =F9/I9 -> 0 | H9: =E9+C9 -> 3 | I9: =F9+D9 -> 61.3 | J9: =VLOOKUP(A9,v_02_2023!A:D,3,FALSE) -> 4 | K9: =VLOOKUP(A9,v_02_2023!A:D,4,FALSE) -> 69.7 | L9: =H9-J9 -> -1 | M9: =I9-K9 -> -8.4 | N9: =M9/K9 -> -0.1205165
A10: B00L5GPWFG | B10: 40.120 | C10: 3 | D10: 73.53 | E10: 0 | F10: 0 | G10: =F10/I10 -> 0 | H10: =E10+C10 -> 3 | I10: =F10+D10 -> 73.53 | J10: =VLOOKUP(A10,v_02_2023!A:D,3,FALSE) -> 2 | K10: =VLOOKUP(A10,v_02_2023!A:D,4,FALSE) -> 49.02 | L10: =H10-J10 -> 1 | M10: =I10-K10 -> 24.51 | N10: =M10/K10 -> 0.5
A11: B00L5H5KUW | B11: 40.121 | C11: 424 | D11: 7577.95 | E11: 0 | F11: 0 | G11: =F11/I11 -> 0 | H11: =E11+C11 -> 424 | I11: =F11+D11 -> 7577.95 | J11: =VLOOKUP(A11,v_02_2023!A:D,3,FALSE) -> 374 | K11: =VLOOKUP(A11,v_02_2023!A:D,4,FALSE) -> 6370.16 | L11: =H11-J11 -> 50 | M11: =I11-K11 -> 1207.79 | N11: =M11/K11 -> 0.1896012
A12: B00NSNZSLM | B12: 90.602 | C12: 1 | D12: 27.03 | E12: =VLOOKUP(A12,s_02_2024!E:G,2,FALSE) -> 96 | F12: =VLOOKUP(A12,s_02_2024!E:G,3,FALSE) -> 2882.4 | G12: =F12/I12 -> 0.99070952 | H12: =E12+C12 -> 97 | I12: =F12+D12 -> 2909.43 | J12: =VLOOKUP(A12,v_02_2023!A:D,3,FALSE) -> 529 | K12: =VLOOKUP(A12,v_02_2023!A:D,4,FALSE) -> 10857.32 | L12: =H12-J12 -> -432 | M12: =I12-K12 -> -7947.89 | N12: =M12/K12 -> -0.73203056
A13: B00OKE4RTM | B13: 90.386 | C13: 3 | D13: 147.35 | E13: 0 | F13: 0 | G13: =F13/I13 -> 0 | H13: =E13+C13 -> 3 | I13: =F13+D13 -> 147.35 | J13: =VLOOKUP(A13,v_02_2023!A:D,3,FALSE) -> 1 | K13: =VLOOKUP(A13,v_02_2023!A:D,4,FALSE) -> 53.22 | L13: =H13-J13 -> 2 | M13: =I13-K13 -> 94.13 | N13: =M13/K13 -> 1.768696
A14: B00OLZPU5K | B14: 40.947 | C14: 1 | D14: 10.57 | E14: 0 | F14: 0 | G14: =F14/I14 -> 0 | H14: =E14+C14 -> 1 | I14: =F14+D14 -> 10.57 | J14: =VLOOKUP(A14,v_02_2023!A:D,3,FALSE) -> 3 | K14: =VLOOKUP(A14,v_02_2023!A:D,4,FALSE) -> 31.71 | L14: =H14-J14 -> -2 | M14: =I14-K14 -> -21.14 | N14: =M14/K14 -> -0.66666667
A15: B011LFVLW8 | B15: 90.620 | C15: 24 | D15: 784.8 | E15: 0 | F15: 0 | G15: =F15/I15 -> 0 | H15: =E15+C15 -> 24 | I15: =F15+D15 -> 784.8 | J15: =VLOOKUP(A15,v_02_2023!A:D,3,FALSE) -> 103 | K15: =VLOOKUP(A15,v_02_2023!A:D,4,FALSE) -> 2946.83 | L15: =H15-J15 -> -79 | M15: =I15-K15 -> -2162.03 | N15: =M15/K15 -> -0.73367992
A16: B011LH9V8M | B16: 40.958V | C16: 1 | D16: 6.73 | E16: 0 | F16: 0 | G16: =F16/I16 -> 0 | H16: =E16+C16 -> 1 | I16: =F16+D16 -> 6.73 | J16: 0 | K16: 0 | L16: =H16-J16 -> 1 | M16: =I16-K16 -> 6.73
A17: B015T5GR0C | B17: 40.760 | C17: 1 | D17: 4.83 | E17: 0 | F17: 0 | G17: =F17/I17 -> 0 | H17: =E17+C17 -> 1 | I17: =F17+D17 -> 4.83 | J17: 0 | K17: 0 | L17: =H17-J17 -> 1 | M17: =I17-K17 -> 4.83
A18: B016MWFVIU | B18: 40.761 | C18: 1 | D18: 16.31 | E18: 0 | F18: 0 | G18: =F18/I18 -> 0 | H18: =E18+C18 -> 1 | I18: =F18+D18 -> 16.31 | J18: 0 | K18: 0 | L18: =H18-J18 -> 1 | M18: =I18-K18 -> 16.31
A19: B017IUJA50 | B19: 90.920G | C19: 293 | D19: 4779.63 | E19: =VLOOKUP(A19,s_02_2024!E:G,2,FALSE) -> 7 | F19: =VLOOKUP(A19,s_02_2024!E:G,3,FALSE) -> 155.61 | G19: =F19/I19 -> 0.031530382 | H19: =E19+C19 -> 300 | I19: =F19+D19 -> 4935.24 | J19: =VLOOKUP(A19,v_02_2023!A:D,3,FALSE) -> 468 | K19: =VLOOKUP(A19,v_02_2023!A:D,4,FALSE) -> 7132.71 | L19: =H19-J19 -> -168 | M19: =I19-K19 -> -2197.47 | N19: =M19/K19 -> -0.30808346
A20: B01CHW1L88 | B20: PE.001 | C20: 1 | D20: 9.54 | E20: 0 | F20: 0 | G20: =F20/I20 -> 0 | H20: =E20+C20 -> 1 | I20: =F20+D20 -> 9.54 | J20: 0 | K20: 0 | L20: =H20-J20 -> 1 | M20: =I20-K20 -> 9.54
A21: B01CHW1YD0 | B21: PE.140 | C21: 2 | D21: 19.03 | E21: 0 | F21: 0 | G21: =F21/I21 -> 0 | H21: =E21+C21 -> 2 | I21: =F21+D21 -> 19.03 | J21: 0 | K21: 0 | L21: =H21-J21 -> 2 | M21: =I21-K21 -> 19.03
A22: B01CHW20UQ | B22: PE.400 | C22: 1 | D22: 11.39 | E22: 0 | F22: 0 | G22: =F22/I22 -> 0 | H22: =E22+C22 -> 1 | I22: =F22+D22 -> 11.39 | J22: 0 | K22: 0 | L22: =H22-J22 -> 1 | M22: =I22-K22 -> 11.39
A23: B01CNX6UIM | B23: PE.300 | C23: 2 | D23: 10.81 | E23: 0 | F23: 0 | G23: =F23/I23 -> 0 | H23: =E23+C23 -> 2 | I23: =F23+D23 -> 10.81 | J23: 0 | K23: 0 | L23: =H23-J23 -> 2 | M23: =I23-K23 -> 10.81
A24: B01CNX6Z78 | B24: 90.820 | C24: 11 | D24: 244.89 | E24: 0 | F24: 0 | G24: =F24/I24 -> 0 | H24: =E24+C24 -> 11 | I24: =F24+D24 -> 244.89 | J24: =VLOOKUP(A24,v_02_2023!A:D,3,FALSE) -> 42 | K24: =VLOOKUP(A24,v_02_2023!A:D,4,FALSE) -> 878.33 | L24: =H24-J24 -> -31 | M24: =I24-K24 -> -633.44 | N24: =M24/K24 -> -0.7211868
A25: B01CNX704K | B25: 90.825 | C25: 1 | D25: 21.26 | E25: =VLOOKUP(A25,s_02_2024!E:G,2,FALSE) -> 5 | F25: =VLOOKUP(A25,s_02_2024!E:G,3,FALSE) -> 234.5 | G25: =F25/I25 -> 0.9168752 | H25: =E25+C25 -> 6 | I25: =F25+D25 -> 255.76 | J25: =VLOOKUP(A25,v_02_2023!A:D,3,FALSE) -> 2 | K25: =VLOOKUP(A25,v_02_2023!A:D,4,FALSE) -> 70.34 | L25: =H25-J25 -> 4 | M25: =I25-K25 -> 185.42 | N25: =M25/K25 -> 2.6360535
A26: B01CNX71NA | B26: 90.871 | C26: 9 | D26: 891.66 | E26: 0 | F26: 0 | G26: =F26/I26 -> 0 | H26: =E26+C26 -> 9 | I26: =F26+D26 -> 891.66 | J26: =VLOOKUP(A26,v_02_2023!A:D,3,FALSE) -> 7 | K26: =VLOOKUP(A26,v_02_2023!A:D,4,FALSE) -> 566.9 | L26: =H26-J26 -> 2 | M26: =I26-K26 -> 324.76 | N26: =M26/K26 -> 0.57286999
A27: B01CNXP36C | B27: 40.981N | C27: 1 | D27: 9.13 | E27: 0 | F27: 0 | G27: =F27/I27 -> 0 | H27: =E27+C27 -> 1 | I27: =F27+D27 -> 9.13 | J27: 0 | K27: 0 | L27: =H27-J27 -> 1 | M27: =I27-K27 -> 9.13
A28: B01HM47LF8 | B28: MD.004 | C28: 3 | D28: 10.22 | E28: 0 | F28: 0 | G28: =F28/I28 -> 0 | H28: =E28+C28 -> 3 | I28: =F28+D28 -> 10.22 | J28: =VLOOKUP(A28,v_02_2023!A:D,3,FALSE) -> 9 | K28: =VLOOKUP(A28,v_02_2023!A:D,4,FALSE) -> 30.95 | L28: =H28-J28 -> -6 | M28: =I28-K28 -> -20.73 | N28: =M28/K28 -> -0.66978998
A29: B01I497WWM | B29: 90.920R | C29: 4 | D29: 66.56 | E29: =VLOOKUP(A29,s_02_2024!E:G,2,FALSE) -> 1084 | F29: =VLOOKUP(A29,s_02_2024!E:G,3,FALSE) -> 21587.91 | G29: =F29/I29 -> 0.99692627 | H29: =E29+C29 -> 1088 | I29: =F29+D29 -> 21654.47 | J29: =VLOOKUP(A29,v_02_2023!A:D,3,FALSE) -> 2309 | K29: =VLOOKUP(A29,v_02_2023!A:D,4,FALSE) -> 31490.19 | L29: =H29-J29 -> -1221 | M29: =I29-K29 -> -9835.72 | N29: =M29/K29 -> -0.31234235
A30: B01IHGX2HQ | B30: MD.104 | C30: 13 | D30: 50.63 | E30: 0 | F30: 0 | G30: =F30/I30 -> 0 | H30: =E30+C30 -> 13 | I30: =F30+D30 -> 50.63 | J30: =VLOOKUP(A30,v_02_2023!A:D,3,FALSE) -> 2 | K30: =VLOOKUP(A30,v_02_2023!A:D,4,FALSE) -> 11.51 | L30: =H30-J30 -> 11 | M30: =I30-K30 -> 39.12 | N30: =M30/K30 -> 3.3987837
A31: B01II7S968 | B31: MD.217 | C31: 5 | D31: 29.95 | E31: 0 | F31: 0 | G31: =F31/I31 -> 0 | H31: =E31+C31 -> 5 | I31: =F31+D31 -> 29.95 | J31: =VLOOKUP(A31,v_02_2023!A:D,3,FALSE) -> 1 | K31: =VLOOKUP(A31,v_02_2023!A:D,4,FALSE) -> 5.46 | L31: =H31-J31 -> 4 | M31: =I31-K31 -> 24.49 | N31: =M31/K31 -> 4.485348
A32: B01K6P6NT0 | B32: 40.400 | C32: 0 | D32: 0 | E32: 0 | F32: 0 | H32: =E32+C32 -> 0 | I32: =F32+D32 -> 0 | J32: =VLOOKUP(A32,v_02_2023!A:D,3,FALSE) -> 1 | K32: =VLOOKUP(A32,v_02_2023!A:D,4,FALSE) -> 18.93 | L32: =H32-J32 -> -1 | M32: =I32-K32 -> -18.93 | N32: =M32/K32 -> -1
A33: B01KMJ9OXW | B33: 90.590Y | C33: 5 | D33: 145.4 | E33: =VLOOKUP(A33,s_02_2024!E:G,2,FALSE) -> 285 | F33: =VLOOKUP(A33,s_02_2024!E:G,3,FALSE) -> 9936.02 | G33: =F33/I33 -> 0.98557743 | H33: =E33+C33 -> 290 | I33: =F33+D33 -> 10081.42 | J33: =VLOOKUP(A33,v_02_2023!A:D,3,FALSE) -> 677 | K33: =VLOOKUP(A33,v_02_2023!A:D,4,FALSE) -> 21012.58 | L33: =H33-J33 -> -387 | M33: =I33-K33 -> -10931.16 | N33: =M33/K33 -> -0.52021979
A34: B01M4O6145 | B34: 90.071 | C34: 69 | D34: 1416.11 | E34: 0 | F34: 0 | G34: =F34/I34 -> 0 | H34: =E34+C34 -> 69 | I34: =F34+D34 -> 1416.11 | J34: =VLOOKUP(A34,v_02_2023!A:D,3,FALSE) -> 71 | K34: =VLOOKUP(A34,v_02_2023!A:D,4,FALSE) -> 1552.39 | L34: =H34-J34 -> -2 | M34: =I34-K34 -> -136.28 | N34: =M34/K34 -> -0.087787218
A35: B01MFA4H6K | B35: S304 | C35: 0 | D35: 0 | E35: 0 | F35: 0 | H35: =E35+C35 -> 0 | I35: =F35+D35 -> 0 | J35: 0 | K35: 0 | L35: =H35-J35 -> 0 | M35: =I35-K35 -> 0
A36: B01MTSEGF9 | B36: 50.700 | C36: 0 | D36: 0 | E36: =VLOOKUP(A36,s_02_2024!E:G,2,FALSE) -> 20 | F36: =VLOOKUP(A36,s_02_2024!E:G,3,FALSE) -> 898 | G36: =F36/I36 -> 1 | H36: =E36+C36 -> 20 | I36: =F36+D36 -> 898 | J36: =VLOOKUP(A36,v_02_2023!A:D,3,FALSE) -> 228 | K36: =VLOOKUP(A36,v_02_2023!A:D,4,FALSE) -> 6544.37 | L36: =H36-J36 -> -208 | M36: =I36-K36 -> -5646.37 | N36: =M36/K36 -> -0.86278282
A37: B01N12PI05 | B37: PE.301 | C37: 10 | D37: 36.22 | E37: 0 | F37: 0 | G37: =F37/I37 -> 0 | H37: =E37+C37 -> 10 | I37: =F37+D37 -> 36.22 | J37: 0 | K37: 0 | L37: =H37-J37 -> 10 | M37: =I37-K37 -> 36.22
A38: B01N4L0SUV | B38: 40.926 | C38: 1 | D38: 20.92 | E38: 0 | F38: 0 | G38: =F38/I38 -> 0 | H38: =E38+C38 -> 1 | I38: =F38+D38 -> 20.92 | J38: =VLOOKUP(A38,v_02_2023!A:D,3,FALSE) -> -1 | K38: =VLOOKUP(A38,v_02_2023!A:D,4,FALSE) -> -15.29 | L38: =H38-J38 -> 2 | M38: =I38-K38 -> 36.21 | N38: =M38/K38 -> -2.3682145
A39: B06W2JZMNV | B39: 90.200 | C39: 1 | D39: 36.58 | E39: 0 | F39: 0 | G39: =F39/I39 -> 0 | H39: =E39+C39 -> 1 | I39: =F39+D39 -> 36.58 | J39: 0 | K39: 0 | L39: =H39-J39 -> 1 | M39: =I39-K39 -> 36.58
A40: B06WGS8ZVG | B40: 90.131 | C40: 2 | D40: 25.04 | E40: 0 | F40: 0 | G40: =F40/I40 -> 0 | H40: =E40+C40 -> 2 | I40: =F40+D40 -> 25.04 | J40: =VLOOKUP(A40,v_02_2023!A:D,3,FALSE) -> 5 | K40: =VLOOKUP(A40,v_02_2023!A:D,4,FALSE) -> 56.77 | L40: =H40-J40 -> -3 | M40: =I40-K40 -> -31.73 | N40: =M40/K40 -> -0.55892197
...

Sheet IT
A1: ASIN | B1: SKU | C1: Ordini Vendor 24 | D1: Valori ordini Vendor 24 | E1: Ordini Seller 24 | F1: Valori ordini Seller 24 | G1: % seller / totale | H1: Ordini Complessivi 24 | I1: Valori ordini Complessivi 24 | J1: Ordini Vendor 23 | K1: Valori ordini Vendor 23 | L1: Differenza Ordini | M1: Differenza Valore | N1: Differenza Valore %
A2: B0050IHH4E | B2: 40.979 | C2: =VLOOKUP(A2,v_02_2024!F:I,3,FALSE) -> 311 | D2: =VLOOKUP(A2,v_02_2024!F:I,4,FALSE) -> 4876.26 | E2: =VLOOKUP(A2,s_02_2024!E:G,2,FALSE) -> 1 | F2: =VLOOKUP(A2,s_02_2024!E:G,3,FALSE) -> 19.9 | G2: =F2/I2 -> 0.0040644097 | H2: =E2+C2 -> 312 | I2: =F2+D2 -> 4896.16 | J2: =VLOOKUP(A2,v_02_2023!F:I,3,FALSE) -> 24 | K2: =VLOOKUP(A2,v_02_2023!F:I,4,FALSE) -> 312.72 | L2: =H2-J2 -> 288 | M2: =I2-K2 -> 4583.44 | N2: =M2/K2 -> 14.65669
A3: B00BH202XK | B3: 40.808A | C3: =VLOOKUP(A3,v_02_2024!F:I,3,FALSE) -> 1 | D3: =VLOOKUP(A3,v_02_2024!F:I,4,FALSE) -> 13.85 | E3: 0 | F3: 0 | G3: =F3/I3 -> 0 | H3: =E3+C3 -> 1 | I3: =F3+D3 -> 13.85 | J3: =VLOOKUP(A3,v_02_2023!F:I,3,FALSE) -> 2 | K3: =VLOOKUP(A3,v_02_2023!F:I,4,FALSE) -> 35.73 | L3: =H3-J3 -> -1 | M3: =I3-K3 -> -21.88 | N3: =M3/K3 -> -0.61237056
A4: B00EYDRS1I | B4: 90.349 | C4: =VLOOKUP(A4,v_02_2024!F:I,3,FALSE) -> 17 | D4: =VLOOKUP(A4,v_02_2024!F:I,4,FALSE) -> 102.19 | E4: 0 | F4: 0 | G4: =F4/I4 -> 0 | H4: =E4+C4 -> 17 | I4: =F4+D4 -> 102.19 | J4: =VLOOKUP(A4,v_02_2023!F:I,3,FALSE) -> 159 | K4: =VLOOKUP(A4,v_02_2023!F:I,4,FALSE) -> 878.28 | L4: =H4-J4 -> -142 | M4: =I4-K4 -> -776.09 | N4: =M4/K4 -> -0.88364758
A5: B00FAJUDU8 | B5: 40.967N | C5: 0 | D5: 0 | E5: =VLOOKUP(A5,s_02_2024!E:G,2,FALSE) -> 36 | F5: =VLOOKUP(A5,s_02_2024!E:G,3,FALSE) -> 1151.91 | G5: =F5/I5 -> 1 | H5: =E5+C5 -> 36 | I5: =F5+D5 -> 1151.91 | J5: =VLOOKUP(A5,v_02_2023!F:I,3,FALSE) -> 92 | K5: =VLOOKUP(A5,v_02_2023!F:I,4,FALSE) -> 1877.72 | L5: =H5-J5 -> -56 | M5: =I5-K5 -> -725.81 | N5: =M5/K5 -> -0.38653793
A6: B00FFBED98 | B6: 40.11 | C6: 0 | D6: 0 | E6: 0 | F6: 0 | H6: =E6+C6 -> 0 | I6: =F6+D6 -> 0 | J6: 0 | K6: 0 | L6: =H6-J6 -> 0 | M6: =I6-K6 -> 0
A7: B00FFBFVG2 | B7: 40.100 | C7: =VLOOKUP(A7,v_02_2024!F:I,3,FALSE) -> 0 | D7: =VLOOKUP(A7,v_02_2024!F:I,4,FALSE) -> 0 | E7: 0 | F7: 0 | H7: =E7+C7 -> 0 | I7: =F7+D7 -> 0 | J7: =VLOOKUP(A7,v_02_2023!F:I,3,FALSE) -> 3 | K7: =VLOOKUP(A7,v_02_2023!F:I,4,FALSE) -> 18.99 | L7: =H7-J7 -> -3 | M7: =I7-K7 -> -18.99 | N7: =M7/K7 -> -1
A8: B00FMZ2VW8 | B8: HK-HQ601C PINK | C8: 0 | D8: 0 | E8: 0 | F8: 0 | H8: =E8+C8 -> 0 | I8: =F8+D8 -> 0 | J8: 0 | K8: 0 | L8: =H8-J8 -> 0 | M8: =I8-K8 -> 0
A9: B00J7MNQFS | B9: 40.994 | C9: =VLOOKUP(A9,v_02_2024!F:I,3,FALSE) -> 3 | D9: =VLOOKUP(A9,v_02_2024!F:I,4,FALSE) -> 61.3 | E9: 0 | F9: 0 | G9: =F9/I9 -> 0 | H9: =E9+C9 -> 3 | I9: =F9+D9 -> 61.3 | J9: =VLOOKUP(A9,v_02_2023!F:I,3,FALSE) -> 3 | K9: =VLOOKUP(A9,v_02_2023!F:I,4,FALSE) -> 49.83 | L9: =H9-J9 -> 0 | M9: =I9-K9 -> 11.47 | N9: =M9/K9 -> 0.23018262
A10: B00L5GPWFG | B10: 40.120 | C10: =VLOOKUP(A10,v_02_2024!F:I,3,FALSE) -> 3 | D10: =VLOOKUP(A10,v_02_2024!F:I,4,FALSE) -> 73.53 | E10: 0 | F10: 0 | G10: =F10/I10 -> 0 | H10: =E10+C10 -> 3 | I10: =F10+D10 -> 73.53 | J10: =VLOOKUP(A10,v_02_2023!F:I,3,FALSE) -> 2 | K10: =VLOOKUP(A10,v_02_2023!F:I,4,FALSE) -> 49.02 | L10: =H10-J10 -> 1 | M10: =I10-K10 -> 24.51 | N10: =M10/K10 -> 0.5
A11: B00L5H5KUW | B11: 40.121 | C11: =VLOOKUP(A11,v_02_2024!F:I,3,FALSE) -> 424 | D11: =VLOOKUP(A11,v_02_2024!F:I,4,FALSE) -> 7577.95 | E11: 0 | F11: 0 | G11: =F11/I11 -> 0 | H11: =E11+C11 -> 424 | I11: =F11+D11 -> 7577.95 | J11: =VLOOKUP(A11,v_02_2023!F:I,3,FALSE) -> 202 | K11: =VLOOKUP(A11,v_02_2023!F:I,4,FALSE) -> 3294.62 | L11: =H11-J11 -> 222 | M11: =I11-K11 -> 4283.33 | N11: =M11/K11 -> 1.3000983
A12: B00NSNZSLM | B12: 90.602 | C12: =VLOOKUP(A12,v_02_2024!F:I,3,FALSE) -> 0 | D12: =VLOOKUP(A12,v_02_2024!F:I,4,FALSE) -> 0 | E12: =VLOOKUP(A12,s_02_2024!E:G,2,FALSE) -> 96 | F12: =VLOOKUP(A12,s_02_2024!E:G,3,FALSE) -> 2882.4 | G12: =F12/I12 -> 1 | H12: =E12+C12 -> 96 | I12: =F12+D12 -> 2882.4 | J12: =VLOOKUP(A12,v_02_2023!F:I,3,FALSE) -> 515 | K12: =VLOOKUP(A12,v_02_2023!F:I,4,FALSE) -> 10511.15 | L12: =H12-J12 -> -419 | M12: =I12-K12 -> -7628.75 | N12: =M12/K12 -> -0.72577691
A13: B00OKE4RTM | B13: 90.386 | C13: =VLOOKUP(A13,v_02_2024!F:I,3,FALSE) -> 3 | D13: =VLOOKUP(A13,v_02_2024!F:I,4,FALSE) -> 147.35 | E13: 0 | F13: 0 | G13: =F13/I13 -> 0 | H13: =E13+C13 -> 3 | I13: =F13+D13 -> 147.35 | J13: =VLOOKUP(A13,v_02_2023!F:I,3,FALSE) -> 1 | K13: =VLOOKUP(A13,v_02_2023!F:I,4,FALSE) -> 53.22 | L13: =H13-J13 -> 2 | M13: =I13-K13 -> 94.13 | N13: =M13/K13 -> 1.768696
A14: B00OLZPU5K | B14: 40.947 | C14: =VLOOKUP(A14,v_02_2024!F:I,3,FALSE) -> 1 | D14: =VLOOKUP(A14,v_02_2024!F:I,4,FALSE) -> 10.57 | E14: 0 | F14: 0 | G14: =F14/I14 -> 0 | H14: =E14+C14 -> 1 | I14: =F14+D14 -> 10.57 | J14: =VLOOKUP(A14,v_02_2023!F:I,3,FALSE) -> 3 | K14: =VLOOKUP(A14,v_02_2023!F:I,4,FALSE) -> 31.71 | L14: =H14-J14 -> -2 | M14: =I14-K14 -> -21.14 | N14: =M14/K14 -> -0.66666667
A15: B011LFVLW8 | B15: 90.620 | C15: =VLOOKUP(A15,v_02_2024!F:I,3,FALSE) -> 24 | D15: =VLOOKUP(A15,v_02_2024!F:I,4,FALSE) -> 784.8 | E15: 0 | F15: 0 | G15: =F15/I15 -> 0 | H15: =E15+C15 -> 24 | I15: =F15+D15 -> 784.8 | J15: =VLOOKUP(A15,v_02_2023!F:I,3,FALSE) -> 103 | K15: =VLOOKUP(A15,v_02_2023!F:I,4,FALSE) -> 2946.83 | L15: =H15-J15 -> -79 | M15: =I15-K15 -> -2162.03 | N15: =M15/K15 -> -0.73367992
A16: B011LH9V8M | B16: 40.958V | C16: =VLOOKUP(A16,v_02_2024!F:I,3,FALSE) -> 1 | D16: =VLOOKUP(A16,v_02_2024!F:I,4,FALSE) -> 6.73 | E16: 0 | F16: 0 | G16: =F16/I16 -> 0 | H16: =E16+C16 -> 1 | I16: =F16+D16 -> 6.73 | J16: 0 | K16: 0 | L16: =H16-J16 -> 1 | M16: =I16-K16 -> 6.73
A17: B015T5GR0C | B17: 40.760 | C17: 0 | D17: 0 | E17: 0 | F17: 0 | H17: =E17+C17 -> 0 | I17: =F17+D17 -> 0 | J17: 0 | K17: 0 | L17: =H17-J17 -> 0 | M17: =I17-K17 -> 0
A18: B016MWFVIU | B18: 40.761 | C18: =VLOOKUP(A18,v_02_2024!F:I,3,FALSE) -> 1 | D18: =VLOOKUP(A18,v_02_2024!F:I,4,FALSE) -> 16.31 | E18: 0 | F18: 0 | G18: =F18/I18 -> 0 | H18: =E18+C18 -> 1 | I18: =F18+D18 -> 16.31 | J18: 0 | K18: 0 | L18: =H18-J18 -> 1 | M18: =I18-K18 -> 16.31
A19: B017IUJA50 | B19: 90.920G | C19: =VLOOKUP(A19,v_02_2024!F:I,3,FALSE) -> 274 | D19: =VLOOKUP(A19,v_02_2024!F:I,4,FALSE) -> 4464.61 | E19: =VLOOKUP(A19,s_02_2024!E:G,2,FALSE) -> 7 | F19: =VLOOKUP(A19,s_02_2024!E:G,3,FALSE) -> 155.61 | G19: =F19/I19 -> 0.033680214 | H19: =E19+C19 -> 281 | I19: =F19+D19 -> 4620.22 | J19: =VLOOKUP(A19,v_02_2023!F:I,3,FALSE) -> 323 | K19: =VLOOKUP(A19,v_02_2023!F:I,4,FALSE) -> 5211.46 | L19: =H19-J19 -> -42 | M19: =I19-K19 -> -591.24 | N19: =M19/K19 -> -0.11344997
A20: B01CHW1L88 | B20: PE.001 | C20: =VLOOKUP(A20,v_02_2024!F:I,3,FALSE) -> 1 | D20: =VLOOKUP(A20,v_02_2024!F:I,4,FALSE) -> 9.54 | E20: 0 | F20: 0 | G20: =F20/I20 -> 0 | H20: =E20+C20 -> 1 | I20: =F20+D20 -> 9.54 | J20: 0 | K20: 0 | L20: =H20-J20 -> 1 | M20: =I20-K20 -> 9.54
A21: B01CHW1YD0 | B21: PE.140 | C21: 0 | D21: 0 | E21: 0 | F21: 0 | H21: =E21+C21 -> 0 | I21: =F21+D21 -> 0 | J21: 0 | K21: 0 | L21: =H21-J21 -> 0 | M21: =I21-K21 -> 0
A22: B01CHW20UQ | B22: PE.400 | C22: 0 | D22: 0 | E22: 0 | F22: 0 | H22: =E22+C22 -> 0 | I22: =F22+D22 -> 0 | J22: 0 | K22: 0 | L22: =H22-J22 -> 0 | M22: =I22-K22 -> 0
A23: B01CNX6UIM | B23: PE.300 | C23: 0 | D23: 0 | E23: 0 | F23: 0 | H23: =E23+C23 -> 0 | I23: =F23+D23 -> 0 | J23: 0 | K23: 0 | L23: =H23-J23 -> 0 | M23: =I23-K23 -> 0
A24: B01CNX6Z78 | B24: 90.820 | C24: 0 | D24: 0 | E24: 0 | F24: 0 | H24: =E24+C24 -> 0 | I24: =F24+D24 -> 0 | J24: 0 | K24: 0 | L24: =H24-J24 -> 0 | M24: =I24-K24 -> 0
A25: B01CNX704K | B25: 90.825 | C25: 0 | D25: 0 | E25: =VLOOKUP(A25,s_02_2024!E:G,2,FALSE) -> 5 | F25: =VLOOKUP(A25,s_02_2024!E:G,3,FALSE) -> 234.5 | G25: =F25/I25 -> 1 | H25: =E25+C25 -> 5 | I25: =F25+D25 -> 234.5 | J25: 0 | K25: 0 | L25: =H25-J25 -> 5 | M25: =I25-K25 -> 234.5
A26: B01CNX71NA | B26: 90.871 | C26: =VLOOKUP(A26,v_02_2024!F:I,3,FALSE) -> 5 | D26: =VLOOKUP(A26,v_02_2024!F:I,4,FALSE) -> 572.22 | E26: 0 | F26: 0 | G26: =F26/I26 -> 0 | H26: =E26+C26 -> 5 | I26: =F26+D26 -> 572.22 | J26: =VLOOKUP(A26,v_02_2023!F:I,3,FALSE) -> 4 | K26: =VLOOKUP(A26,v_02_2023!F:I,4,FALSE) -> 320.65 | L26: =H26-J26 -> 1 | M26: =I26-K26 -> 251.57 | N26: =M26/K26 -> 0.78456261
A27: B01CNXP36C | B27: 40.981N | C27: 0 | D27: 0 | E27: 0 | F27: 0 | H27: =E27+C27 -> 0 | I27: =F27+D27 -> 0 | J27: 0 | K27: 0 | L27: =H27-J27 -> 0 | M27: =I27-K27 -> 0
A28: B01HM47LF8 | B28: MD.004 | C28: =VLOOKUP(A28,v_02_2024!F:I,3,FALSE) -> 2 | D28: =VLOOKUP(A28,v_02_2024!F:I,4,FALSE) -> 6.98 | E28: 0 | F28: 0 | G28: =F28/I28 -> 0 | H28: =E28+C28 -> 2 | I28: =F28+D28 -> 6.98 | J28: =VLOOKUP(A28,v_02_2023!F:I,3,FALSE) -> 9 | K28: =VLOOKUP(A28,v_02_2023!F:I,4,FALSE) -> 30.95 | L28: =H28-J28 -> -7 | M28: =I28-K28 -> -23.97 | N28: =M28/K28 -> -0.77447496
A29: B01I497WWM | B29: 90.920R | C29: =VLOOKUP(A29,v_02_2024!F:I,3,FALSE) -> 2 | D29: =VLOOKUP(A29,v_02_2024!F:I,4,FALSE) -> 32.62 | E29: =VLOOKUP(A29,s_02_2024!E:G,2,FALSE) -> 1084 | F29: =VLOOKUP(A29,s_02_2024!E:G,3,FALSE) -> 21587.91 | G29: =F29/I29 -> 0.99849125 | H29: =E29+C29 -> 1086 | I29: =F29+D29 -> 21620.53 | J29: =VLOOKUP(A29,v_02_2023!F:I,3,FALSE) -> 2222 | K29: =VLOOKUP(A29,v_02_2023!F:I,4,FALSE) -> 30066.66 | L29: =H29-J29 -> -1136 | M29: =I29-K29 -> -8446.13 | N29: =M29/K29 -> -0.28091348
A30: B01IHGX2HQ | B30: MD.104 | C30: =VLOOKUP(A30,v_02_2024!F:I,3,FALSE) -> 13 | D30: =VLOOKUP(A30,v_02_2024!F:I,4,FALSE) -> 50.63 | E30: 0 | F30: 0 | G30: =F30/I30 -> 0 | H30: =E30+C30 -> 13 | I30: =F30+D30 -> 50.63 | J30: =VLOOKUP(A30,v_02_2023!F:I,3,FALSE) -> 2 | K30: =VLOOKUP(A30,v_02_2023!F:I,4,FALSE) -> 11.51 | L30: =H30-J30 -> 11 | M30: =I30-K30 -> 39.12 | N30: =M30/K30 -> 3.3987837
A31: B01II7S968 | B31: MD.217 | C31: =VLOOKUP(A31,v_02_2024!F:I,3,FALSE) -> 3 | D31: =VLOOKUP(A31,v_02_2024!F:I,4,FALSE) -> 18.15 | E31: 0 | F31: 0 | G31: =F31/I31 -> 0 | H31: =E31+C31 -> 3 | I31: =F31+D31 -> 18.15 | J31: 0 | K31: 0 | L31: =H31-J31 -> 3 | M31: =I31-K31 -> 18.15
A32: B01K6P6NT0 | B32: 40.400 | C32: 0 | D32: 0 | E32: 0 | F32: 0 | H32: =E32+C32 -> 0 | I32: =F32+D32 -> 0 | J32: 0 | K32: 0 | L32: =H32-J32 -> 0 | M32: =I32-K32 -> 0
A33: B01KMJ9OXW | B33: 90.590Y | C33: =VLOOKUP(A33,v_02_2024!F:I,3,FALSE) -> 0 | D33: =VLOOKUP(A33,v_02_2024!F:I,4,FALSE) -> 0 | E33: =VLOOKUP(A33,s_02_2024!E:G,2,FALSE) -> 285 | F33: =VLOOKUP(A33,s_02_2024!E:G,3,FALSE) -> 9936.02 | G33: =F33/I33 -> 1 | H33: =E33+C33 -> 285 | I33: =F33+D33 -> 9936.02 | J33: =VLOOKUP(A33,v_02_2023!F:I,3,FALSE) -> 327 | K33: =VLOOKUP(A33,v_02_2023!F:I,4,FALSE) -> 9421.49 | L33: =H33-J33 -> -42 | M33: =I33-K33 -> 514.53 | N33: =M33/K33 -> 0.054612381
A34: B01M4O6145 | B34: 90.071 | C34: =VLOOKUP(A34,v_02_2024!F:I,3,FALSE) -> 43 | D34: =VLOOKUP(A34,v_02_2024!F:I,4,FALSE) -> 877.63 | E34: 0 | F34: 0 | G34: =F34/I34 -> 0 | H34: =E34+C34 -> 43 | I34: =F34+D34 -> 877.63 | J34: =VLOOKUP(A34,v_02_2023!F:I,3,FALSE) -> 65 | K34: =VLOOKUP(A34,v_02_2023!F:I,4,FALSE) -> 1379.23 | L34: =H34-J34 -> -22 | M34: =I34-K34 -> -501.6 | N34: =M34/K34 -> -0.36368118
