Workbook

Sheet vendor_03_2023
A1: ASIN | B1: Numero del modello | C1: Codice marketplace | D1: Ricavi ordini | E1: Unità ordinate | F1: Ricavi spedizioni | G1: COGS spedizioni | H1: Unità spedite | I1: Resi cliente
A2: B07ZJQTGG8 | B2: 50.245 | C2: IT | D2: 22600.71 | E2: 1851 | F2: 22771.65 | G2: 14348.16 | H2: 1865 | I2: 55
A3: B01I497WWM | B3: 90.920R | C3: IT | D3: 18280.61 | E3: 1296 | F3: 18359.33 | G3: 11024.15 | H3: 1296 | I3: 115
A4: B096MX229M | B4: P102ROB050 | C4: DE | D4: 15499.76 | E4: 1238 | F4: 15850.32 | G4: 9798.32 | H4: 1266 | I4: 151
A5: B0757TJRR9 | B5: 40.500 | C5: IT | D5: 15132.43 | E5: 545 | F5: 14923.23 | G5: 9971.57 | H5: 537 | I5: 24
A6: B096MX229M | B6: P102ROB050 | C6: FR | D6: 13834.25 | E6: 1287 | F6: 13759 | G6: 9989.6 | H6: 1280 | I6: 63
A7: B0B8DLSNJF | B7: P302VIS050 | C7: IT | D7: 13374.2 | E7: 820 | F7: 13488.37 | G7: 11805.12 | H7: 827 | I7: 28
A8: B01KMJ9OXW | B8: 90.590Y | C8: FR | D8: 13050.89 | E8: 403 | F8: 13063.25 | G8: 8525.16 | H8: 403 | I8: 20
A9: B095PQJGKX | B9: C107UTT002 | C9: FR | D9: 12802.96 | E9: 1552 | F9: 12679.21 | G9: 8385.3 | H9: 1537 | I9: 14
A10: B095PQJGKX | B10: C107UTT002 | C10: ES | D10: 10264.25 | E10: 1255 | F10: 10583.27 | G10: 7059.84 | H10: 1294 | I10: 56
A11: B00NSNZSLM | B11: 90.602 | C11: IT | D11: 10082.54 | E11: 494 | F11: 10347.87 | G11: 8850.36 | H11: 507 | I11: 15
A12: B09146GTKW | B12: P302VIS002 | C12: IT | D12: 9561.69 | E12: 1179 | F12: 9537.36 | G12: 6878.4 | H12: 1176 | I12: 42
A13: B07ZJQTGG8 | B13: 50.245 | C13: FR | D13: 9041.76 | E13: 728 | F13: 9066.6 | G13: 6083.02 | H13: 730 | I13: 26
... A43: B085R2GCKX | B43: 40.332 | C43: IT | D43: 3828.87 | E43: 261 | F43: 3916.89 | G43: 2152.1 | H43: 267 | I43: 16
A44: B0050IHH4E | B44: 40.979 | C44: IT | D44: 3824.22 | E44: 294 | F44: 3516.1 | G44: 2750.5 | H44: 270
A45: B07N4C3H3V | B45: 40.405 | C45: DE | D45: 3741.4 | E45: 373 | F45: 3763.11 | G45: 2412.72 | H45: 375 | I45: 11
A46: B085JJ8RC6 | B46: BB.050 | C46: FR | D46: 3674.54 | E46: 269 | F46: 3783.82 | G46: 2907.52 | H46: 277 | I46: 18
A47: B0757TJRR9 | B47: 40.500 | C47: FR | D47: 3633.84 | E47: 132 | F47: 3559.08 | G47: 2427.48 | H47: 129 | I47: 9
A48: B096MX229M | B48: P102ROB050 | C48: ES | D48: 3631.45 | E48: 295 | F48: 3656.07 | G48: 2265.6 | H48: 297 | I48: 42
A49: B0BJ2TBPJW | B49: C206UTI004 | C49: IT | D49: 3594.46 | E49: 879 | F49: 3545.38 | G49: 2336.74 | H49: 867 | I49: 1
A50: B08GY7286R | B50: P203TFO001 | C50: IT | D50: 3586.73 | E50: 199 | F50: 3680.72 | G50: 2055.59 | H50: 204 | I50: 31
A51: B08L9D9KR9 | B51: P202VAL001 | C51: IT | D51: 3502.16 | E51: 71 | F51: 3598.9 | G51: 3244.7 | H51: 73 | I51: 11
A52: B07NQ2VYGD | B52: BT.710Y | C52: FR | D52: 3496.67 | E52: 97 | F52: 3618.23 | G52: 1786.7 | H52: 100 | I52: 6
A53: B07NQC6S9V | B53: BT.651Y | C53: FR | D53: 3480.06 | E53: 93 | F53: 3517.48 | G53: 3172.5 | H53: 94 | I53: 2
A54: B097HRQNRG | B54: P101FRI100 | C54: DE | D54: 3436.04 | E54: 110 | F54: 3343.01 | G54: 1996.44 | H54: 107 | I54: 26
A55: B06Y195DJN | B55: 90.882 | C55: FR | D55: 3207.82 | E55: 77 | F55: 3082.84 | G55: 2278.9 | H55: 74 | I55: 13
A56: B088XJQ37J | B56: C301ABE001 | C56: IT | D56: 3202.71 | E56: 303 | F56: 3266.13 | G56: 2111.52 | H56: 309 | I56: 29
... A60: B095X9KDJR | B60: P101BOL100 | C60: FR | D60: 2865.04 | E60: 173 | F60: 2815.3 | G60: 2284.5 | H60: 170 | I60: 12
A61: B08LZN1PWY | B61: P101TEM001 | C61: FR | D61: 2840.19 | E61: 33 | F61: 2580.48 | G61: 1385.22 | H61: 30
A62: B08B66J4C3 | B62: P101PIA001 | C62: DE | D62: 2817.35 | E62: 224 | F62: 2804.83 | G62: 1480.67 | H62: 223 | I62: 13
A63: B084C3JTC2 | B63: 40.406 | C63: IT | D63: 2745.12 | E63: 112 | F63: 2549.04 | G63: 1965.39 | H63: 104 | I63: 8
A64: B085JHTR6Q | B64: BP.790 | C64: IT | D64: 2653.39 | E64: 129 | F64: 2641.18 | G64: 2101.28 | H64: 128 | I64: 7
A65: B09B47S644 | B65: P101CUD501 | C65: FR | D65: 2594.99 | E65: 89 | F65: 2567.29 | G65: 1743.4 | H65: 88 | I65: 5
A66: B0B8DLSNJF | B66: P302VIS050 | C66: ES | D66: 2549.75 | E66: 155 | F66: 2516.85 | G66: 2210.83 | H66: 153 | I66: 5
A67: B07NQ1T7YK | B67: BP.101H | C67: IT | D67: 2539.68 | E67: 208 | F67: 2637.36 | G67: 2303.04 | H67: 216 | I67: 11
A68: B07KYWNC7Z | B68: 40.405 | C68: IT | D68: 2535.71 | E68: 129 | F68: 2358.64 | G68: 1998 | H68: 120 | I68: 4
A69: B07NQ2VYGD | B69: BT.710Y | C69: ES | D69: 2446.29 | E69: 99 | F69: 2495.71 | G69: 1815.68 | H69: 101 | I69: 16
A70: B07HM7P6MP | B70: RI.080 | C70: IT | D70: 2439.18 | E70: 112 | F70: 2456.68 | G70: 1976.48 | H70: 113 | I70: 7
A71: B0BD83RNDG | B71: C106CAS002 | C71: IT | D71: 2420.53 | E71: 229 | F71: 2441.67 | G71: 1997.1 | H71: 231 | I71: 1
A72: B076QFRRZ5 | B72: 40.931 | C72: IT | D72: 2411.94 | E72: 178 | F72: 2412.83 | G72: 1199.32 | H72: 178 | I72: 25
...

Sheet vendor_03_2024
A1: ASIN | B1: Numero del modello | C1: Codice marketplace | D1: Ricavi ordini | E1: Unità ordinate | F1: Ricavi spedizioni | G1: COGS spedizioni | H1: Unità spedite | I1: Resi cliente
A2: B0BHHV552D | B2: P203TER201 | C2: IT | D2: 9074.87 | E2: 558 | F2: 8862.85 | G2: 6568.29 | H2: 545 | I2: 85
A3: B0050IHH4E | B3: 40.979 | C3: DE | D3: 8964.88 | E3: 634 | F3: 8911.52 | G3: 5696.78 | H3: 626 | I3: 45
A4: B0050IHH4E | B4: 40.979 | C4: IT | D4: 6983.03 | E4: 486 | F4: 6700.53 | G4: 4517.98 | H4: 466 | I4: 15
A5: B09146GTKW | B5: P302VIS002 | C5: IT | D5: 5723.45 | E5: 544 | F5: 5533.77 | G5: 3168 | H5: 528 | I5: 28
A6: B096MX229M | B6: P102ROB050 | C6: DE | D6: 5380.42 | E6: 431 | F6: 5105.68 | G6: 3225.2 | H6: 409 | I6: 31
A7: B0CLVS3FH6 | B7: P201UTP111 | C7: IT | D7: 5284.44 | E7: 324 | F7: 4990.86 | G7: 4284 | H7: 306 | I7: 24
A8: B00L5H5KUW | B8: 40.121 | C8: IT | D8: 5023.29 | E8: 275 | F8: 4969.44 | G8: 3229 | H8: 272
A9: B0BBH12BYN | B9: P101COS001 | C9: IT | D9: 5001.34 | E9: 57 | F9: 5079.94 | G9: 3342.7 | H9: 58 | I9: 16
A10: B07SSLRCT6 | B10: BP.304 | C10: FR | D10: 3652.58 | E10: 253 | F10: 3770.46 | G10: 2744.2 | H10: 262 | I10: 23
A11: B07Q38Z7CK | B11: BC.060 | C11: IT | D11: 3399.3 | E11: 168 | F11: 3460.53 | G11: 2565 | H11: 171 | I11: 34
A12: B09968BKDS | B12: P102FRU003 | C12: FR | D12: 2885.72 | E12: 203 | F12: 2835.81 | G12: 1745.72 | H12: 200 | I12: 20
A13: B07JGVMFY1 | B13: BP.581 | C13: FR | D13: 2760.2 | E13: 185 | F13: 2715.44 | G13: 1833.8 | H13: 182 | I13: 15
A14: B08GY7286R | B14: P203TFO001 | C14: IT | D14: 2651.93 | E14: 191 | F14: 2734.11 | G14: 1960.2 | H14: 198 | I14: 15
A15: B07V131F5W | B15: 40.490 | C15: IT | D15: 2591.61 | E15: 105 | F15: 2542.59 | G15: 1854 | H15: 103 | I15: 1
A16: B0B39H1Z8J | B16: C106CAS001 | C16: IT | D16: 2397.59 | E16: 222 | F16: 2343.81 | G16: 1140.12 | H16: 217 | I16: 30
A17: B0CLY2CF4T | B17: P201UTP113 | C17: IT | D17: 2234.47 | E17: 137 | F17: 2201.85 | G17: 1890 | H17: 135 | I17: 5
A18: B0BJ2TBPJW | B18: C206UTI004 | C18: IT | D18: 2224.23 | E18: 453 | F18: 2199.68 | G18: 950.98 | H18: 448 | I18: 1
A19: B076QCMZX1 | B19: 40.821 | C19: IT | D19: 1977.32 | E19: 162 | F19: 1989.53 | G19: 1371.9 | H19: 163 | I19: 13
A20: B0B8JVTQYQ | B20: P101CUD200 | C20: DE | D20: 1957.21 | E20: 42 | F20: 1957.21 | G20: 1438.29 | H20: 42 | I20: 21
... A63: B0BNNH9RZQ | B63: P302VIS060 | C63: ES | D63: 900.25 | E63: 72 | F63: 900.25 | G63: 502.92 | H63: 72 | I63: 37
A64: B07NQ2VYGD | B64: BT.710Y | C64: ES | D64: 864.85 | E64: 35 | F64: 1087.24 | G64: 765.6 | H64: 44
A65: B07NQ1T7YK | B65: BP.101H | C65: FR | D65: 856.06 | E65: 61 | F65: 980.44 | G65: 703.36 | H65: 72 | I65: 10
A66: B0CLVS3FH6 | B66: P201UTP111 | C66: DE | D66: 853.17 | E66: 45 | F66: 853.17 | G66: 630 | H66: 45 | I66: 3
A67: B09D8G2H7Q | B67: P102SBA500 | C67: IT | D67: 842.72 | E67: 8 | F67: 842.72 | G67: 646.4 | H67: 8 | I67: 11
A68: B07V131F5W | B68: 40.490 | C68: ES | D68: 819.64 | E68: 34 | F68: 716.59 | G68: 522 | H68: 29 | I68: 1
A69: B076DCL19C | B69: BP.720 | C69: IT | D69: 814.3 | E69: 17 | F69: 814.3 | G69: 670.85 | H69: 17 | I69: 6
A70: B09D8G2H7Q | B70: P102SBA500 | C70: FR | D70: 755.38 | E70: 7 | F70: 644.75 | G70: 484.8 | H70: 6
A71: B01M4O6145 | B71: 90.071 | C71: IT | D71: 755.17 | E71: 37 | F71: 693.94 | G71: 657.9 | H71: 34 | I71: 4
A72: B0B2F48ZMP | B72: P102GEL100 | C72: FR | D72: 723.25 | E72: 21 | F72: 689.72 | G72: 598.4 | H72: 20 | I72: 2
A73: B09BD8BG34 | B73: P301PIS001 | C73: DE | D73: 713.64 | E73: 57 | F73: 688.6 | G73: 484 | H73: 55 | I73: 8
A74: B08FMLPKY9 | B74: P201UTP004 | C74: FR | D74: 712.94 | E74: 43 | F74: 712.94 | G74: 580.5 | H74: 43 | I74: 8
A75: B085R2GCKX | B75: 40.332 | C75: IT | D75: 712.92 | E75: 43 | F75: 664.39 | G75: 450 | H75: 40 | I75: 14
A76: B07ZJMFB3R | B76: BC.510 | C76: IT | D76: 709.12 | E76: 12 | F76: 709.12 | G76: 556.8 | H76: 12 | I76: 6
A77: B0B8JVTQYQ | B77: P101CUD200 | C77: ES | D77: 701.68 | E77: 18 | F77: 712.34 | G77: 615.6 | H77: 18 | I77: 1
A78: B08JYWF3PK | B78: C102COC101 | C78: FR | D78: 701.25 | E78: 85 | F78: 726 | G78: 528 | H78: 88
A79: B0BD83RNDG | B79: C106CAS002 | C79: IT | D79: 690.53 | E79: 62 | F79: 722.24 | G79: 479.37 | H79: 65 | I79: 4
A80: B07R984VMS | B80: BI.505 | C80: FR | D80: 687.96 | E80: 93 | F80: 687.96 | G80: 587.76 | H80: 93 | I80: 1
A81: B011LFVLW8 | B81: 90.620 | C81: IT | D81: 686.19 | E81: 19 | F81: 751.59 | G81: 567 | H81: 21 | I81: 6
A82: B06Y1997YH | B82: 90.883 | C82: IT | D82: 685.1 | E82: 11 | F82: 742.4 | G82: 511.44 | H82: 12 | I82: 4
...

Sheet seller_03_2024
A1: amazon-order-id | B1: merchant-order-id | C1: purchase-date | D1: last-updated-date | E1: order-status | F1: fulfillment-channel | G1: sales-channel | H1: order-channel | I1: url | J1: ship-service-level | K1: product-name | L1: sku | M1: asin | N1: item-status | O1: quantity | P1: currency | Q1: item-price | R1: item-tax | S1: shipping-price | T1: shipping-tax | U1: gift-wrap-price | V1: gift-wrap-tax | W1: item-promotion-discount | X1: ship-promotion-discount | Y1: ship-city | Z1: ship-state | AA1: ship-postal-code | AB1: ship-country | AC1: promotion-ids | AD1: buyer-company-name | AE1: buyer-cst-number | AF1: buyer-vat-number | AG1: buyer-tax-registration-id | AH1: buyer-tax-registration-country | AI1: buyer-tax-registration-type
A2: 171-1499659-3176339 | B2: 171-1499659-3176339 | C2: 2024-03-31T20:39:14+00:00 | D2: 2024-03-31T20:40:22+00:00 | E2: Pending | F2: Amazon | G2: Amazon.fr | J2: Standard | K2: BEPER 40.405 Seche Cheveux de Voyage Pliable - Mini Seche Cheveux Silencieux, 2 Températures et 2 Vitesses | L2: 40.405_FBA | M2: B07N4C3H3V | N2: Unshipped | O2: 1 | P2: EUR | Q2: 19.9 | Y2: Courchevel | AA2: 73120 | AB2: FR
A3: 171-2567557-4574741 | B3: 171-2567557-4574741 | C3: 2024-03-31T18:05:43+00:00 | D3: 2024-04-03T01:23:10+00:00 | E3: Shipped | F3: Amazon | G3: Amazon.fr | J3: Standard | K3: Beper - Cuiseur à Vapeur Multicombustion de 5L, Économiseur d'Espace, Minuterie de 60 minutes, Cuisson à la Vapeur Saine, Puissance 400-500W - Arge | L3: BC.261_FBA | M3: B08485QRVZ | N3: Shipped | O3: 1 | P3: EUR | Q3: 39.9 | R3: 6.65 | Y3: Rouen | AA3: 76100 | AB3: FR | AC3: Free Shipping 2017/10/17 17-17-37-677
A4: 403-1418796-1133936 | B4: 403-1418796-1133936 | C4: 2024-03-31T17:41:39+00:00 | D4: 2024-04-03T11:19:38+00:00 | E4: Shipped | F4: Amazon | G4: Amazon.fr | J4: Standard | K4: Beper - Machine à Pop-Corn, Pop-Corn en 3 Minutes, Sans Matières Grasses, Circulation d'Air Chaud, Puissance 1200W - Rouge [Classe d'efficacité én | L4: 90.590Y_FBA | M4: B01KMJ9OXW | N4: Shipped | O4: 1 | P4: EUR | Q4: 44.9 | R4: 7.48 | Y4: St Maur Des Fosses | AA4: 94100 | AB4: FR | AC4: Free Shipping 2017/10/17 17-17-37-677
A5: 408-9283493-4561146 | B5: 408-9283493-4561146 | C5: 2024-03-31T16:12:40+00:00 | D5: 2024-04-02T08:32:56+00:00 | E5: Shipped | F5: Amazon | G5: Amazon.fr | J5: Standard | K5: Beper - Machine à Pop-Corn, Pop-Corn en 3 Minutes, Sans Matières Grasses, Circulation d'Air Chaud, Puissance 1200W - Rouge [Classe d'efficacité én | L5: 90.590Y_FBA | M5: B01KMJ9OXW | N5: Shipped | O5: 1 | P5: EUR | Q5: 44.9 | R5: 7.48 | Y5: Leaz | AA5: 1200 | AB5: FR | AC5: Free Shipping 2017/10/17 17-17-37-677
A6: 408-8270481-5314704 | B6: 408-8270481-5314704 | C6: 2024-03-31T16:11:15+00:00 | D6: 2024-04-03T06:49:33+00:00 | E6: Shipped | F6: Amazon | G6: Amazon.fr | J6: Standard | K6: Beper - Mixeur électrique pour milkshakes, frappés, milkshakes et cocktails, 2 vitesses, bol en aluminium 0,5 l, 100 W,Rouge | L6: BP.690_FBA | M6: B07TQVD94L | N6: Shipped | O6: 1 | P6: EUR | Q6: 50.31 | R6: 8.73 | S6: 2.47 | X6: 2.47 | Y6: Charleroi | Z6: Hainaut | AA6: 6061 | AB6: BE | AC6: Free Shipping 2017/10/17 17-17-37-677
A7: 405-0123604-5319535 | B7: 405-0123604-5319535 | C7: 2024-03-31T16:08:17+00:00 | D7: 2024-04-03T01:19:42+00:00 | E7: Shipped | F7: Amazon | G7: Amazon.fr | J7: Standard | K7: BEPER BT.710Y Crêpière électrique avec poignée, 800 W, plaque en aluminium avec revêtement antiadhésif, rouge | L7: BT.710Y_FBA | M7: B07NQ2VYGD | N7: Shipped | O7: 1 | P7: EUR | Q7: 39.9 | R7: 6.65 | S7: 1.66 | X7: 1.66 | Y7: Tournefeuille | AA7: 31170 | AB7: FR | AC7: Free Shipping 2017/10/17 17-17-37-677
A8: 171-2425871-7294725 | B8: 171-2425871-7294725 | C8: 2024-03-31T15:32:09+00:00 | D8: 2024-04-02T08:21:18+00:00 | E8: Shipped | F8: Amazon | G8: Amazon.fr | J8: Expedited | K8: Beper - Machine à Pop-Corn, Pop-Corn en 3 Minutes, Sans Matières Grasses, Circulation d'Air Chaud, Puissance 1200W - Rouge [Classe d'efficacité én | L8: 90.590Y_FBA | M8: B01KMJ9OXW | N8: Shipped | O8: 1 | P8: EUR | Q8: 44.9 | R8: 7.48 | Y8: Paris | AA8: 75017 | AB8: FR
A9: 408-1342122-3264351 | B9: 408-1342122-3264351 | C9: 2024-03-31T14:30:58+00:00 | D9: 2024-04-02T21:44:00+00:00 | E9: Shipped | F9: Amazon | G9: Amazon.fr | J9: Standard | K9: BEPER BT.710Y Crêpière électrique avec poignée, 800 W, plaque en aluminium avec revêtement antiadhésif, rouge | L9: BT.710Y_FBA | M9: B07NQ2VYGD | N9: Shipped | O9: 1 | P9: EUR | Q9: 39.9 | R9: 6.65 | Y9: Menthon-Saint-Bernard | AA9: 74290 | AB9: FR | AC9: Free Shipping 2017/10/17 17-17-37-677
A10: 402-0602668-1374723 | B10: 402-0602668-1374723 | C10: 2024-03-31T10:15:14+00:00 | D10: 2024-04-02T03:09:01+00:00 | E10: Shipped | F10: Amazon | G10: Amazon.fr | J10: Standard | K10: Beper - Masseur Anti-Cellulite pour Femme 4 en 1, Massage Infrarouge, Triple Action Circulaire, Tonifiant et Raffermissant, Puissance Réglable, Syst | L10: 40.500_FBA | M10: B0757TJRR9 | N10: Shipped | O10: 1 | P10: EUR | Q10: 44.9 | R10: 7.48 | Y10: Lagny sur marne | AA10: 77400 | AB10: FR | AC10: Free Shipping 2017/10/17 17-17-37-677
A11: 405-1320381-2982755 | B11: 405-1320381-2982755 | C11: 2024-03-31T01:30:27+00:00 | D11: 2024-04-03T01:21:31+00:00 | E11: Shipped | F11: Amazon | G11: Amazon.fr | J11: Standard | K11: BEPER 40.405 Seche Cheveux de Voyage Pliable - Mini Seche Cheveux Silencieux, 2 Températures et 2 Vitesses | L11: 40.405_FBA | M11: B07N4C3H3V | N11: Shipped | O11: 1 | P11: EUR | Q11: 19.9 | R11: 3.32 | S11: 3.99 | T11: 0.67 | Y11: CLICHY | AA11: 92110 | AB11: FR
A12: 402-4932270-9549137 | B12: 402-4932270-9549137 | C12: 2024-03-30T16:03:08+00:00 | D12: 2024-04-01T14:51:17+00:00 | E12: Shipped | F12: Amazon | G12: Amazon.fr | J12: Standard | K12: Beper - Machine à Pop-Corn, Pop-Corn en 3 Minutes, Sans Matières Grasses, Circulation d'Air Chaud, Puissance 1200W - Rouge [Classe d'efficacité én | L12: 90.590Y_FBA | M12: B01KMJ9OXW | N12: Shipped | O12: 1 | P12: EUR | Q12: 44.9 | R12: 7.48 | Y12: Lyon | AA12: 69004 | AB12: FR | AC12: Free Shipping 2017/10/17 17-17-37-677
A13: 404-3244453-6181163 | B13: 404-3244453-6181163 | C13: 2024-03-30T14:51:27+00:00 | D13: 2024-04-01T15:06:43+00:00 | E13: Shipped | F13: Amazon | G13: Amazon.fr | J13: Expedited | K13: BEPER BT.710Y Crêpière électrique avec poignée, 800 W, plaque en aluminium avec revêtement antiadhésif, rouge | L13: BT.710Y_FBA | M13: B07NQ2VYGD | N13: Shipped | O13: 1 | P13: EUR | Q13: 39.9 | R13: 6.65 | Y13: St Simeon De Bressieux | AA13: 38870 | AB13: FR
A14: 404-3364024-5653124 | B14: 404-3364024-5653124 | C14: 2024-03-29T18:41:04+00:00 | D14: 2024-04-02T03:08:43+00:00 | E14: Shipped | F14: Amazon | G14: Amazon.fr | J14: Standard | K14: Beper - Masseur Anti-Cellulite pour Femme 4 en 1, Massage Infrarouge, Triple Action Circulaire, Tonifiant et Raffermissant, Puissance Réglable, Syst | L14: 40.500_FBA | M14: B0757TJRR9 | N14: Shipped | O14: 1 | P14: EUR | Q14: 44.9 | R14: 7.48 | Y14: St Sebastien De Morsent | AA14: 27180 | AB14: FR | AC14: Free Shipping 2017/10/17 17-17-37-677
A15: 407-4288541-7357165 | B15: 407-4288541-7357165 | C15: 2024-03-29T17:44:52+00:00 | D15: 2024-04-02T01:26:35+00:00 | E15: Shipped | F15: Amazon | G15: Amazon.fr | J15: Standard | K15: BEPER 40.405 Seche Cheveux de Voyage Pliable - Mini Seche Cheveux Silencieux, 2 Températures et 2 Vitesses | L15: 40.405_FBA | M15: B07N4C3H3V | N15: Shipped | O15: 1 | P15: EUR | Q15: 19.9 | R15: 3.32 | Y15: St Jean De Vedas | AA15: 34430 | AB15: FR
A16: 404-3316547-5440357 | B16: 404-3316547-5440357 | C16: 2024-03-29T16:09:40+00:00 | D16: 2024-04-02T06:19:12+00:00 | E16: Shipped | F16: Amazon | G16: Amazon.fr | J16: Standard | K16: Beper - Mixeur électrique pour milkshakes, frappés, milkshakes et cocktails, 2 vitesses, bol en aluminium 0,5 l, 100 W,Rouge | L16: BP.690_FBA | M16: B07TQVD94L | N16: Shipped | O16: 1 | P16: EUR | Q16: 49.9 | R16: 8.32 | Y16: bram | AA16: 11150 | AB16: FR | AC16: Free Shipping 2017/10/17 17-17-37-677
A17: 403-1219089-2709129 | B17: 403-1219089-2709129 | C17: 2024-03-29T15:10:55+00:00 | D17: 2024-04-01T23:28:53+00:00 | E17: Shipped | F17: Amazon | G17: Amazon.fr | J17: Standard | K17: BEPER BT.710Y Crêpière électrique avec poignée, 800 W, plaque en aluminium avec revêtement antiadhésif, rouge | L17: BT.710Y_FBA | M17: B07NQ2VYGD | N17: Shipped | O17: 1 | P17: EUR | Q17: 39.9 | R17: 6.65 | Y17: manduel | AA17: 30129 | AB17: FR | AC17: Free Shipping 2017/10/17 17-17-37-677
A18: 408-0336320-0378768 | B18: 408-0336320-0378768 | C18: 2024-03-29T11:39:03+00:00 | D18: 2024-04-02T07:58:22+00:00 | E18: Shipped | F18: Amazon | G18: Amazon.fr | J18: Standard | K18: BEPER BT.710Y Crêpière électrique avec poignée, 800 W, plaque en aluminium avec revêtement antiadhésif, rouge | L18: BT.710Y_FBA | M18: B07NQ2VYGD | N18: Shipped | O18: 1 | P18: EUR | Q18: 39.9 | R18: 6.65 | S18: 1.67 | X18: 1.67 | Y18: Toulouse | AA18: 31300 | AB18: FR | AC18: Free Shipping 2017/10/17 17-17-37-677
A19: 404-8488041-3782750 | B19: 404-8488041-3782750 | C19: 2024-03-29T10:53:18+00:00 | D19: 2024-04-01T23:35:49+00:00 | E19: Shipped | F19: Amazon | G19: Amazon.fr | J19: Expedited | K19: BEPER BT.710Y Crêpière électrique avec poignée, 800 W, plaque en aluminium avec revêtement antiadhésif, rouge | L19: BT.710Y_FBA | M19: B07NQ2VYGD | N19: Shipped | O19: 1 | P19: EUR | Q19: 39.9 | R19: 6.65 | Y19: Chéry-lès-Pouilly les Pouilly | AA19: 2000 | AB19: FR
A20: 404-0715395-8282712 | B20: 404-0715395-8282712 | C20: 2024-03-29T09:13:00+00:00 | D20: 2024-04-01T23:28:54+00:00 | E20: Shipped | F20: Amazon | G20: Amazon.fr | J20: Expedited | K20: BEPER BT.710Y Crêpière électrique avec poignée, 800 W, plaque en aluminium avec revêtement antiadhésif, rouge | L20: BT.710Y_FBA | M20: B07NQ2VYGD | N20: Shipped | O20: 1 | P20: EUR | Q20: 39.9 | R20: 6.65 | Y20: Charly sur Marne | AA20: 2310 | AB20: FR
A21: 171-9233986-7715553 | B21: 171-9233986-7715553 | C21: 2024-03-28T20:47:58+00:00 | D21: 2024-04-02T03:09:10+00:00 | E21: Shipped | F21: Amazon | G21: Amazon.fr | J21: Expedited | K21: BEPER 50.245 Rasoir Anti Lames en Acier-Appareil pour Enlever Les Bouloches, USB Inclus, Blanc/Octane | L21: 50.245_FBA | M21: B07ZJQTGG8 | N21: Shipped | O21: 1 | P21: EUR | Q21: 19.9 | R21: 3.32 | Y21: BETHUNE | AA21: 62400 | AB21: FR
A22: 404-3211334-1069112 | B22: 404-3211334-1069112 | C22: 2024-03-28T19:08:48+00:00 | D22: 2024-03-30T02:37:00+00:00 | E22: Shipped | F22: Amazon | G22: Amazon.fr | J22: Expedited | K22: BEPER 50.700 Nettoyeur Vapeur pour Sol, Canapé, Tapis - Nettoyant Vapeur, 135° max, câble de 3 Mètres, 350 ml | L22: 50.700_FBA | M22: B01MTSEGF9 | N22: Shipped | O22: 1 | P22: EUR | Q22: 49.9 | R22: 8.32 | Y22: Foussemagne | AA22: 90150 | AB22: FR
A23: 406-4192736-4919565 | B23: 406-4192736-4919565 | C23: 2024-03-28T16:53:31+00:00 | D23: 2024-03-30T09:28:29+00:00 | E23: Shipped | F23: Amazon | G23: Amazon.fr | J23: Expedited | K23: Beper - Machine à Pop-Corn, Pop-Corn en 3 Minutes, Sans Matières Grasses, Circulation d'Air Chaud, Puissance 1200W - Rouge [Classe d'efficacité én | L23: 90.590Y_FBA | M23: B01KMJ9OXW | N23: Shipped | O23: 1 | P23: EUR | Q23: 44.9 | R23: 7.48 | Y23: Ascarat | AA23: 64220 | AB23: FR
A24: 405-1278468-6947524 | B24: 405-1278468-6947524 | C24: 2024-03-28T11:22:00+00:00 | D24: 2024-03-29T02:22:17+00:00 | E24: Shipped | F24: Amazon | G24: Amazon.fr | J24: Standard | K24: Beper - Vert & Blanc Sauna Facial et Aromathérapie 2 Puissances, Traitements Curatifs et Relaxants, Hydratation et Nettoyage du Visage, Réservoir d' | L24: 40.967N_FBA | M24: B00FAJUDU8 | N24: Shipped | O24: 1 | P24: EUR | Q24: 39.9 | R24: 6.65 | Y24: levallois perret | Z24: - | AA24: 92300 | AB24: FR | AC24: Free Shipping 2017/10/17 17-17-37-677
A25: 408-0927499-4843517 | B25: 408-0927499-4843517 | C25: 2024-03-28T10:22:50+00:00 | D25: 2024-03-29T08:09:44+00:00 | E25: Shipped | F25: Amazon | G25: Amazon.fr | J25: Standard | K25: BEPER BT.710Y Crêpière électrique avec poignée, 800 W, plaque en aluminium avec revêtement antiadhésif, rouge | L25: BT.710Y_FBA | M25: B07NQ2VYGD | N25: Shipped | O25: 1 | P25: EUR | Q25: 39.9 | R25: 6.65 | S25: 3.32 | X25: 3.32 | Y25: CHATEAURENARD | AA25: 13160 | AB25: FR | AC25: Free Shipping 2017/10/17 17-17-37-677
A26: 407-6962157-5158757 | B26: 407-6962157-5158757 | C26: 2024-03-28T06:24:40+00:00 | D26: 2024-03-29T04:23:06+00:00 | E26: Shipped | F26: Amazon | G26: Amazon.fr | J26: Standard | K26: BEPER 50.700 Nettoyeur Vapeur pour Sol, Canapé, Tapis - Nettoyant Vapeur, 135° max, câble de 3 Mètres, 350 ml | L26: 50.700_FBA | M26: B01MTSEGF9 | N26: Shipped | O26: 1 | P26: EUR | Q26: 49.9 | R26: 8.32 | S26: 1.66 | X26: 1.66 | Y26: mennecy | AA26: 91540 | AB26: FR | AC26: Free Shipping 2017/10/17 17-17-37-677
A27: 406-1497766-6778713 | B27: 406-1497766-6778713 | C27: 2024-03-27T22:16:10+00:00 | D27: 2024-03-29T04:18:14+00:00 | E27: Shipped | F27: Amazon | G27: Amazon.fr | J27: Standard | K27: BEPER BT.710Y Crêpière électrique avec poignée, 800 W, plaque en aluminium avec revêtement antiadhésif, rouge | L27: BT.710Y_FBA | M27: B07NQ2VYGD | N27: Shipped | O27: 1 | P27: EUR | Q27: 39.9 | R27: 6.65 | Y27: Nantua | AA27: 1130 | AB27: FR | AC27: Free Shipping 2017/10/17 17-17-37-677
A28: 403-5486831-6296317 | B28: 403-5486831-6296317 | C28: 2024-03-27T22:02:19+00:00 | D28: 2024-03-28T08:30:11+00:00 | E28: Shipped | F28: Amazon | G28: Amazon.fr | J28: Standard | K28: BEPER BT.710Y Crêpière électrique avec poignée, 800 W, plaque en aluminium avec revêtement antiadhésif, rouge | L28: BT.710Y_FBA | M28: B07NQ2VYGD | N28: Shipped | O28: 1 | P28: EUR | Q28: 39.9 | R28: 6.65 | S28: 3.32 | X28: 3.32 | Y28: arcueil | AA28: 94110 | AB28: FR | AC28: Free Shipping 2017/10/17 17-17-37-677
A29: 404-6830767-6475558 | B29: 404-6830767-6475558 | C29: 2024-03-27T18:43:43+00:00 | D29: 2024-03-27T22:17:45+00:00 | E29: Shipped | F29: Amazon | G29: Amazon.fr | J29: Expedited | K29: BEPER BT.710Y Crêpière électrique avec poignée, 800 W, plaque en aluminium avec revêtement antiadhésif, rouge | L29: BT.710Y_FBA | M29: B07NQ2VYGD | N29: Shipped | O29: 1 | P29: EUR | Q29: 39.9 | R29: 6.65 | Y29: MONTFERMEIL | AA29: 93370 | AB29: FR
A30: 406-8224646-9309144 | B30: 406-8224646-9309144 | C30: 2024-03-27T18:16:20+00:00 | D30: 2024-03-28T20:47:28+00:00 | E30: Shipped | F30: Amazon | G30: Amazon.fr | J30: Standard | K30: BEPER BT.710Y Crêpière électrique avec poignée, 800 W, plaque en aluminium avec revêtement antiadhésif, rouge | L30: BT.710Y_FBA | M30: B07NQ2VYGD | N30: Shipped | O30: 1 | P30: EUR | Q30: 39.9 | R30: 6.65 | S30: 1.67 | X30: 1.67 | Y30: Targon | AA30: 33760 | AB30: FR | AC30: Free Shipping 2017/10/17 17-17-37-677
A31: 171-3157907-9078734 | B31: 171-3157907-9078734 | C31: 2024-03-27T17:14:22+00:00 | D31: 2024-03-27T22:17:43+00:00 | E31: Shipped | F31: Amazon | G31: Amazon.fr | J31: Expedited | K31: BEPER BT.710Y Crêpière électrique avec poignée, 800 W, plaque en aluminium avec revêtement antiadhésif, rouge | L31: BT.710Y_FBA | M31: B07NQ2VYGD | N31: Shipped | O31: 1 | P31: EUR | Q31: 40.23 | R31: 6.98 | Y31: SPY | AA31: 5190 | AB31: BE
A32: 407-1996005-2568315 | B32: 407-1996005-2568315 | C32: 2024-03-27T15:07:23+00:00 | D32: 2024-03-28T03:16:00+00:00 | E32: Shipped | F32: Amazon | G32: Amazon.fr | J32: Standard | K32: BEPER BT.710Y Crêpière électrique avec poignée, 800 W, plaque en aluminium avec revêtement antiadhésif, rouge | L32: BT.710Y_FBA | M32: B07NQ2VYGD | N32: Shipped | O32: 1 | P32: EUR | Q32: 39.9 | R32: 6.65 | Y32: Courcelles les gisors | AA32: 60240 | AB32: FR | AC32: Free Shipping 2017/10/17 17-17-37-677
A33: 404-6224560-0753166 | B33: 404-6224560-0753166 | C33: 2024-03-27T12:59:29+00:00 | D33: 2024-03-28T08:31:04+00:00 | E33: Shipped | F33: Amazon | G33: Amazon.fr | J33: Expedited | K33: BEPER BT.710Y Crêpière électrique avec poignée, 800 W, plaque en aluminium avec revêtement antiadhésif, rouge | L33: BT.710Y_FBA | M33: B07NQ2VYGD | N33: Shipped | O33: 1 | P33: EUR | Q33: 39.9 | R33: 6.65 | Y33: Vedene | AA33: 84270 | AB33: FR
A34: 407-9265003-1683523 | B34: 407-9265003-1683523 | C34: 2024-03-27T12:13:01+00:00 | D34: 2024-03-28T12:05:44+00:00 | E34: Shipped | F34: Amazon | G34: Amazon.fr | J34: Expedited | K34: BEPER BT.710Y Crêpière électrique avec poignée, 800 W, plaque en aluminium avec revêtement antiadhésif, rouge | L34: BT.710Y_FBA | M34: B07NQ2VYGD | N34: Shipped | O34: 1 | P34: EUR | Q34: 39.9 | R34: 6.65 | Y34: CORMEILLES EN PARISIS | AA34: 95240 | AB34: FR
A35: 406-1709875-6245107 | B35: 406-1709875-6245107 | C35: 2024-03-26T16:32:50+00:00 | D35: 2024-03-26T23:02:53+00:00 | E35: Shipped | F35: Amazon | G35: Amazon.fr | J35: Standard | K35: BEPER BT.710Y Crêpière électrique avec poignée, 800 W, plaque en aluminium avec revêtement antiadhésif, rouge | L35: BT.710Y_FBA | M35: B07NQ2VYGD | N35: Shipped | O35: 1 | P35: EUR | Q35: 39.9 | R35: 6.65 | Y35: chemellier | AA35: 49320 | AB35: FR | AC35: Free Shipping 2017/10/17 17-17-37-677
A36: 408-3656938-1596349 | B36: 408-3656938-1596349 | C36: 2024-03-26T15:00:02+00:00 | D36: 2024-03-27T12:57:44+00:00 | E36: Shipped | F36: Amazon | G36: Amazon.fr | J36: Standard | K36: BEPER BT.710Y Crêpière électrique avec poignée, 800 W, plaque en aluminium avec revêtement antiadhésif, rouge | L36: BT.710Y_FBA | M36: B07NQ2VYGD | N36: Shipped | O36: 1 | P36: EUR | Q36: 39.9 | R36: 6.65 | S36: 3.32 | X36: 3.32 | Y36: Mandelieu La Napoule | AA36: 6210 | AB36: FR | AC36: Free Shipping 2017/10/17 17-17-37-677
A37: 406-7145952-7366756 | B37: 406-7145952-7366756 | C37: 2024-03-26T09:29:05+00:00 | D37: 2024-03-27T01:32:07+00:00 | E37: Shipped | F37: Amazon | G37: Amazon.fr | J37: Expedited | K37: BEPER BT.710Y Crêpière électrique avec poignée, 800 W, plaque en aluminium avec revêtement antiadhésif, rouge | L37: BT.710Y_FBA | M37: B07NQ2VYGD | N37: Shipped | O37: 1 | P37: EUR | Q37: 39.9 | R37: 6.65 | Y37: LESQUIN | AA37: 59810 | AB37: FR
A38: 403-4175617-0969134 | B38: 403-4175617-0969134 | C38: 2024-03-26T08:09:10+00:00 | D38: 2024-03-26T18:05:25+00:00 | E38: Shipped | F38: Amazon | G38: Amazon.fr | J38: Expedited | K38: BEPER 40.405 Seche Cheveux de Voyage Pliable - Mini Seche Cheveux Silencieux, 2 Températures et 2 Vitesses | L38: 40.405_FBA | M38: B07N4C3H3V | N38: Shipped | O38: 1 | P38: EUR | Q38: 19.9 | R38: 3.32 | Y38: Le Bourget Du Lac | AA38: 73370 | AB38: FR
A39: 406-7370648-0125100 | B39: 406-7370648-0125100 | C39: 2024-03-25T20:48:51+00:00 | D39: 2024-03-26T20:58:16+00:00 | E39: Shipped | F39: Amazon | G39: Amazon.fr | J39: Standard | K39: BEPER BT.602H Gaufrier 700W Cable poignée Thermo-Isolante, Rouge/Blanc | L39: BT.602H_FBA | M39: B076DCKSTJ | N39: Shipped | O39: 1 | P39: EUR | Q39: 35.19 | R39: 6.11 | Y39: Frameries | AA39: 7080 | AB39: BE | AC39: Free Shipping 2017/10/17 17-17-37-677
A40: 406-7370648-0125100 | B40: 406-7370648-0125100 | C40: 2024-03-25T20:48:51+00:00 | D40: 2024-03-26T20:58:16+00:00 | E40: Shipped | F40: Amazon | G40: Amazon.fr | J40: Standard | K40: BEPER BT.710Y Crêpière électrique avec poignée, 800 W, plaque en aluminium avec revêtement antiadhésif, rouge | L40: BT.710Y_FBA | M40: B07NQ2VYGD | N40: Shipped | O40: 1 | P40: EUR | Q40: 40.23 | R40: 6.98 | Y40: Frameries | AA40: 7080 | AB40: BE | AC40: Free Shipping 2017/10/17 17-17-37-677
...

Sheet v_03_23
A1: Codice marketplace | B1: (Tutto) | F1: Codice marketplace | G1: IT
A3: ASIN | B3: Numero del modello | C3: Somma di Unità ordinate | D3: Somma di Ricavi ordini | F3: ASIN | G3: Numero del modello | H3: Somma di Unità ordinate | I3: Somma di Ricavi ordini
A4: B0050IHH4E | B4: 40.979 | C4: 287 | D4: 3732.24 | F4: B0050IHH4E | G4: 40.979 | H4: 294 | I4: 3824.22
A5: B009O92WU4 | B5: 40.999 | C5: 4 | D5: 33.15 | F5: B00CMAD2FG | G5: HK-NV009W | H5: 1 | I5: 20.41
A6: B00C5CCJP0 | B6: 40.993 | C6: 1 | D6: 10.64 | F6: B00EYDRS1I | G6: 90.349 | H6: 48 | I6: 319.65
A7: B00CMAD2FG | B7: HK-NV009W | C7: 2 | D7: 33.58 | F7: B00FAJUDU8 | G7: 40.967N | H7: 74 | I7: 1574.07
A8: B00EYDRS1I | B8: 90.349 | C8: 107 | D8: 604.37 | F8: B00FFBFVG2 | G8: 40.100 | H8: 5 | I8: 42.39
A9: B00FAJUDU8 | B9: 40.967N | C9: 218 | D9: 4814.19 | F9: B00J7MNQFS | G9: 40.994 | H9: 6 | I9: 112.46
A10: B00FFBED98 | B10: 40.11 | C10: 1 | D10: 27.17 | F10: B00L5GPWFG | G10: 40.120 | H10: 4 | I10: 95.58
A11: B00FFBFVG2 | B11: 40.100 | C11: 5 | D11: 42.39 | F11: B00L5H5KUW | G11: 40.121 | H11: -3 | I11: -48.93
A12: B00J7MNQFS | B12: 40.994 | C12: 6 | D12: 112.46 | F12: B00NSNZSLM | G12: 90.602 | H12: 494 | I12: 10082.54
A13: B00L5GPWFG | B13: 40.120 | C13: 4 | D13: 95.58 | F13: B00OKE4RTM | G13: 90.386 | H13: 6 | I13: 294.6
A14: B00L5H5KUW | B14: 40.121 | C14: 58 | D14: 1197.15 | F14: B00OLZPU5K | G14: 40.947 | H14: 1 | I14: 10.57
A15: B00NSNZSLM | B15: 90.602 | C15: 503 | D15: 10307.45 | F15: B00YCPX8R6 | G15: 40.969 | H15: 34 | I15: 192.44
... A213: B091LRR67V | B213: P101FRI050 | C213: 97 | D213: 6336.99 | F213: B0BTHSH5MK | G213: C103ACC001 | H213: 36 | I213: 304.26
A214: B091VSY78C | B214: P303BIP050 | C214: 5 | D214: 81.83 | F214: Totale complessivo | H214: 21937 | I214: 332933.01
A215: B09251R9RJ | B215: P304CAP001 | C215: 11 | D215: 180.66
A216: B0929CVW7Q | B216: P206ZAN110 | C216: 1 | D216: 12.42
A217: B092DN1NCS | B217: P206VEN440 | C217: 3 | D217: 24.75
A218: B092J2RHL8 | B218: P206ZAN200 | C218: 50 | D218: 369.54
A219: B092JNYG6Z | B219: P204CAL201 | C219: 1 | D219: 8.11
A220: B092QXCQ8K | B220: P205DIF001 | C220: 77 | D220: 1157.01
A221: B09495C38F | B221: P204FER002 | C221: 576 | D221: 9142.88
A222: B0953R2W31 | B222: P102ACP001 | C222: 111 | D222: 1351.69
A223: B0957PWXL8 | B223: P102ACP010 | C223: 3 | D223: 74.55
A224: B095PQJGKX | B224: C107UTT002 | C224: 3345 | D224: 27470.2
A225: B095WCSSLC | B225: C301ABE101 | C225: 59 | D225: 411.57
A226: B095X9KDJR | B226: P101BOL100 | C226: 886 | D226: 11893.82
... A288: B0BTHSH5MK | B288: C103ACC001 | C288: 38 | D288: 323.26
A289: Totale complessivo | C289: 41452 | D289: 637551.46

Sheet v_03_24
A1: Codice marketplace | B1: (Tutto) | F1: Codice marketplace | G1: IT
A3: ASIN | B3: Numero del modello | C3: Somma di Unità ordinate | D3: Somma di Ricavi ordini | F3: ASIN | G3: Numero del modello | H3: Somma di Unità ordinate | I3: Somma di Ricavi ordini
A4: B0050IHH4E | B4: 40.979 | C4: 1183 | D4: 16822.21 | F4: B0050IHH4E | G4: 40.979 | H4: 486 | I4: 6983.03
A5: B009O92WU4 | B5: 40.999 | C5: 1 | D5: 5.03 | F5: B00BH202XK | G5: 40.808A | H5: 6 | I5: 83.1
A6: B00BH202XK | B6: 40.808A | C6: 10 | D6: 127.35 | F6: B00EYDRS1I | G6: 90.349 | H6: 36 | I6: 211.74
A7: B00CMAD2FG | B7: HK-NV009W | C7: 1 | D7: 15.18 | F7: B00FFBFVG2 | G7: 40.100 | H7: 0 | I7: 0
A8: B00EYDRS1I | B8: 90.349 | C8: 48 | D8: 271.81 | F8: B00L5GPWFG | G8: 40.120 | H8: 6 | I8: 147.9
A9: B00FFBFVG2 | B9: 40.100 | C9: 0 | D9: 0 | F9: B00L5H5KUW | G9: 40.121 | H9: 275 | I9: 5023.29
A10: B00FMZ2VW8 | B10: HK-HQ601C PINK | C10: 0 | D10: 0 | F10: B00NSNZSLM | G10: 90.602 | H10: 1 | I10: 20.41
A11: B00L5GPWFG | B11: 40.120 | C11: 6 | D11: 147.9 | F11: B00OKE4RTM | G11: 90.386 | H11: 2 | I11: 98.08
A12: B00L5H5KUW | B12: 40.121 | C12: 275 | D12: 5023.29 | F12: B00YH3FRV8 | G12: 40.998 | H12: 1 | I12: 7.43
A13: B00NSNZSLM | B13: 90.602 | C13: 1 | D13: 20.41 | F13: B011LFM60E | G13: 40.948T | H13: 2 | I13: 12.96
A14: B00OKE4RTM | B14: 90.386 | C14: 2 | D14: 98.08 | F14: B011LFVLW8 | G14: 90.620 | H14: 19 | I14: 686.19
A15: B00YH3FRV8 | B15: 40.998 | C15: 1 | D15: 7.43 | F15: B017IUJA50 | G15: 90.920G | H15: 15 | I15: 209.45
... A201: B097785V2V | B201: P202VAL110 | C201: 1 | D201: 5.42 | F201: B0CXJCJF5B | G201: P101PIA003 | H201: 8 | I201: 117.36
A202: B0978ZKW4S | B202: P205DIF100 | C202: 35 | D202: 428.14 | F202: Totale complessivo | H202: 6632 | I202: 104761.64
A203: B097F45J2B | B203: P102FRU500 | C203: 2 | D203: 65.4
A204: B097HRQNRG | B204: P101FRI100 | C204: 5 | D204: 150.29
A205: B097YTGFH7 | B205: P102ROB200 | C205: 22 | D205: 1103.13
A206: B098F33WBD | B206: RCO4091819 | C206: 21 | D206: 2.93
A207: B098QM485T | B207: P101CUD050 | C207: 5 | D207: 208.96
A208: B09968BKDS | B208: P102FRU003 | C208: 243 | D208: 3443.57
A209: B09B15P5H1 | B209: P102FRU200 | C209: 6 | D209: 91.74
A210: B09B2NT2SV | B210: P102FRU150 | C210: 9 | D210: 194.04
A211: B09B47S644 | B211: P101CUD501 | C211: 79 | D211: 2302.19
A212: B09BBFTDLJ | B212: P101TOS501 | C212: 1 | D212: 61.57
A213: B09BD8BG34 | B213: P301PIS001 | C213: 188 | D213: 2349.32
A214: B09BG1GGSM | B214: P204FER003 | C214: 0 | D214: 0
... A284: B0CXJCJF5B | B284: P101PIA003 | C284: 13 | D284: 191.49
A285: (vuoto) | B285: (vuoto)
A286: Totale complessivo | C286: 13774 | D286: 219396.13

Sheet s_03_24
E1: sales-channel | F1: Amazon.it
A2: sales-channel | B2: (Tutto) | J2: (Tutto)
E3: Etichette di riga | F3: Somma di quantity | G3: Somma di item-price
A4: asin | B4: sku | C4: Somma di quantity | D4: Somma di item-price | E4: B00FAJUDU8 | F4: 72 | G4: 2152.8 | J4: sku | K4: Somma di quantity | L4: Somma di item-price
A5: B00FAJUDU8 | B5: 40.967N | C5: 3 | D5: 89.7 | E5: B00NSNZSLM | F5: 49 | G5: 1612.1
B6: 40.967N_FBA | C6: 86 | D6: 2741.4 | E6: B017IUJA50 | F6: 137 | G6: 2722.71 | J6: 40.967N_FBA | K6: 86 | L6: 2741.4
A7: B00NSNZSLM | B7: BT.603Y | C7: 2 | D7: 65.8 | E7: B01CNX6Z78 | F7: 3 | G7: 104.7
B8: BT.603Y_FBA | C8: 47 | D8: 1546.3 | E8: B01CNX704K | F8: 1 | G8: 46.9 | J8: BT.603Y_FBA | K8: 47 | L8: 1546.3
A9: B017IUJA50 | B9: 90.920G | C9: 14 | D9: 278.6 | E9: B01I497WWM | F9: 531 | G9: 10557.34
B10: 90.920G_FBA | C10: 123 | D10: 2444.11 | E10: B01KMJ9OXW | F10: 139 | G10: 4844.53 | J10: 90.920G_FBA | K10: 123 | L10: 2444.11
A11: B01CNX6Z78 | B11: 90820 | C11: 3 | D11: 104.7 | E11: B01MTSEGF9 | F11: 19 | G11: 853.1
A12: B01CNX704K | B12: 90825 | C12: 1 | D12: 46.9 | E12: B06Y17FS6D | F12: 1 | G12: 39.9
A13: B01I497WWM | B13: 90.920R | C13: 2 | D13: 39.8 | E13: B06Y195DJN | F13: 16 | G13: 798.4
B14: 90.920R_FBA | C14: 526 | D14: 10463.81 | E14: B06Y1997YH | F14: 2 | G14: 159.8 | J14: 90.920R_FBA | K14: 526 | L14: 10463.81
B15: amzn.gr.90.920R-a2o_Ri7zcG6-mSjMeKSVj-LN | C15: 3 | D15: 53.73 | E15: B0757TJRR9 | F15: 497 | G15: 16362.46
A16: B01KMJ9OXW | B16: 90.590Y | C16: 2 | D16: 69.8 | E16: B076D74TC7 | F16: 6 | G16: 232.2
B17: 90.590Y_FBA | C17: 164 | D17: 5897.23 | E17: B076DCKSTJ | F17: 106 | G17: 2713.4 | J17: 90.590Y_FBA | K17: 164 | L17: 5897.23
A18: B01MTSEGF9 | B18: 50.700_FBA | C18: 31 | D18: 1442.9 | E18: B076Q7BR6F | F18: 22 | G18: 1040.8 | J18: 50.700_FBA | K18: 31 | L18: 1442.9
A19: B06Y17FS6D | B19: 90550 | C19: 1 | D19: 39.9 | E19: B07BB2DQ4V | F19: 1 | G19: 39.9
A20: B06Y195DJN | B20: 90882 | C20: 2 | D20: 99.8 | E20: B07BHCZR84 | F20: 1 | G20: 19.9
B21: 90.882_FBA | C21: 16 | D21: 818.4 | E21: B07HM7P6MP | F21: 2 | G21: 59.8 | J21: 90.882_FBA | K21: 16 | L21: 818.4
A22: B06Y1997YH | B22: 90883 | C22: 2 | D22: 159.8 | E22: B07N4C3H3V | F22: 244 | G22: 3635.6
A23: B0757TJRR9 | B23: 40500 | C23: 64 | D23: 2132.57 | E23: B07NQ2VYGD | F23: 499 | G23: 14519.28
B24: 40.500_FBA | C24: 446 | D24: 14829.54 | E24: B07NQC6S9V | F24: 12 | G24: 506.7 | J24: 40.500_FBA | K24: 446 | L24: 14829.54
B25: amzn.gr.40.500-78_VnB2lvTKD2lNtmILtG6-VG | C25: 1 | D25: 28.95 | E25: B07P7GGGQM | F25: 16 | G25: 958.4
A26: B076D74TC7 | B26: BT.700Y_FBA | C26: 6 | D26: 232.2 | E26: B07TQVD94L | F26: 16 | G26: 602.4 | J26: BT.700Y_FBA | K26: 6 | L26: 232.2
A27: B076DCKSTJ | B27: BT.602H | C27: 9 | D27: 242.1 | E27: B07V131F5W | F27: 167 | G27: 4754.3
B28: BT.602H_FBA | C28: 98 | D28: 2506.49 | E28: B07W7S9KYM | F28: 1 | G28: 59.9 | J28: BT.602H_FBA | K28: 98 | L28: 2506.49
A29: B076Q7BR6F | B29: BC.041N | C29: 3 | D29: 149.7 | E29: B07YBN2FS3 | F29: 24 | G29: 1908.01
B30: BC.041N_FBA | C30: 20 | D30: 946 | E30: B07ZJQTGG8 | F30: 155 | G30: 2309.5 | J30: BC.041N_FBA | K30: 20 | L30: 946
A31: B07BB2DQ4V | B31: BT.150Y_FBA | C31: 1 | D31: 39.9 | E31: B0823CVGHX | F31: 60 | G31: 4194 | J31: BT.150Y_FBA | K31: 1 | L31: 39.9
A32: B07BHCZR84 | B32: BA.200Y | C32: 1 | D32: 19.9 | E32: B08485QRVZ | F32: 70 | G32: 2082.22
A33: B07HM7P6MP | B33: RI.080 | C33: 2 | D33: 59.8 | E33: B085R2GCKX | F33: 4 | G33: 91.6
A34: B07N4C3H3V | B34: 40.405_FBA | C34: 253 | D34: 3814.7 | E34: B08FDYW72J | F34: 2 | G34: 69.8 | J34: 40.405_FBA | K34: 253 | L34: 3814.7
A35: B07NQ2VYGD | B35: amzn.gr.BT.710Y_FBA-210-4xyKJjiMm2Til-AC | C35: 1 | D35: 27.93 | E35: B08GS7XW73 | F35: 27 | G35: 556.35 | J35: amzn.gr.BT.710Y_FBA-210-4xyKJjiMm2Til-AC | K35: 1 | L35: 27.93
B36: amzn.gr.BT.710Y-4MyGoFppOTLJERCkjI-cP-LN | C36: 1 | D36: 22.41 | E36: B08GY7286R | F36: 9 | G36: 197.1
B37: amzn.gr.BT.710Y-m_rMJX0XWOKRxfp7Jvoem-VG | C37: 1 | D37: 26.31 | E37: B08JM7SZ36 | F37: 86 | G37: 3431.4
B38: BT.710Y | C38: 71 | D38: 2147.41 | E38: B08JYDDFZ2 | F38: 158 | G38: 2588.2
B39: BT.710Y_FBA | C39: 487 | D39: 14757.71 | E39: B08KSBDTQD | F39: 15 | G39: 598.5 | J39: BT.710Y_FBA | K39: 487 | L39: 14757.71
A40: B07NQC6S9V | B40: BT.651Y_FBA | C40: 12 | D40: 506.7 | E40: B08LZN1PWY | F40: 19 | G40: 1430.1 | J40: BT.651Y_FBA | K40: 12 | L40: 506.7
...

Sheet pivot
A3: ASIN | B3: SKU | C3: Somma di Ordini Vendor 24 | D3: Somma di Valori ordini Vendor 24 | E3: Somma di Ordini Seller | F3: Somma di Valori ordini Seller | G3: Somma di Ordini Complessivi | H3: Somma di Valori ordini Complessivi | I3: Somma di Ordini Vendor 23 | J3: Somma di Valori ordini Vendor 23
A4: B0050IHH4E | B4: 40.979 | C4: 1183 | D4: 16822.21 | E4: 0 | F4: 0 | G4: 1183 | H4: 16822.21 | I4: 287 | J4: 3732.24
A5: B009O92WU4 | B5: 40.999 | C5: 1 | D5: 5.03 | E5: 0 | F5: 0 | G5: 1 | H5: 5.03 | I5: 4 | J5: 33.15
A6: B00BH202XK | B6: 40.808A | C6: 10 | D6: 127.35 | E6: 0 | F6: 0 | G6: 10 | H6: 127.35 | I6: 0 | J6: 0
A7: B00CMAD2FG | B7: HK-NV009W | C7: 1 | D7: 15.18 | E7: 0 | F7: 0 | G7: 1 | H7: 15.18 | I7: 2 | J7: 33.58
A8: B00FFBFVG2 | B8: 40.100 | C8: 0 | D8: 0 | E8: 0 | F8: 0 | G8: 0 | H8: 0 | I8: 5 | J8: 42.39
A9: B00L5GPWFG | B9: 40.120 | C9: 6 | D9: 147.9 | E9: 0 | F9: 0 | G9: 6 | H9: 147.9 | I9: 4 | J9: 95.58
A10: B00L5H5KUW | B10: 40.121 | C10: 275 | D10: 5023.29 | E10: 0 | F10: 0 | G10: 275 | H10: 5023.29 | I10: 58 | J10: 1197.15
A11: B00NSNZSLM | B11: 90.602 | C11: 1 | D11: 20.41 | E11: 49 | F11: 1612.1 | G11: 50 | H11: 1632.51 | I11: 503 | J11: 10307.45
A12: B00YH3FRV8 | B12: 40.998 | C12: 1 | D12: 7.43 | E12: 0 | F12: 0 | G12: 1 | H12: 7.43 | I12: 0 | J12: 0
A13: B011LFM60E | B13: 40.948T | C13: 2 | D13: 12.96 | E13: 0 | F13: 0 | G13: 2 | H13: 12.96 | I13: 2 | J13: 7.53
A14: B011LFVLW8 | B14: 90.620 | C14: 19 | D14: 686.19 | E14: 0 | F14: 0 | G14: 19 | H14: 686.19 | I14: 16 | J14: 590.39
A15: B017IUJA50 | B15: 90.920G | C15: 15 | D15: 209.45 | E15: 137 | F15: 2722.71 | G15: 152 | H15: 2932.16 | I15: 448 | J15: 6892.94
... A284: B076DD35DZ | B284: BC.002 | C284: 3 | D284: 130.44 | E284: 0 | F284: 0 | G284: 3 | H284: 130.44 | I284: 3 | J284: 130.54
A285: Totale complessivo | C285: 13773 | D285: 219317.97 | E285: 3399 | F285: 94996.87 | G285: 17172 | H285: 314314.84 | I285: 40784 | J285: 625743.48

Sheet IT
A1: ASIN | B1: SKU | C1: Ordini Vendor 24 | D1: Valori ordini Vendor 24 | E1: Ordini Seller | F1: Valori ordini Seller | G1: % seller / totale | H1: Ordini Complessivi | I1: Valori ordini Complessivi | J1: Ordini Vendor 23 | K1: Valori ordini Vendor 23 | L1: Differenza Ordini | M1: Differenza Valore | N1: Differenza Valore %
A2: B0050IHH4E | B2: 40.979 | C2: =VLOOKUP(A2,v_03_24!F:I,3,FALSE) -> 486 | D2: =VLOOKUP(A2,v_03_24!F:I,4,FALSE) -> 6983.03 | E2: 0 | F2: 0 | G2: =F2/I2 -> 0 | H2: =C2+E2 -> 486 | I2: =D2+F2 -> 6983.03 | J2: =VLOOKUP(A2,v_03_23!F:I,3,FALSE) -> 294 | K2: =VLOOKUP(A2,v_03_23!F:I,4,FALSE) -> 3824.22 | L2: =H2-J2 -> 192 | M2: =I2-K2 -> 3158.81 | N2: =M2/K2 -> 0.82600112
A3: B009O92WU4 | B3: 40.999 | C3: 0 | D3: 0 | E3: 0 | F3: 0 | H3: =C3+E3 -> 0 | I3: =D3+F3 -> 0 | J3: 0 | K3: 0 | L3: =H3-J3 -> 0 | M3: =I3-K3 -> 0
A4: B00BH202XK | B4: 40.808A | C4: =VLOOKUP(A4,v_03_24!F:I,3,FALSE) -> 6 | D4: =VLOOKUP(A4,v_03_24!F:I,4,FALSE) -> 83.1 | E4: 0 | F4: 0 | G4: =F4/I4 -> 0 | H4: =C4+E4 -> 6 | I4: =D4+F4 -> 83.1 | J4: 0 | K4: 0 | L4: =H4-J4 -> 6 | M4: =I4-K4 -> 83.1
A5: B00CMAD2FG | B5: HK-NV009W | C5: 0 | D5: 0 | E5: 0 | F5: 0 | H5: =C5+E5 -> 0 | I5: =D5+F5 -> 0 | J5: =VLOOKUP(A5,v_03_23!F:I,3,FALSE) -> 1 | K5: =VLOOKUP(A5,v_03_23!F:I,4,FALSE) -> 20.41 | L5: =H5-J5 -> -1 | M5: =I5-K5 -> -20.41 | N5: =M5/K5 -> -1
A6: B00FFBFVG2 | B6: 40.100 | C6: =VLOOKUP(A6,v_03_24!F:I,3,FALSE) -> 0 | D6: =VLOOKUP(A6,v_03_24!F:I,4,FALSE) -> 0 | E6: 0 | F6: 0 | H6: =C6+E6 -> 0 | I6: =D6+F6 -> 0 | J6: =VLOOKUP(A6,v_03_23!F:I,3,FALSE) -> 5 | K6: =VLOOKUP(A6,v_03_23!F:I,4,FALSE) -> 42.39 | L6: =H6-J6 -> -5 | M6: =I6-K6 -> -42.39 | N6: =M6/K6 -> -1
A7: B00L5GPWFG | B7: 40.120 | C7: =VLOOKUP(A7,v_03_24!F:I,3,FALSE) -> 6 | D7: =VLOOKUP(A7,v_03_24!F:I,4,FALSE) -> 147.9 | E7: 0 | F7: 0 | G7: =F7/I7 -> 0 | H7: =C7+E7 -> 6 | I7: =D7+F7 -> 147.9 | J7: =VLOOKUP(A7,v_03_23!F:I,3,FALSE) -> 4 | K7: =VLOOKUP(A7,v_03_23!F:I,4,FALSE) -> 95.58 | L7: =H7-J7 -> 2 | M7: =I7-K7 -> 52.32 | N7: =M7/K7 -> 0.54739485
A8: B00L5H5KUW | B8: 40.121 | C8: =VLOOKUP(A8,v_03_24!F:I,3,FALSE) -> 275 | D8: =VLOOKUP(A8,v_03_24!F:I,4,FALSE) -> 5023.29 | E8: 0 | F8: 0 | G8: =F8/I8 -> 0 | H8: =C8+E8 -> 275 | I8: =D8+F8 -> 5023.29 | J8: =VLOOKUP(A8,v_03_23!F:I,3,FALSE) -> -3 | K8: =VLOOKUP(A8,v_03_23!F:I,4,FALSE) -> -48.93 | L8: =H8-J8 -> 278 | M8: =I8-K8 -> 5072.22 | N8: =M8/K8 -> -103.66278
A9: B00NSNZSLM | B9: 90.602 | C9: =VLOOKUP(A9,v_03_24!F:I,3,FALSE) -> 1 | D9: =VLOOKUP(A9,v_03_24!F:I,4,FALSE) -> 20.41 | E9: =VLOOKUP(A9,s_03_24!E:G,2,FALSE) -> 49 | F9: =VLOOKUP(A9,s_03_24!E:G,3,FALSE) -> 1612.1 | G9: =F9/I9 -> 0.98749778 | H9: =C9+E9 -> 50 | I9: =D9+F9 -> 1632.51 | J9: =VLOOKUP(A9,v_03_23!F:I,3,FALSE) -> 494 | K9: =VLOOKUP(A9,v_03_23!F:I,4,FALSE) -> 10082.54 | L9: =H9-J9 -> -444 | M9: =I9-K9 -> -8450.03 | N9: =M9/K9 -> -0.83808544
A10: B00YH3FRV8 | B10: 40.998 | C10: =VLOOKUP(A10,v_03_24!F:I,3,FALSE) -> 1 | D10: =VLOOKUP(A10,v_03_24!F:I,4,FALSE) -> 7.43 | E10: 0 | F10: 0 | G10: =F10/I10 -> 0 | H10: =C10+E10 -> 1 | I10: =D10+F10 -> 7.43 | J10: 0 | K10: 0 | L10: =H10-J10 -> 1 | M10: =I10-K10 -> 7.43
A11: B011LFM60E | B11: 40.948T | C11: =VLOOKUP(A11,v_03_24!F:I,3,FALSE) -> 2 | D11: =VLOOKUP(A11,v_03_24!F:I,4,FALSE) -> 12.96 | E11: 0 | F11: 0 | G11: =F11/I11 -> 0 | H11: =C11+E11 -> 2 | I11: =D11+F11 -> 12.96 | J11: =VLOOKUP(A11,v_03_23!F:I,3,FALSE) -> 1 | K11: =VLOOKUP(A11,v_03_23!F:I,4,FALSE) -> 3.9 | L11: =H11-J11 -> 1 | M11: =I11-K11 -> 9.06 | N11: =M11/K11 -> 2.3230769
A12: B011LFVLW8 | B12: 90.620 | C12: =VLOOKUP(A12,v_03_24!F:I,3,FALSE) -> 19 | D12: =VLOOKUP(A12,v_03_24!F:I,4,FALSE) -> 686.19 | E12: 0 | F12: 0 | G12: =F12/I12 -> 0 | H12: =C12+E12 -> 19 | I12: =D12+F12 -> 686.19 | J12: =VLOOKUP(A12,v_03_23!F:I,3,FALSE) -> 16 | K12: =VLOOKUP(A12,v_03_23!F:I,4,FALSE) -> 590.39 | L12: =H12-J12 -> 3 | M12: =I12-K12 -> 95.8 | N12: =M12/K12 -> 0.16226562
A13: B017IUJA50 | B13: 90.920G | C13: =VLOOKUP(A13,v_03_24!F:I,3,FALSE) -> 15 | D13: =VLOOKUP(A13,v_03_24!F:I,4,FALSE) -> 209.45 | E13: =VLOOKUP(A13,s_03_24!E:G,2,FALSE) -> 137 | F13: =VLOOKUP(A13,s_03_24!E:G,3,FALSE) -> 2722.71 | G13: =F13/I13 -> 0.92856802 | H13: =C13+E13 -> 152 | I13: =D13+F13 -> 2932.16 | J13: =VLOOKUP(A13,v_03_23!F:I,3,FALSE) -> 329 | K13: =VLOOKUP(A13,v_03_23!F:I,4,FALSE) -> 5312.75 | L13: =H13-J13 -> -177 | M13: =I13-K13 -> -2380.59 | N13: =M13/K13 -> -0.44808997
A14: B01CHW1L88 | B14: PE.001 | C14: =VLOOKUP(A14,v_03_24!F:I,3,FALSE) -> 1 | D14: =VLOOKUP(A14,v_03_24!F:I,4,FALSE) -> 15.05 | E14: 0 | F14: 0 | G14: =F14/I14 -> 0 | H14: =C14+E14 -> 1 | I14: =D14+F14 -> 15.05 | J14: 0 | K14: 0 | L14: =H14-J14 -> 1 | M14: =I14-K14 -> 15.05
A15: B01CNX6UIM | B15: PE.300 | C15: =VLOOKUP(A15,v_03_24!F:I,3,FALSE) -> 0 | D15: =VLOOKUP(A15,v_03_24!F:I,4,FALSE) -> 0 | E15: 0 | F15: 0 | H15: =C15+E15 -> 0 | I15: =D15+F15 -> 0 | J15: 0 | K15: 0 | L15: =H15-J15 -> 0 | M15: =I15-K15 -> 0
A16: B01CNX704K | B16: 90.825 | C16: 0 | D16: 0 | E16: =VLOOKUP(A16,s_03_24!E:G,2,FALSE) -> 1 | F16: =VLOOKUP(A16,s_03_24!E:G,3,FALSE) -> 46.9 | G16: =F16/I16 -> 1 | H16: =C16+E16 -> 1 | I16: =D16+F16 -> 46.9 | J16: 0 | K16: 0 | L16: =H16-J16 -> 1 | M16: =I16-K16 -> 46.9
A17: B01CNX71NA | B17: 90.871 | C17: =VLOOKUP(A17,v_03_24!F:I,3,FALSE) -> 1 | D17: =VLOOKUP(A17,v_03_24!F:I,4,FALSE) -> 86.86 | E17: 0 | F17: 0 | G17: =F17/I17 -> 0 | H17: =C17+E17 -> 1 | I17: =D17+F17 -> 86.86 | J17: =VLOOKUP(A17,v_03_23!F:I,3,FALSE) -> 11 | K17: =VLOOKUP(A17,v_03_23!F:I,4,FALSE) -> 903.8 | L17: =H17-J17 -> -10 | M17: =I17-K17 -> -816.94 | N17: =M17/K17 -> -0.90389467
A18: B01I497WWM | B18: 90.920R | C18: =VLOOKUP(A18,v_03_24!F:I,3,FALSE) -> 14 | D18: =VLOOKUP(A18,v_03_24!F:I,4,FALSE) -> 260.2 | E18: =VLOOKUP(A18,s_03_24!E:G,2,FALSE) -> 531 | F18: =VLOOKUP(A18,s_03_24!E:G,3,FALSE) -> 10557.34 | G18: =F18/I18 -> 0.97594647 | H18: =C18+E18 -> 545 | I18: =D18+F18 -> 10817.54 | J18: =VLOOKUP(A18,v_03_23!F:I,3,FALSE) -> 1296 | K18: =VLOOKUP(A18,v_03_23!F:I,4,FALSE) -> 18280.61 | L18: =H18-J18 -> -751 | M18: =I18-K18 -> -7463.07 | N18: =M18/K18 -> -0.4082506
A19: B01II7S968 | B19: MD.217 | C19: 0 | D19: 0 | E19: 0 | F19: 0 | H19: =C19+E19 -> 0 | I19: =D19+F19 -> 0 | J19: 0 | K19: 0 | L19: =H19-J19 -> 0 | M19: =I19-K19 -> 0
A20: B01KMJ9OXW | B20: 90.590Y | C20: =VLOOKUP(A20,v_03_24!F:I,3,FALSE) -> 1 | D20: =VLOOKUP(A20,v_03_24!F:I,4,FALSE) -> 35.32 | E20: =VLOOKUP(A20,s_03_24!E:G,2,FALSE) -> 139 | F20: =VLOOKUP(A20,s_03_24!E:G,3,FALSE) -> 4844.53 | G20: =F20/I20 -> 0.99276207 | H20: =C20+E20 -> 140 | I20: =D20+F20 -> 4879.85 | J20: =VLOOKUP(A20,v_03_23!F:I,3,FALSE) -> 244 | K20: =VLOOKUP(A20,v_03_23!F:I,4,FALSE) -> 7663.28 | L20: =H20-J20 -> -104 | M20: =I20-K20 -> -2783.43 | N20: =M20/K20 -> -0.36321653
A21: B06WGS8ZVG | B21: 90.131 | C21: =VLOOKUP(A21,v_03_24!F:I,3,FALSE) -> 2 | D21: =VLOOKUP(A21,v_03_24!F:I,4,FALSE) -> 27.28 | E21: 0 | F21: 0 | G21: =F21/I21 -> 0 | H21: =C21+E21 -> 2 | I21: =D21+F21 -> 27.28 | J21: =VLOOKUP(A21,v_03_23!F:I,3,FALSE) -> 9 | K21: =VLOOKUP(A21,v_03_23!F:I,4,FALSE) -> 105.59 | L21: =H21-J21 -> -7 | M21: =I21-K21 -> -78.31 | N21: =M21/K21 -> -0.7416422
A22: B06XPK3BTC | B22: 40.450GO | C22: =VLOOKUP(A22,v_03_24!F:I,3,FALSE) -> 2 | D22: =VLOOKUP(A22,v_03_24!F:I,4,FALSE) -> 31.65 | E22: 0 | F22: 0 | G22: =F22/I22 -> 0 | H22: =C22+E22 -> 2 | I22: =D22+F22 -> 31.65 | J22: =VLOOKUP(A22,v_03_23!F:I,3,FALSE) -> 6 | K22: =VLOOKUP(A22,v_03_23!F:I,4,FALSE) -> 90.34 | L22: =H22-J22 -> -4 | M22: =I22-K22 -> -58.69 | N22: =M22/K22 -> -0.64965685
A23: B06XYMCV3W | B23: 90.485H | C23: =VLOOKUP(A23,v_03_24!F:I,3,FALSE) -> 0 | D23: =VLOOKUP(A23,v_03_24!F:I,4,FALSE) -> 0 | E23: 0 | F23: 0 | H23: =C23+E23 -> 0 | I23: =D23+F23 -> 0 | J23: 0 | K23: 0 | L23: =H23-J23 -> 0 | M23: =I23-K23 -> 0
A24: B06Y17FS6D | B24: 90.550 | C24: =VLOOKUP(A24,v_03_24!F:I,3,FALSE) -> 49 | D24: =VLOOKUP(A24,v_03_24!F:I,4,FALSE) -> 1395.95 | E24: =VLOOKUP(A24,s_03_24!E:G,2,FALSE) -> 1 | F24: =VLOOKUP(A24,s_03_24!E:G,3,FALSE) -> 39.9 | G24: =F24/I24 -> 0.027788418 | H24: =C24+E24 -> 50 | I24: =D24+F24 -> 1435.85 | J24: =VLOOKUP(A24,v_03_23!F:I,3,FALSE) -> 29 | K24: =VLOOKUP(A24,v_03_23!F:I,4,FALSE) -> 710.79 | L24: =H24-J24 -> 21 | M24: =I24-K24 -> 725.06 | N24: =M24/K24 -> 1.0200763
A25: B06Y195DJN | B25: 90.882 | C25: 0 | D25: 0 | E25: =VLOOKUP(A25,s_03_24!E:G,2,FALSE) -> 16 | F25: =VLOOKUP(A25,s_03_24!E:G,3,FALSE) -> 798.4 | G25: =F25/I25 -> 1 | H25: =C25+E25 -> 16 | I25: =D25+F25 -> 798.4 | J25: 0 | K25: 0 | L25: =H25-J25 -> 16 | M25: =I25-K25 -> 798.4
A26: B073B67PLQ | B26: 90.884 | C26: =VLOOKUP(A26,v_03_24!F:I,3,FALSE) -> 14 | D26: =VLOOKUP(A26,v_03_24!F:I,4,FALSE) -> 1136.27 | E26: 0 | F26: 0 | G26: =F26/I26 -> 0 | H26: =C26+E26 -> 14 | I26: =D26+F26 -> 1136.27 | J26: =VLOOKUP(A26,v_03_23!F:I,3,FALSE) -> 68 | K26: =VLOOKUP(A26,v_03_23!F:I,4,FALSE) -> 5010.92 | L26: =H26-J26 -> -54 | M26: =I26-K26 -> -3874.65 | N26: =M26/K26 -> -0.77324124
A27: B075K5C2QG | B27: RI.201 | C27: =VLOOKUP(A27,v_03_24!F:I,3,FALSE) -> 2 | D27: =VLOOKUP(A27,v_03_24!F:I,4,FALSE) -> 40.82 | E27: 0 | F27: 0 | G27: =F27/I27 -> 0 | H27: =C27+E27 -> 2 | I27: =D27+F27 -> 40.82 | J27: =VLOOKUP(A27,v_03_23!F:I,3,FALSE) -> -2 | K27: =VLOOKUP(A27,v_03_23!F:I,4,FALSE) -> -33.5 | L27: =H27-J27 -> 4 | M27: =I27-K27 -> 74.32 | N27: =M27/K27 -> -2.2185075
A28: B075RF5S3N | B28: BC.160A | C28: =VLOOKUP(A28,v_03_24!F:I,3,FALSE) -> 5 | D28: =VLOOKUP(A28,v_03_24!F:I,4,FALSE) -> 129.21 | E28: 0 | F28: 0 | G28: =F28/I28 -> 0 | H28: =C28+E28 -> 5 | I28: =D28+F28 -> 129.21 | J28: =VLOOKUP(A28,v_03_23!F:I,3,FALSE) -> 17 | K28: =VLOOKUP(A28,v_03_23!F:I,4,FALSE) -> 351.12 | L28: =H28-J28 -> -12 | M28: =I28-K28 -> -221.91 | N28: =M28/K28 -> -0.63200615
A29: B075RF8FM9 | B29: BC.160G | C29: =VLOOKUP(A29,v_03_24!F:I,3,FALSE) -> 0 | D29: =VLOOKUP(A29,v_03_24!F:I,4,FALSE) -> 0 | E29: 0 | F29: 0 | H29: =C29+E29 -> 0 | I29: =D29+F29 -> 0 | J29: =VLOOKUP(A29,v_03_23!F:I,3,FALSE) -> 0 | K29: =VLOOKUP(A29,v_03_23!F:I,4,FALSE) -> 0 | L29: =H29-J29 -> 0 | M29: =I29-K29 -> 0
A30: B075XR3T8V | B30: BT.600Y | C30: 0 | D30: 0 | E30: 0 | F30: 0 | H30: =C30+E30 -> 0 | I30: =D30+F30 -> 0 | J30: 0 | K30: 0 | L30: =H30-J30 -> 0 | M30: =I30-K30 -> 0
A31: B076D74TC7 | B31: BT.700Y | C31: 0 | D31: 0 | E31: =VLOOKUP(A31,s_03_24!E:G,2,FALSE) -> 6 | F31: =VLOOKUP(A31,s_03_24!E:G,3,FALSE) -> 232.2 | G31: =F31/I31 -> 1 | H31: =C31+E31 -> 6 | I31: =D31+F31 -> 232.2 | J31: 0 | K31: 0 | L31: =H31-J31 -> 6 | M31: =I31-K31 -> 232.2
A32: B076DC4VWG | B32: 40.501 | C32: =VLOOKUP(A32,v_03_24!F:I,3,FALSE) -> 0 | D32: =VLOOKUP(A32,v_03_24!F:I,4,FALSE) -> 0 | E32: 0 | F32: 0 | H32: =C32+E32 -> 0 | I32: =D32+F32 -> 0 | J32: =VLOOKUP(A32,v_03_23!F:I,3,FALSE) -> 3 | K32: =VLOOKUP(A32,v_03_23!F:I,4,FALSE) -> 62.68 | L32: =H32-J32 -> -3 | M32: =I32-K32 -> -62.68 | N32: =M32/K32 -> -1
A33: B076DCL19C | B33: BP.720 | C33: =VLOOKUP(A33,v_03_24!F:I,3,FALSE) -> 17 | D33: =VLOOKUP(A33,v_03_24!F:I,4,FALSE) -> 814.3 | E33: 0 | F33: 0 | G33: =F33/I33 -> 0 | H33: =C33+E33 -> 17 | I33: =D33+F33 -> 814.3 | J33: =VLOOKUP(A33,v_03_23!F:I,3,FALSE) -> 24 | K33: =VLOOKUP(A33,v_03_23!F:I,4,FALSE) -> 1436.05 | L33: =H33-J33 -> -7 | M33: =I33-K33 -> -621.75 | N33: =M33/K33 -> -0.43295846
A34: B076DCX3JH | B34: BB.103 | C34: 0 | D34: 0 | E34: 0 | F34: 0 | H34: =C34+E34 -> 0 | I34: =D34+F34 -> 0 | J34: 0 | K34: 0 | L34: =H34-J34 -> 0 | M34: =I34-K34 -> 0
A35: B076QCMZX1 | B35: 40.821 | C35: =VLOOKUP(A35,v_03_24!F:I,3,FALSE) -> 162 | D35: =VLOOKUP(A35,v_03_24!F:I,4,FALSE) -> 1977.32 | E35: 0 | F35: 0 | G35: =F35/I35 -> 0 | H35: =C35+E35 -> 162 | I35: =D35+F35 -> 1977.32 | J35: =VLOOKUP(A35,v_03_23!F:I,3,FALSE) -> 97 | K35: =VLOOKUP(A35,v_03_23!F:I,4,FALSE) -> 866.21 | L35: =H35-J35 -> 65 | M35: =I35-K35 -> 1111.11 | N35: =M35/K35 -> 1.2827259
A36: B076QFRRZ5 | B36: 40.931 | C36: =VLOOKUP(A36,v_03_24!F:I,3,FALSE) -> 40 | D36: =VLOOKUP(A36,v_03_24!F:I,4,FALSE) -> 573.31 | E36: 0 | F36: 0 | G36: =F36/I36 -> 0 | H36: =C36+E36 -> 40 | I36: =D36+F36 -> 573.31 | J36: =VLOOKUP(A36,v_03_23!F:I,3,FALSE) -> 178 | K36: =VLOOKUP(A36,v_03_23!F:I,4,FALSE) -> 2411.94 | L36: =H36-J36 -> -138 | M36: =I36-K36 -> -1838.63 | N36: =M36/K36 -> -0.76230337
A37: B079SB5VJZ | B37: 50451 | C37: =VLOOKUP(A37,v_03_24!F:I,3,FALSE) -> 2 | D37: =VLOOKUP(A37,v_03_24!F:I,4,FALSE) -> 91.63 | E37: 0 | F37: 0 | G37: =F37/I37 -> 0 | H37: =C37+E37 -> 2 | I37: =D37+F37 -> 91.63 | J37: =VLOOKUP(A37,v_03_23!F:I,3,FALSE) -> 265 | K37: =VLOOKUP(A37,v_03_23!F:I,4,FALSE) -> 8761.44 | L37: =H37-J37 -> -263 | M37: =I37-K37 -> -8669.81 | N37: =M37/K37 -> -0.98954167
A38: B07B9CBD91 | B38: VE.550 | C38: 0 | D38: 0 | E38: 0 | F38: 0 | H38: =C38+E38 -> 0 | I38: =D38+F38 -> 0 | J38: 0 | K38: 0 | L38: =H38-J38 -> 0 | M38: =I38-K38 -> 0
A39: B07B9CPH62 | B39: BG.200Y | C39: =VLOOKUP(A39,v_03_24!F:I,3,FALSE) -> 6 | D39: =VLOOKUP(A39,v_03_24!F:I,4,FALSE) -> 294.6 | E39: 0 | F39: 0 | G39: =F39/I39 -> 0 | H39: =C39+E39 -> 6 | I39: =D39+F39 -> 294.6 | J39: =VLOOKUP(A39,v_03_23!F:I,3,FALSE) -> 32 | K39: =VLOOKUP(A39,v_03_23!F:I,4,FALSE) -> 1571.2 | L39: =H39-J39 -> -26 | M39: =I39-K39 -> -1276.6 | N39: =M39/K39 -> -0.8125
A40: B07BHCZR84 | B40: BA.200Y | C40: =VLOOKUP(A40,v_03_24!F:I,3,FALSE) -> 22 | D40: =VLOOKUP(A40,v_03_24!F:I,4,FALSE) -> 266.22 | E40: =VLOOKUP(A40,s_03_24!E:G,2,FALSE) -> 1 | F40: =VLOOKUP(A40,s_03_24!E:G,3,FALSE) -> 19.9 | G40: =F40/I40 -> 0.069551237 | H40: =C40+E40 -> 23 | I40: =D40+F40 -> 286.12 | J40: =VLOOKUP(A40,v_03_23!F:I,3,FALSE) -> 36 | K40: =VLOOKUP(A40,v_03_23!F:I,4,FALSE) -> 385.44 | L40: =H40-J40 -> -13 | M40: =I40-K40 -> -99.32 | N40: =M40/K40 -> -0.25767954
...

Sheet Complessivo
A1: ASIN | B1: SKU | C1: Ordini Vendor 24 | D1: Valori ordini Vendor 24 | E1: Ordini Seller | F1: Valori ordini Seller | G1: % seller / totale | H1: Ordini Complessivi | I1: Valori ordini Complessivi | J1: Ordini Vendor 23 | K1: Valori ordini Vendor 23 | L1: Differenza Ordini | M1: Differenza Valore | N1: Differenza Valore %
A2: B0050IHH4E | B2: 40.979 | C2: =VLOOKUP(A2,v_03_24!A:D,3,FALSE) -> 1183 | D2: =VLOOKUP(A2,v_03_24!A:D,4,FALSE) -> 16822.21 | E2: 0 | F2: 0 | G2: =F2/I2 -> 0 | H2: =C2+E2 -> 1183 | I2: =D2+F2 -> 16822.21 | J2: =VLOOKUP(A2,v_03_23!A:D,3,FALSE) -> 287 | K2: =VLOOKUP(A2,v_03_23!A:D,4,FALSE) -> 3732.24 | L2: =H2-J2 -> 896 | M2: =I2-K2 -> 13089.97 | N2: =M2/K2 -> 3.5072691
A3: B009O92WU4 | B3: 40.999 | C3: =VLOOKUP(A3,v_03_24!A:D,3,FALSE) -> 1 | D3: =VLOOKUP(A3,v_03_24!A:D,4,FALSE) -> 5.03 | E3: 0 | F3: 0 | G3: =F3/I3 -> 0 | H3: =C3+E3 -> 1 | I3: =D3+F3 -> 5.03 | J3: =VLOOKUP(A3,v_03_23!A:D,3,FALSE) -> 4 | K3: =VLOOKUP(A3,v_03_23!A:D,4,FALSE) -> 33.15 | L3: =H3-J3 -> -3 | M3: =I3-K3 -> -28.12 | N3: =M3/K3 -> -0.84826546
A4: B00BH202XK | B4: 40.808A | C4: =VLOOKUP(A4,v_03_24!A:D,3,FALSE) -> 10 | D4: =VLOOKUP(A4,v_03_24!A:D,4,FALSE) -> 127.35 | E4: 0 | F4: 0 | G4: =F4/I4 -> 0 | H4: =C4+E4 -> 10 | I4: =D4+F4 -> 127.35 | J4: 0 | K4: 0 | L4: =H4-J4 -> 10 | M4: =I4-K4 -> 127.35
A5: B00CMAD2FG | B5: HK-NV009W | C5: =VLOOKUP(A5,v_03_24!A:D,3,FALSE) -> 1 | D5: =VLOOKUP(A5,v_03_24!A:D,4,FALSE) -> 15.18 | E5: 0 | F5: 0 | G5: =F5/I5 -> 0 | H5: =C5+E5 -> 1 | I5: =D5+F5 -> 15.18 | J5: =VLOOKUP(A5,v_03_23!A:D,3,FALSE) -> 2 | K5: =VLOOKUP(A5,v_03_23!A:D,4,FALSE) -> 33.58 | L5: =H5-J5 -> -1 | M5: =I5-K5 -> -18.4 | N5: =M5/K5 -> -0.54794521
A6: B00FFBFVG2 | B6: 40.100 | C6: =VLOOKUP(A6,v_03_24!A:D,3,FALSE) -> 0 | D6: =VLOOKUP(A6,v_03_24!A:D,4,FALSE) -> 0 | E6: 0 | F6: 0 | H6: =C6+E6 -> 0 | I6: =D6+F6 -> 0 | J6: =VLOOKUP(A6,v_03_23!A:D,3,FALSE) -> 5 | K6: =VLOOKUP(A6,v_03_23!A:D,4,FALSE) -> 42.39 | L6: =H6-J6 -> -5 | M6: =I6-K6 -> -42.39 | N6: =M6/K6 -> -1
A7: B00L5GPWFG | B7: 40.120 | C7: =VLOOKUP(A7,v_03_24!A:D,3,FALSE) -> 6 | D7: =VLOOKUP(A7,v_03_24!A:D,4,FALSE) -> 147.9 | E7: 0 | F7: 0 | G7: =F7/I7 -> 0 | H7: =C7+E7 -> 6 | I7: =D7+F7 -> 147.9 | J7: =VLOOKUP(A7,v_03_23!A:D,3,FALSE) -> 4 | K7: =VLOOKUP(A7,v_03_23!A:D,4,FALSE) -> 95.58 | L7: =H7-J7 -> 2 | M7: =I7-K7 -> 52.32 | N7: =M7/K7 -> 0.54739485
A8: B00L5H5KUW | B8: 40.121 | C8: =VLOOKUP(A8,v_03_24!A:D,3,FALSE) -> 275 | D8: =VLOOKUP(A8,v_03_24!A:D,4,FALSE) -> 5023.29 | E8: 0 | F8: 0 | G8: =F8/I8 -> 0 | H8: =C8+E8 -> 275 | I8: =D8+F8 -> 5023.29 | J8: =VLOOKUP(A8,v_03_23!A:D,3,FALSE) -> 58 | K8: =VLOOKUP(A8,v_03_23!A:D,4,FALSE) -> 1197.15 | L8: =H8-J8 -> 217 | M8: =I8-K8 -> 3826.14 | N8: =M8/K8 -> 3.1960406
A9: B00NSNZSLM | B9: 90.602 | C9: =VLOOKUP(A9,v_03_24!A:D,3,FALSE) -> 1 | D9: =VLOOKUP(A9,v_03_24!A:D,4,FALSE) -> 20.41 | E9: =VLOOKUP(A9,s_03_24!A:C,2,FALSE) -> BT.603Y | F9: =VLOOKUP(A9,s_03_24!A:C,3,FALSE) -> 2 | G9: =F9/I9 -> 0.089245872 | H9: =C9+E9 -> #VALUE! | I9: =D9+F9 -> 22.41 | J9: =VLOOKUP(A9,v_03_23!A:D,3,FALSE) -> 503 | K9: =VLOOKUP(A9,v_03_23!A:D,4,FALSE) -> 10307.45 | L9: =H9-J9 -> #VALUE! | M9: =I9-K9 -> -10285.04 | N9: =M9/K9 -> -0.99782584
A10: B00YH3FRV8 | B10: 40.998 | C10: =VLOOKUP(A10,v_03_24!A:D,3,FALSE) -> 1 | D10: =VLOOKUP(A10,v_03_24!A:D,4,FALSE) -> 7.43 | E10: 0 | F10: 0 | G10: =F10/I10 -> 0 | H10: =C10+E10 -> 1 | I10: =D10+F10 -> 7.43 | J10: 0 | K10: 0 | L10: =H10-J10 -> 1 | M10: =I10-K10 -> 7.43
A11: B011LFM60E | B11: 40.948T | C11: =VLOOKUP(A11,v_03_24!A:D,3,FALSE) -> 2 | D11: =VLOOKUP(A11,v_03_24!A:D,4,FALSE) -> 12.96 | E11: 0 | F11: 0 | G11: =F11/I11 -> 0 | H11: =C11+E11 -> 2 | I11: =D11+F11 -> 12.96 | J11: =VLOOKUP(A11,v_03_23!A:D,3,FALSE) -> 2 | K11: =VLOOKUP(A11,v_03_23!A:D,4,FALSE) -> 7.53 | L11: =H11-J11 -> 0 | M11: =I11-K11 -> 5.43 | N11: =M11/K11 -> 0.72111554
A12: B011LFVLW8 | B12: 90.620 | C12: =VLOOKUP(A12,v_03_24!A:D,3,FALSE) -> 19 | D12: =VLOOKUP(A12,v_03_24!A:D,4,FALSE) -> 686.19 | E12: 0 | F12: 0 | G12: =F12/I12 -> 0 | H12: =C12+E12 -> 19 | I12: =D12+F12 -> 686.19 | J12: =VLOOKUP(A12,v_03_23!A:D,3,FALSE) -> 16 | K12: =VLOOKUP(A12,v_03_23!A:D,4,FALSE) -> 590.39 | L12: =H12-J12 -> 3 | M12: =I12-K12 -> 95.8 | N12: =M12/K12 -> 0.16226562
A13: B017IUJA50 | B13: 90.920G | C13: =VLOOKUP(A13,v_03_24!A:D,3,FALSE) -> 15 | D13: =VLOOKUP(A13,v_03_24!A:D,4,FALSE) -> 209.45 | E13: =VLOOKUP(A13,s_03_24!A:C,2,FALSE) -> 90.920G | F13: =VLOOKUP(A13,s_03_24!A:C,3,FALSE) -> 14 | G13: =F13/I13 -> 0.062653838 | H13: =C13+E13 -> #VALUE! | I13: =D13+F13 -> 223.45 | J13: =VLOOKUP(A13,v_03_23!A:D,3,FALSE) -> 448 | K13: =VLOOKUP(A13,v_03_23!A:D,4,FALSE) -> 6892.94 | L13: =H13-J13 -> #VALUE! | M13: =I13-K13 -> -6669.49 | N13: =M13/K13 -> -0.96758277
A14: B01CHW1L88 | B14: PE.001 | C14: =VLOOKUP(A14,v_03_24!A:D,3,FALSE) -> 1 | D14: =VLOOKUP(A14,v_03_24!A:D,4,FALSE) -> 15.05 | E14: 0 | F14: 0 | G14: =F14/I14 -> 0 | H14: =C14+E14 -> 1 | I14: =D14+F14 -> 15.05 | J14: 0 | K14: 0 | L14: =H14-J14 -> 1 | M14: =I14-K14 -> 15.05
A15: B01CNX6UIM | B15: PE.300 | C15: =VLOOKUP(A15,v_03_24!A:D,3,FALSE) -> 3 | D15: =VLOOKUP(A15,v_03_24!A:D,4,FALSE) -> 17.19 | E15: 0 | F15: 0 | G15: =F15/I15 -> 0 | H15: =C15+E15 -> 3 | I15: =D15+F15 -> 17.19 | J15: 0 | K15: 0 | L15: =H15-J15 -> 3 | M15: =I15-K15 -> 17.19
A16: B01CNX704K | B16: 90.825 | C16: =VLOOKUP(A16,v_03_24!A:D,3,FALSE) -> 1 | D16: =VLOOKUP(A16,v_03_24!A:D,4,FALSE) -> 22.97 | E16: =VLOOKUP(A16,s_03_24!A:C,2,FALSE) -> 90825 | F16: =VLOOKUP(A16,s_03_24!A:C,3,FALSE) -> 1 | G16: =F16/I16 -> 0.041718815 | H16: =C16+E16 -> 90826 | I16: =D16+F16 -> 23.97 | J16: =VLOOKUP(A16,v_03_23!A:D,3,FALSE) -> 8 | K16: =VLOOKUP(A16,v_03_23!A:D,4,FALSE) -> 317.23 | L16: =H16-J16 -> 90818 | M16: =I16-K16 -> -293.26 | N16: =M16/K16 -> -0.92443968
A17: B01CNX71NA | B17: 90.871 | C17: =VLOOKUP(A17,v_03_24!A:D,3,FALSE) -> 12 | D17: =VLOOKUP(A17,v_03_24!A:D,4,FALSE) -> 1075.69 | E17: 0 | F17: 0 | G17: =F17/I17 -> 0 | H17: =C17+E17 -> 12 | I17: =D17+F17 -> 1075.69 | J17: =VLOOKUP(A17,v_03_23!A:D,3,FALSE) -> 15 | K17: =VLOOKUP(A17,v_03_23!A:D,4,FALSE) -> 1218.42 | L17: =H17-J17 -> -3 | M17: =I17-K17 -> -142.73 | N17: =M17/K17 -> -0.11714351
